Workbook

Sheet Controls
A1: Anthropic Operating Model - Controls
A3: SCENARIO | B3: Base
A4: BASIS | B4: Run-rate
A6: Block index | B6: =IF(B3="Base",IF(B4="Run-rate",1,2),IF(B3="Best",IF(B4="Run-rate",3,4),IF(B4="Run-rate",5,6)))
A8: How it works | B8: Pick a SCENARIO and BASIS above. The P&L Build sheet recomputes live via the block index in B6.
A9: SCENARIO | B9: Base / Best / Worst flex 2027-32 revenue growth plus inference and training-intensity margin levers. 2022-26 are actuals and identical across scenarios.
A10: BASIS | B10: Run-rate = annualized/exit basis (matches PitchBook TTM; 2026 ~breakeven). Recognized = GAAP-style recognized revenue (~50% of run-rate in 2026); workforce and capex are held at absolute levels, so the recognized view carries a wider operating loss.
A11: Charts | B11: The Charts sheet is a fixed Base / Run-rate snapshot (renders without recalculation). The P&L Build table is the live switchable view.
A12: Recalc | B12: If figures look blank on open, press Ctrl+Alt+F9 (Excel) to force a full recalculation.

Sheet P&L Build
A1: Anthropic PBC - Operating Model 2022A-2032E | Base / Run-rate view ($M unless noted). Live Scenario/Basis switch: see Controls + "Live Switch" sheet.
A2: Line Item | B2: Type | C2: Unit | D2: What it is | E2: 2022 | F2: 2023 | G2: 2024 | H2: 2025 | I2: 2026 | J2: 2027 | K2: 2028 | L2: 2029 | M2: 2030 | N2: 2031 | O2: 2032
A3: REVENUE
A4: Booked revenue | B4: IN | C4: $M | D4: Anchor. 2022-26 PitchBook TTM (10/100/1,000/9,000/47,000); 2027-32 base case. PB carries 55,000 for 2027 as a conservative mark. | E4: 10 | F4: 100 | G4: 1000 | H4: 9000 | I4: 47000 | J4: 80000 | K4: 115000 | L4: 150000 | M4: 185000 | N4: 215000 | O4: 245000
A5: API PRICING AND BLENDED EFFECTIVE RATE
A6: Model mix % - Mythos | B6: IN | C6: % | D6: Token share, flagship tier (Fable 5 / Mythos 5, $10/$50). Introduced 2026. | E6: 0 | F6: 0 | G6: 0 | H6: 0 | I6: 0.03 | J6: 0.05 | K6: 0.06 | L6: 0.07 | M6: 0.08 | N6: 0.09 | O6: 0.1
A7: Model mix % - Opus | B7: IN | C7: % | D7: Token share, Opus ($15/$75 to Aug-2025, cut to $5/$25 at Opus 4.5). | E7: 0 | F7: 0.1 | G7: 0.08 | H7: 0.1 | I7: 0.12 | J7: 0.12 | K7: 0.12 | L7: 0.12 | M7: 0.12 | N7: 0.12 | O7: 0.12
A8: Model mix % - Sonnet | B8: IN | C8: % | D8: Token share, Sonnet workhorse ($3/$15). | E8: 0.4 | F8: 0.3 | G8: 0.32 | H8: 0.45 | I8: 0.45 | J8: 0.44 | K8: 0.43 | L8: 0.42 | M8: 0.41 | N8: 0.4 | O8: 0.4
A9: Model mix % - Haiku | B9: IN | C9: % | D9: Token share, Haiku ($0.25/$1.25 -> $1/$5). | E9: 0.6 | F9: 0.6 | G9: 0.6 | H9: 0.45 | I9: 0.4 | J9: 0.39 | K9: 0.39 | L9: 0.39 | M9: 0.39 | N9: 0.39 | O9: 0.38
A10: List input $/Mtok - Mythos | B10: IN | C10: $ | D10: List input price, flagship. | E10: 15 | F10: 15 | G10: 15 | H10: 15 | I10: 15 | J10: 15 | K10: 14 | L10: 13 | M10: 12 | N10: 12 | O10: 11
A11: List input $/Mtok - Opus | B11: IN | C11: $ | D11: List input price, Opus. | E11: 11 | F11: 8 | G11: 15 | H11: 15 | I11: 5 | J11: 5 | K11: 5 | L11: 4.5 | M11: 4.5 | N11: 4 | O11: 4
A12: List input $/Mtok - Sonnet | B12: IN | C12: $ | D12: List input price, Sonnet. | E12: 3 | F12: 3 | G12: 3 | H12: 3 | I12: 3 | J12: 3 | K12: 3 | L12: 2.5 | M12: 2.5 | N12: 2 | O12: 2
A13: List input $/Mtok - Haiku | B13: IN | C13: $ | D13: List input price, Haiku. | E13: 0.8 | F13: 0.8 | G13: 0.25 | H13: 0.8 | I13: 1 | J13: 1 | K13: 1 | L13: 0.9 | M13: 0.9 | N13: 0.8 | O13: 0.8
A14: List output $/Mtok - Mythos | B14: IN | C14: $ | D14: List output price, flagship. | E14: 75 | F14: 75 | G14: 75 | H14: 75 | I14: 75 | J14: 70 | K14: 65 | L14: 60 | M14: 55 | N14: 55 | O14: 50
A15: List output $/Mtok - Opus | B15: IN | C15: $ | D15: List output price, Opus. | E15: 33 | F15: 24 | G15: 75 | H15: 75 | I15: 25 | J15: 25 | K15: 22 | L15: 22 | M15: 20 | N15: 20 | O15: 18
A16: List output $/Mtok - Sonnet | B16: IN | C16: $ | D16: List output price, Sonnet. | E16: 15 | F16: 15 | G16: 15 | H16: 15 | I16: 15 | J16: 15 | K16: 13 | L16: 13 | M16: 12 | N16: 10 | O16: 10
A17: List output $/Mtok - Haiku | B17: IN | C17: $ | D17: List output price, Haiku. | E17: 2.4 | F17: 2.4 | G17: 1.25 | H17: 4 | I17: 5 | J17: 5 | K17: 4.5 | L17: 4.5 | M17: 4 | N17: 4 | O17: 3.6
... A27: Blended effective $/Mtok | B27: CALC | C27: $ | D27: Mix-weighted, adjusted for input share, caching, batch. | E27: 2.9806452 | F27: 3.4768421 | G27: 3.793749 | H27: 4.1467112 | I27: 3.0571739 | J27: 2.9587834 | K27: 2.6527823 | L27: 2.3780343 | M27: 2.2407352 | N27: 2.0581018 | O27: 1.9921081
A28: NON-API REVENUE STREAMS
A29: # Enterprise contracts (>$1M ARR) | B29: IN | C29: count | D29: ~1,000+ at $1M+ ACV by 2026. | E29: 0 | F29: 5 | G29: 60 | H29: 300 | I29: 1000 | J29: 1700 | K29: 2400 | L29: 3100 | M29: 3700 | N29: 4200 | O29: 4600
A30: Committed-use discount % (memo) | B30: IN | C30: % | D30: Volume discount realized on enterprise API. | E30: 0 | F30: 0.05 | G30: 0.1 | H30: 0.12 | I30: 0.15 | J30: 0.15 | K30: 0.16 | L30: 0.16 | M30: 0.17 | N30: 0.17 | O30: 0.18
A31: Active enterprise dashboard seats | B31: IN | C31: count | D31: Console/admin seats. | E31: 0 | F31: 2000 | G31: 40000 | H31: 250000 | I31: 900000 | J31: 1600000 | K31: 2300000 | L31: 3000000 | M31: 3600000 | N31: 4100000 | O31: 4500000
A32: Enterprise platform fee / seat / mo | B32: IN | C32: $ | D32: Monthly platform fee per seat. | E32: 0 | F32: 30 | G32: 35 | H32: 40 | I32: 45 | J32: 48 | K32: 50 | L32: 52 | M32: 54 | N32: 55 | O32: 56
A33: Enterprise seat revenue | B33: CALC | C33: $M | D33: seats x fee x 12. | E33: 0 | F33: 0.72 | G33: 16.8 | H33: 120 | I33: 486 | J33: 921.6 | K33: 1380 | L33: 1872 | M33: 2332.8 | N33: 2706 | O33: 3024
A34: Consumer subscription revenue (anchor) | B34: IN | C34: $M | D34: Claude Pro ($20) + Max ($100/$200). | E34: 0 | F34: 8 | G34: 120 | H34: 1300 | I34: 6600 | J34: 11200 | K34: 16100 | L34: 21000 | M34: 25900 | N34: 30100 | O34: 34300
A35: Blended consumer ARPU ($/mo) | B35: IN | C35: $ | D35: Blend of Pro and Max. | E35: 20 | F35: 20 | G35: 21 | H35: 23 | I35: 26 | J35: 28 | K35: 29 | L35: 30 | M35: 31 | N35: 32 | O35: 33
A36: Paying consumer subs (implied) | B36: PLUG | C36: Count | D36: consumer rev / (ARPU x 12). | E36: 0 | F36: 33333.333 | G36: 476190.48 | H36: 4710144.9 | I36: 21153846 | J36: 33333333 | K36: 46264368 | L36: 58333333 | M36: 69623656 | N36: 78385417 | O36: 86616162
A37: Active developer seats | B37: IN | C37: Count | D37: Claude Code seats (Feb-2025). | E37: 0 | F37: 0 | G37: 0 | H37: 350000 | I37: 1100000 | J37: 1800000 | K37: 2500000 | L37: 3100000 | M37: 3600000 | N37: 4000000 | O37: 4300000
A38: Base seat fee ($/mo) | B38: IN | C38: $ | D38: Claude Code base seat fee. | E38: 0 | F38: 0 | G38: 0 | H38: 20 | I38: 22 | J38: 24 | K38: 25 | L38: 26 | M38: 27 | N38: 28 | O38: 28
A39: Claude Code base seat revenue | B39: CALC | C39: $M | D39: seats x fee x 12. | E39: 0 | F39: 0 | G39: 0 | H39: 84 | I39: 290.4 | J39: 518.4 | K39: 750 | L39: 967.2 | M39: 1166.4 | N39: 1344 | O39: 1444.8
A40: Avg overage tokens / dev / mo | B40: IN | C40: Mtok | D40: Usage above base seat. | E40: 0 | F40: 0 | G40: 0 | H40: 12 | I40: 20 | J40: 26 | K40: 30 | L40: 33 | M40: 36 | N40: 38 | O40: 40
... A60: Total non-API revenue | B60: CALC | C60: $M | D60: Sum of non-API streams. | E60: 0 | F60: 17.72 | G60: 300.115 | H60: 3188.7792 | I60: 13998.754 | J60: 23319.133 | K60: 32789.275 | L60: 41925.307 | M60: 50563.131 | N60: 57976.56 | O60: 64889.009
A61: FIRST PARTY DIRECT API REVENUE
A62: First-party API revenue | B62: PLUG | C62: $M | D62: Booked revenue minus non-API streams. | E62: 10 | F62: 82.28 | G62: 699.885 | H62: 5811.2208 | I62: 33001.246 | J62: 56680.867 | K62: 82210.725 | L62: 108074.69 | M62: 134436.87 | N62: 157023.44 | O62: 180110.99
A63: API TOKEN ENGINE
A64: Total tokens processed (all) | B64: PLUG | C64: T | D64: API revenue / blended $/Mtok (trillions). | E64: 3.3549784 | F64: 23.665153 | G64: 184.48374 | H64: 1401.4047 | I64: 10794.69 | J64: 19156.816 | K64: 30990.377 | L64: 45447.071 | M64: 59996.768 | N64: 76295.274 | O64: 90412.257
A65: Total input tokens | B65: CALC | C65: T | D65: tokens x input share. | E65: 2.5974026 | F65: 18.683015 | G65: 151.21618 | H65: 1208.1075 | I65: 9386.6874 | J65: 16857.998 | K65: 27459.828 | L65: 40663.169 | M65: 53770.689 | N65: 68470.117 | O65: 81229.762
A66: Total output tokens | B66: CALC | C66: T | D66: tokens x (1 - input share). | E66: 0.75757576 | F66: 4.9821375 | G66: 33.26756 | H66: 193.29721 | I66: 1408.0031 | J66: 2298.8179 | K66: 3530.5493 | L66: 4783.9022 | M66: 6226.0797 | N66: 7825.1563 | O66: 9182.4948
A67: Total first-party API calls | B67: CALC | C67: B | D67: tokens / tokens-per-call (billions). | E67: 2.1645022 | F67: 12.455344 | G67: 60.486472 | H67: 241.62151 | I67: 1173.3359 | J67: 1532.5452 | K67: 1961.4163 | L67: 2391.9511 | M67: 2830.0362 | N67: 3260.4818 | O67: 3531.7288
A68: Memo: calls / contract / day | B68: CALC | C68: # | D68: calls / contracts / 365. | E68: 5930142.9 | F68: 6824845.8 | G68: 2761939.4 | H68: 2206589.1 | I68: 3214619 | J68: 2469855.4 | K68: 2239059.7 | L68: 2113964.8 | M68: 2095547 | N68: 2126863.5 | O68: 2103471.6
...

Sheet Live Switch
A1: LIVE SWITCH - reflects Scenario & Basis chosen on the Controls sheet (press Ctrl+Alt+F9 if cells look blank)
A2: Line Item | B2: Type | C2: Unit | D2: What it is | E2: 2022 | F2: 2023 | G2: 2024 | H2: 2025 | I2: 2026 | J2: 2027 | K2: 2028 | L2: 2029 | M2: 2030 | N2: 2031 | O2: 2032
A3: REVENUE
A4: Booked revenue | B4: IN | C4: $M | D4: Anchor. 2022-26 PitchBook TTM (10/100/1,000/9,000/47,000); 2027-32 base case. PB carries 55,000 for 2027 as a conservative mark. | E4: =CHOOSE(Controls!$B$6,D1!E4,D2!E4,D3!E4,D4!E4,D5!E4,D6!E4) | F4: =CHOOSE(Controls!$B$6,D1!F4,D2!F4,D3!F4,D4!F4,D5!F4,D6!F4) | G4: =CHOOSE(Controls!$B$6,D1!G4,D2!G4,D3!G4,D4!G4,D5!G4,D6!G4) | H4: =CHOOSE(Controls!$B$6,D1!H4,D2!H4,D3!H4,D4!H4,D5!H4,D6!H4) | I4: =CHOOSE(Controls!$B$6,D1!I4,D2!I4,D3!I4,D4!I4,D5!I4,D6!I4) | J4: =CHOOSE(Controls!$B$6,D1!J4,D2!J4,D3!J4,D4!J4,D5!J4,D6!J4) | K4: =CHOOSE(Controls!$B$6,D1!K4,D2!K4,D3!K4,D4!K4,D5!K4,D6!K4) | L4: =CHOOSE(Controls!$B$6,D1!L4,D2!L4,D3!L4,D4!L4,D5!L4,D6!L4) | ... O4: =CHOOSE(Controls!$B$6,D1!O4,D2!O4,D3!O4,D4!O4,D5!O4,D6!O4)
A5: API PRICING AND BLENDED EFFECTIVE RATE
A6: Model mix % - Mythos | B6: IN | C6: % | D6: Token share, flagship tier (Fable 5 / Mythos 5, $10/$50). Introduced 2026. | E6: =CHOOSE(Controls!$B$6,D1!E6,D2!E6,D3!E6,D4!E6,D5!E6,D6!E6) | F6: =CHOOSE(Controls!$B$6,D1!F6,D2!F6,D3!F6,D4!F6,D5!F6,D6!F6) | G6: =CHOOSE(Controls!$B$6,D1!G6,D2!G6,D3!G6,D4!G6,D5!G6,D6!G6) | H6: =CHOOSE(Controls!$B$6,D1!H6,D2!H6,D3!H6,D4!H6,D5!H6,D6!H6) | I6: =CHOOSE(Controls!$B$6,D1!I6,D2!I6,D3!I6,D4!I6,D5!I6,D6!I6) | J6: =CHOOSE(Controls!$B$6,D1!J6,D2!J6,D3!J6,D4!J6,D5!J6,D6!J6) | K6: =CHOOSE(Controls!$B$6,D1!K6,D2!K6,D3!K6,D4!K6,D5!K6,D6!K6) | L6: =CHOOSE(Controls!$B$6,D1!L6,D2!L6,D3!L6,D4!L6,D5!L6,D6!L6) | ... O6: =CHOOSE(Controls!$B$6,D1!O6,D2!O6,D3!O6,D4!O6,D5!O6,D6!O6)
A7: Model mix % - Opus | B7: IN | C7: % | D7: Token share, Opus ($15/$75 to Aug-2025, cut to $5/$25 at Opus 4.5). | E7: =CHOOSE(Controls!$B$6,D1!E7,D2!E7,D3!E7,D4!E7,D5!E7,D6!E7) | F7: =CHOOSE(Controls!$B$6,D1!F7,D2!F7,D3!F7,D4!F7,D5!F7,D6!F7) | G7: =CHOOSE(Controls!$B$6,D1!G7,D2!G7,D3!G7,D4!G7,D5!G7,D6!G7) | H7: =CHOOSE(Controls!$B$6,D1!H7,D2!H7,D3!H7,D4!H7,D5!H7,D6!H7) | I7: =CHOOSE(Controls!$B$6,D1!I7,D2!I7,D3!I7,D4!I7,D5!I7,D6!I7) | J7: =CHOOSE(Controls!$B$6,D1!J7,D2!J7,D3!J7,D4!J7,D5!J7,D6!J7) | K7: =CHOOSE(Controls!$B$6,D1!K7,D2!K7,D3!K7,D4!K7,D5!K7,D6!K7) | L7: =CHOOSE(Controls!$B$6,D1!L7,D2!L7,D3!L7,D4!L7,D5!L7,D6!L7) | ... O7: =CHOOSE(Controls!$B$6,D1!O7,D2!O7,D3!O7,D4!O7,D5!O7,D6!O7)
A8: Model mix % - Sonnet | B8: IN | C8: % | D8: Token share, Sonnet workhorse ($3/$15). | E8: =CHOOSE(Controls!$B$6,D1!E8,D2!E8,D3!E8,D4!E8,D5!E8,D6!E8) | F8: =CHOOSE(Controls!$B$6,D1!F8,D2!F8,D3!F8,D4!F8,D5!F8,D6!F8) | G8: =CHOOSE(Controls!$B$6,D1!G8,D2!G8,D3!G8,D4!G8,D5!G8,D6!G8) | H8: =CHOOSE(Controls!$B$6,D1!H8,D2!H8,D3!H8,D4!H8,D5!H8,D6!H8) | I8: =CHOOSE(Controls!$B$6,D1!I8,D2!I8,D3!I8,D4!I8,D5!I8,D6!I8) | J8: =CHOOSE(Controls!$B$6,D1!J8,D2!J8,D3!J8,D4!J8,D5!J8,D6!J8) | K8: =CHOOSE(Controls!$B$6,D1!K8,D2!K8,D3!K8,D4!K8,D5!K8,D6!K8) | L8: =CHOOSE(Controls!$B$6,D1!L8,D2!L8,D3!L8,D4!L8,D5!L8,D6!L8) | ... O8: =CHOOSE(Controls!$B$6,D1!O8,D2!O8,D3!O8,D4!O8,D5!O8,D6!O8)
A9: Model mix % - Haiku | B9: IN | C9: % | D9: Token share, Haiku ($0.25/$1.25 -> $1/$5). | E9: =CHOOSE(Controls!$B$6,D1!E9,D2!E9,D3!E9,D4!E9,D5!E9,D6!E9) | F9: =CHOOSE(Controls!$B$6,D1!F9,D2!F9,D3!F9,D4!F9,D5!F9,D6!F9) | G9: =CHOOSE(Controls!$B$6,D1!G9,D2!G9,D3!G9,D4!G9,D5!G9,D6!G9) | H9: =CHOOSE(Controls!$B$6,D1!H9,D2!H9,D3!H9,D4!H9,D5!H9,D6!H9) | I9: =CHOOSE(Controls!$B$6,D1!I9,D2!I9,D3!I9,D4!I9,D5!I9,D6!I9) | J9: =CHOOSE(Controls!$B$6,D1!J9,D2!J9,D3!J9,D4!J9,D5!J9,D6!J9) | K9: =CHOOSE(Controls!$B$6,D1!K9,D2!K9,D3!K9,D4!K9,D5!K9,D6!K9) | L9: =CHOOSE(Controls!$B$6,D1!L9,D2!L9,D3!L9,D4!L9,D5!L9,D6!L9) | ... O9: =CHOOSE(Controls!$B$6,D1!O9,D2!O9,D3!O9,D4!O9,D5!O9,D6!O9)
A10: List input $/Mtok - Mythos | B10: IN | C10: $ | D10: List input price, flagship. | E10: =CHOOSE(Controls!$B$6,D1!E10,D2!E10,D3!E10,D4!E10,D5!E10,D6!E10) | F10: =CHOOSE(Controls!$B$6,D1!F10,D2!F10,D3!F10,D4!F10,D5!F10,D6!F10) | G10: =CHOOSE(Controls!$B$6,D1!G10,D2!G10,D3!G10,D4!G10,D5!G10,D6!G10) | H10: =CHOOSE(Controls!$B$6,D1!H10,D2!H10,D3!H10,D4!H10,D5!H10,D6!H10) | I10: =CHOOSE(Controls!$B$6,D1!I10,D2!I10,D3!I10,D4!I10,D5!I10,D6!I10) | J10: =CHOOSE(Controls!$B$6,D1!J10,D2!J10,D3!J10,D4!J10,D5!J10,D6!J10) | K10: =CHOOSE(Controls!$B$6,D1!K10,D2!K10,D3!K10,D4!K10,D5!K10,D6!K10) | L10: =CHOOSE(Controls!$B$6,D1!L10,D2!L10,D3!L10,D4!L10,D5!L10,D6!L10) | ... O10: =CHOOSE(Controls!$B$6,D1!O10,D2!O10,D3!O10,D4!O10,D5!O10,D6!O10)
A11: List input $/Mtok - Opus | B11: IN | C11: $ | D11: List input price, Opus. | E11: =CHOOSE(Controls!$B$6,D1!E11,D2!E11,D3!E11,D4!E11,D5!E11,D6!E11) | F11: =CHOOSE(Controls!$B$6,D1!F11,D2!F11,D3!F11,D4!F11,D5!F11,D6!F11) | G11: =CHOOSE(Controls!$B$6,D1!G11,D2!G11,D3!G11,D4!G11,D5!G11,D6!G11) | H11: =CHOOSE(Controls!$B$6,D1!H11,D2!H11,D3!H11,D4!H11,D5!H11,D6!H11) | I11: =CHOOSE(Controls!$B$6,D1!I11,D2!I11,D3!I11,D4!I11,D5!I11,D6!I11) | J11: =CHOOSE(Controls!$B$6,D1!J11,D2!J11,D3!J11,D4!J11,D5!J11,D6!J11) | K11: =CHOOSE(Controls!$B$6,D1!K11,D2!K11,D3!K11,D4!K11,D5!K11,D6!K11) | L11: =CHOOSE(Controls!$B$6,D1!L11,D2!L11,D3!L11,D4!L11,D5!L11,D6!L11) | ... O11: =CHOOSE(Controls!$B$6,D1!O11,D2!O11,D3!O11,D4!O11,D5!O11,D6!O11)
A12: List input $/Mtok - Sonnet | B12: IN | C12: $ | D12: List input price, Sonnet. | E12: =CHOOSE(Controls!$B$6,D1!E12,D2!E12,D3!E12,D4!E12,D5!E12,D6!E12) | F12: =CHOOSE(Controls!$B$6,D1!F12,D2!F12,D3!F12,D4!F12,D5!F12,D6!F12) | G12: =CHOOSE(Controls!$B$6,D1!G12,D2!G12,D3!G12,D4!G12,D5!G12,D6!G12) | H12: =CHOOSE(Controls!$B$6,D1!H12,D2!H12,D3!H12,D4!H12,D5!H12,D6!H12) | I12: =CHOOSE(Controls!$B$6,D1!I12,D2!I12,D3!I12,D4!I12,D5!I12,D6!I12) | J12: =CHOOSE(Controls!$B$6,D1!J12,D2!J12,D3!J12,D4!J12,D5!J12,D6!J12) | K12: =CHOOSE(Controls!$B$6,D1!K12,D2!K12,D3!K12,D4!K12,D5!K12,D6!K12) | L12: =CHOOSE(Controls!$B$6,D1!L12,D2!L12,D3!L12,D4!L12,D5!L12,D6!L12) | ... O12: =CHOOSE(Controls!$B$6,D1!O12,D2!O12,D3!O12,D4!O12,D5!O12,D6!O12)
A13: List input $/Mtok - Haiku | B13: IN | C13: $ | D13: List input price, Haiku. | E13: =CHOOSE(Controls!$B$6,D1!E13,D2!E13,D3!E13,D4!E13,D5!E13,D6!E13) | F13: =CHOOSE(Controls!$B$6,D1!F13,D2!F13,D3!F13,D4!F13,D5!F13,D6!F13) | G13: =CHOOSE(Controls!$B$6,D1!G13,D2!G13,D3!G13,D4!G13,D5!G13,D6!G13) | H13: =CHOOSE(Controls!$B$6,D1!H13,D2!H13,D3!H13,D4!H13,D5!H13,D6!H13) | I13: =CHOOSE(Controls!$B$6,D1!I13,D2!I13,D3!I13,D4!I13,D5!I13,D6!I13) | J13: =CHOOSE(Controls!$B$6,D1!J13,D2!J13,D3!J13,D4!J13,D5!J13,D6!J13) | K13: =CHOOSE(Controls!$B$6,D1!K13,D2!K13,D3!K13,D4!K13,D5!K13,D6!K13) | L13: =CHOOSE(Controls!$B$6,D1!L13,D2!L13,D3!L13,D4!L13,D5!L13,D6!L13) | ... O13: =CHOOSE(Controls!$B$6,D1!O13,D2!O13,D3!O13,D4!O13,D5!O13,D6!O13)
A14: List output $/Mtok - Mythos | B14: IN | C14: $ | D14: List output price, flagship. | E14: =CHOOSE(Controls!$B$6,D1!E14,D2!E14,D3!E14,D4!E14,D5!E14,D6!E14) | F14: =CHOOSE(Controls!$B$6,D1!F14,D2!F14,D3!F14,D4!F14,D5!F14,D6!F14) | G14: =CHOOSE(Controls!$B$6,D1!G14,D2!G14,D3!G14,D4!G14,D5!G14,D6!G14) | H14: =CHOOSE(Controls!$B$6,D1!H14,D2!H14,D3!H14,D4!H14,D5!H14,D6!H14) | I14: =CHOOSE(Controls!$B$6,D1!I14,D2!I14,D3!I14,D4!I14,D5!I14,D6!I14) | J14: =CHOOSE(Controls!$B$6,D1!J14,D2!J14,D3!J14,D4!J14,D5!J14,D6!J14) | K14: =CHOOSE(Controls!$B$6,D1!K14,D2!K14,D3!K14,D4!K14,D5!K14,D6!K14) | L14: =CHOOSE(Controls!$B$6,D1!L14,D2!L14,D3!L14,D4!L14,D5!L14,D6!L14) | ... O14: =CHOOSE(Controls!$B$6,D1!O14,D2!O14,D3!O14,D4!O14,D5!O14,D6!O14)
A15: List output $/Mtok - Opus | B15: IN | C15: $ | D15: List output price, Opus. | E15: =CHOOSE(Controls!$B$6,D1!E15,D2!E15,D3!E15,D4!E15,D5!E15,D6!E15) | F15: =CHOOSE(Controls!$B$6,D1!F15,D2!F15,D3!F15,D4!F15,D5!F15,D6!F15) | G15: =CHOOSE(Controls!$B$6,D1!G15,D2!G15,D3!G15,D4!G15,D5!G15,D6!G15) | H15: =CHOOSE(Controls!$B$6,D1!H15,D2!H15,D3!H15,D4!H15,D5!H15,D6!H15) | I15: =CHOOSE(Controls!$B$6,D1!I15,D2!I15,D3!I15,D4!I15,D5!I15,D6!I15) | J15: =CHOOSE(Controls!$B$6,D1!J15,D2!J15,D3!J15,D4!J15,D5!J15,D6!J15) | K15: =CHOOSE(Controls!$B$6,D1!K15,D2!K15,D3!K15,D4!K15,D5!K15,D6!K15) | L15: =CHOOSE(Controls!$B$6,D1!L15,D2!L15,D3!L15,D4!L15,D5!L15,D6!L15) | ... O15: =CHOOSE(Controls!$B$6,D1!O15,D2!O15,D3!O15,D4!O15,D5!O15,D6!O15)
A16: List output $/Mtok - Sonnet | B16: IN | C16: $ | D16: List output price, Sonnet. | E16: =CHOOSE(Controls!$B$6,D1!E16,D2!E16,D3!E16,D4!E16,D5!E16,D6!E16) | F16: =CHOOSE(Controls!$B$6,D1!F16,D2!F16,D3!F16,D4!F16,D5!F16,D6!F16) | G16: =CHOOSE(Controls!$B$6,D1!G16,D2!G16,D3!G16,D4!G16,D5!G16,D6!G16) | H16: =CHOOSE(Controls!$B$6,D1!H16,D2!H16,D3!H16,D4!H16,D5!H16,D6!H16) | I16: =CHOOSE(Controls!$B$6,D1!I16,D2!I16,D3!I16,D4!I16,D5!I16,D6!I16) | J16: =CHOOSE(Controls!$B$6,D1!J16,D2!J16,D3!J16,D4!J16,D5!J16,D6!J16) | K16: =CHOOSE(Controls!$B$6,D1!K16,D2!K16,D3!K16,D4!K16,D5!K16,D6!K16) | L16: =CHOOSE(Controls!$B$6,D1!L16,D2!L16,D3!L16,D4!L16,D5!L16,D6!L16) | ... O16: =CHOOSE(Controls!$B$6,D1!O16,D2!O16,D3!O16,D4!O16,D5!O16,D6!O16)
A17: List output $/Mtok - Haiku | B17: IN | C17: $ | D17: List output price, Haiku. | E17: =CHOOSE(Controls!$B$6,D1!E17,D2!E17,D3!E17,D4!E17,D5!E17,D6!E17) | F17: =CHOOSE(Controls!$B$6,D1!F17,D2!F17,D3!F17,D4!F17,D5!F17,D6!F17) | G17: =CHOOSE(Controls!$B$6,D1!G17,D2!G17,D3!G17,D4!G17,D5!G17,D6!G17) | H17: =CHOOSE(Controls!$B$6,D1!H17,D2!H17,D3!H17,D4!H17,D5!H17,D6!H17) | I17: =CHOOSE(Controls!$B$6,D1!I17,D2!I17,D3!I17,D4!I17,D5!I17,D6!I17) | J17: =CHOOSE(Controls!$B$6,D1!J17,D2!J17,D3!J17,D4!J17,D5!J17,D6!J17) | K17: =CHOOSE(Controls!$B$6,D1!K17,D2!K17,D3!K17,D4!K17,D5!K17,D6!K17) | L17: =CHOOSE(Controls!$B$6,D1!L17,D2!L17,D3!L17,D4!L17,D5!L17,D6!L17) | ... O17: =CHOOSE(Controls!$B$6,D1!O17,D2!O17,D3!O17,D4!O17,D5!O17,D6!O17)
... A27: Blended effective $/Mtok | B27: CALC | C27: $ | D27: Mix-weighted, adjusted for input share, caching, batch. | E27: =CHOOSE(Controls!$B$6,D1!E27,D2!E27,D3!E27,D4!E27,D5!E27,D6!E27) | F27: =CHOOSE(Controls!$B$6,D1!F27,D2!F27,D3!F27,D4!F27,D5!F27,D6!F27) | G27: =CHOOSE(Controls!$B$6,D1!G27,D2!G27,D3!G27,D4!G27,D5!G27,D6!G27) | H27: =CHOOSE(Controls!$B$6,D1!H27,D2!H27,D3!H27,D4!H27,D5!H27,D6!H27) | I27: =CHOOSE(Controls!$B$6,D1!I27,D2!I27,D3!I27,D4!I27,D5!I27,D6!I27) | J27: =CHOOSE(Controls!$B$6,D1!J27,D2!J27,D3!J27,D4!J27,D5!J27,D6!J27) | K27: =CHOOSE(Controls!$B$6,D1!K27,D2!K27,D3!K27,D4!K27,D5!K27,D6!K27) | L27: =CHOOSE(Controls!$B$6,D1!L27,D2!L27,D3!L27,D4!L27,D5!L27,D6!L27) | ... O27: =CHOOSE(Controls!$B$6,D1!O27,D2!O27,D3!O27,D4!O27,D5!O27,D6!O27)
A28: NON-API REVENUE STREAMS
A29: # Enterprise contracts (>$1M ARR) | B29: IN | C29: count | D29: ~1,000+ at $1M+ ACV by 2026. | E29: =CHOOSE(Controls!$B$6,D1!E29,D2!E29,D3!E29,D4!E29,D5!E29,D6!E29) | F29: =CHOOSE(Controls!$B$6,D1!F29,D2!F29,D3!F29,D4!F29,D5!F29,D6!F29) | G29: =CHOOSE(Controls!$B$6,D1!G29,D2!G29,D3!G29,D4!G29,D5!G29,D6!G29) | H29: =CHOOSE(Controls!$B$6,D1!H29,D2!H29,D3!H29,D4!H29,D5!H29,D6!H29) | I29: =CHOOSE(Controls!$B$6,D1!I29,D2!I29,D3!I29,D4!I29,D5!I29,D6!I29) | J29: =CHOOSE(Controls!$B$6,D1!J29,D2!J29,D3!J29,D4!J29,D5!J29,D6!J29) | K29: =CHOOSE(Controls!$B$6,D1!K29,D2!K29,D3!K29,D4!K29,D5!K29,D6!K29) | L29: =CHOOSE(Controls!$B$6,D1!L29,D2!L29,D3!L29,D4!L29,D5!L29,D6!L29) | ... O29: =CHOOSE(Controls!$B$6,D1!O29,D2!O29,D3!O29,D4!O29,D5!O29,D6!O29)
A30: Committed-use discount % (memo) | B30: IN | C30: % | D30: Volume discount realized on enterprise API. | E30: =CHOOSE(Controls!$B$6,D1!E30,D2!E30,D3!E30,D4!E30,D5!E30,D6!E30) | F30: =CHOOSE(Controls!$B$6,D1!F30,D2!F30,D3!F30,D4!F30,D5!F30,D6!F30) | G30: =CHOOSE(Controls!$B$6,D1!G30,D2!G30,D3!G30,D4!G30,D5!G30,D6!G30) | H30: =CHOOSE(Controls!$B$6,D1!H30,D2!H30,D3!H30,D4!H30,D5!H30,D6!H30) | I30: =CHOOSE(Controls!$B$6,D1!I30,D2!I30,D3!I30,D4!I30,D5!I30,D6!I30) | J30: =CHOOSE(Controls!$B$6,D1!J30,D2!J30,D3!J30,D4!J30,D5!J30,D6!J30) | K30: =CHOOSE(Controls!$B$6,D1!K30,D2!K30,D3!K30,D4!K30,D5!K30,D6!K30) | L30: =CHOOSE(Controls!$B$6,D1!L30,D2!L30,D3!L30,D4!L30,D5!L30,D6!L30) | ... O30: =CHOOSE(Controls!$B$6,D1!O30,D2!O30,D3!O30,D4!O30,D5!O30,D6!O30)
A31: Active enterprise dashboard seats | B31: IN | C31: count | D31: Console/admin seats. | E31: =CHOOSE(Controls!$B$6,D1!E31,D2!E31,D3!E31,D4!E31,D5!E31,D6!E31) | F31: =CHOOSE(Controls!$B$6,D1!F31,D2!F31,D3!F31,D4!F31,D5!F31,D6!F31) | G31: =CHOOSE(Controls!$B$6,D1!G31,D2!G31,D3!G31,D4!G31,D5!G31,D6!G31) | H31: =CHOOSE(Controls!$B$6,D1!H31,D2!H31,D3!H31,D4!H31,D5!H31,D6!H31) | I31: =CHOOSE(Controls!$B$6,D1!I31,D2!I31,D3!I31,D4!I31,D5!I31,D6!I31) | J31: =CHOOSE(Controls!$B$6,D1!J31,D2!J31,D3!J31,D4!J31,D5!J31,D6!J31) | K31: =CHOOSE(Controls!$B$6,D1!K31,D2!K31,D3!K31,D4!K31,D5!K31,D6!K31) | L31: =CHOOSE(Controls!$B$6,D1!L31,D2!L31,D3!L31,D4!L31,D5!L31,D6!L31) | ... O31: =CHOOSE(Controls!$B$6,D1!O31,D2!O31,D3!O31,D4!O31,D5!O31,D6!O31)
A32: Enterprise platform fee / seat / mo | B32: IN | C32: $ | D32: Monthly platform fee per seat. | E32: =CHOOSE(Controls!$B$6,D1!E32,D2!E32,D3!E32,D4!E32,D5!E32,D6!E32) | F32: =CHOOSE(Controls!$B$6,D1!F32,D2!F32,D3!F32,D4!F32,D5!F32,D6!F32) | G32: =CHOOSE(Controls!$B$6,D1!G32,D2!G32,D3!G32,D4!G32,D5!G32,D6!G32) | H32: =CHOOSE(Controls!$B$6,D1!H32,D2!H32,D3!H32,D4!H32,D5!H32,D6!H32) | I32: =CHOOSE(Controls!$B$6,D1!I32,D2!I32,D3!I32,D4!I32,D5!I32,D6!I32) | J32: =CHOOSE(Controls!$B$6,D1!J32,D2!J32,D3!J32,D4!J32,D5!J32,D6!J32) | K32: =CHOOSE(Controls!$B$6,D1!K32,D2!K32,D3!K32,D4!K32,D5!K32,D6!K32) | L32: =CHOOSE(Controls!$B$6,D1!L32,D2!L32,D3!L32,D4!L32,D5!L32,D6!L32) | ... O32: =CHOOSE(Controls!$B$6,D1!O32,D2!O32,D3!O32,D4!O32,D5!O32,D6!O32)
A33: Enterprise seat revenue | B33: CALC | C33: $M | D33: seats x fee x 12. | E33: =CHOOSE(Controls!$B$6,D1!E33,D2!E33,D3!E33,D4!E33,D5!E33,D6!E33) | F33: =CHOOSE(Controls!$B$6,D1!F33,D2!F33,D3!F33,D4!F33,D5!F33,D6!F33) | G33: =CHOOSE(Controls!$B$6,D1!G33,D2!G33,D3!G33,D4!G33,D5!G33,D6!G33) | H33: =CHOOSE(Controls!$B$6,D1!H33,D2!H33,D3!H33,D4!H33,D5!H33,D6!H33) | I33: =CHOOSE(Controls!$B$6,D1!I33,D2!I33,D3!I33,D4!I33,D5!I33,D6!I33) | J33: =CHOOSE(Controls!$B$6,D1!J33,D2!J33,D3!J33,D4!J33,D5!J33,D6!J33) | K33: =CHOOSE(Controls!$B$6,D1!K33,D2!K33,D3!K33,D4!K33,D5!K33,D6!K33) | L33: =CHOOSE(Controls!$B$6,D1!L33,D2!L33,D3!L33,D4!L33,D5!L33,D6!L33) | ... O33: =CHOOSE(Controls!$B$6,D1!O33,D2!O33,D3!O33,D4!O33,D5!O33,D6!O33)
A34: Consumer subscription revenue (anchor) | B34: IN | C34: $M | D34: Claude Pro ($20) + Max ($100/$200). | E34: =CHOOSE(Controls!$B$6,D1!E34,D2!E34,D3!E34,D4!E34,D5!E34,D6!E34) | F34: =CHOOSE(Controls!$B$6,D1!F34,D2!F34,D3!F34,D4!F34,D5!F34,D6!F34) | G34: =CHOOSE(Controls!$B$6,D1!G34,D2!G34,D3!G34,D4!G34,D5!G34,D6!G34) | H34: =CHOOSE(Controls!$B$6,D1!H34,D2!H34,D3!H34,D4!H34,D5!H34,D6!H34) | I34: =CHOOSE(Controls!$B$6,D1!I34,D2!I34,D3!I34,D4!I34,D5!I34,D6!I34) | J34: =CHOOSE(Controls!$B$6,D1!J34,D2!J34,D3!J34,D4!J34,D5!J34,D6!J34) | K34: =CHOOSE(Controls!$B$6,D1!K34,D2!K34,D3!K34,D4!K34,D5!K34,D6!K34) | L34: =CHOOSE(Controls!$B$6,D1!L34,D2!L34,D3!L34,D4!L34,D5!L34,D6!L34) | ... O34: =CHOOSE(Controls!$B$6,D1!O34,D2!O34,D3!O34,D4!O34,D5!O34,D6!O34)
A35: Blended consumer ARPU ($/mo) | B35: IN | C35: $ | D35: Blend of Pro and Max. | E35: =CHOOSE(Controls!$B$6,D1!E35,D2!E35,D3!E35,D4!E35,D5!E35,D6!E35) | F35: =CHOOSE(Controls!$B$6,D1!F35,D2!F35,D3!F35,D4!F35,D5!F35,D6!F35) | G35: =CHOOSE(Controls!$B$6,D1!G35,D2!G35,D3!G35,D4!G35,D5!G35,D6!G35) | H35: =CHOOSE(Controls!$B$6,D1!H35,D2!H35,D3!H35,D4!H35,D5!H35,D6!H35) | I35: =CHOOSE(Controls!$B$6,D1!I35,D2!I35,D3!I35,D4!I35,D5!I35,D6!I35) | J35: =CHOOSE(Controls!$B$6,D1!J35,D2!J35,D3!J35,D4!J35,D5!J35,D6!J35) | K35: =CHOOSE(Controls!$B$6,D1!K35,D2!K35,D3!K35,D4!K35,D5!K35,D6!K35) | L35: =CHOOSE(Controls!$B$6,D1!L35,D2!L35,D3!L35,D4!L35,D5!L35,D6!L35) | ... O35: =CHOOSE(Controls!$B$6,D1!O35,D2!O35,D3!O35,D4!O35,D5!O35,D6!O35)
A36: Paying consumer subs (implied) | B36: PLUG | C36: Count | D36: consumer rev / (ARPU x 12). | E36: =CHOOSE(Controls!$B$6,D1!E36,D2!E36,D3!E36,D4!E36,D5!E36,D6!E36) | F36: =CHOOSE(Controls!$B$6,D1!F36,D2!F36,D3!F36,D4!F36,D5!F36,D6!F36) | G36: =CHOOSE(Controls!$B$6,D1!G36,D2!G36,D3!G36,D4!G36,D5!G36,D6!G36) | H36: =CHOOSE(Controls!$B$6,D1!H36,D2!H36,D3!H36,D4!H36,D5!H36,D6!H36) | I36: =CHOOSE(Controls!$B$6,D1!I36,D2!I36,D3!I36,D4!I36,D5!I36,D6!I36) | J36: =CHOOSE(Controls!$B$6,D1!J36,D2!J36,D3!J36,D4!J36,D5!J36,D6!J36) | K36: =CHOOSE(Controls!$B$6,D1!K36,D2!K36,D3!K36,D4!K36,D5!K36,D6!K36) | L36: =CHOOSE(Controls!$B$6,D1!L36,D2!L36,D3!L36,D4!L36,D5!L36,D6!L36) | ... O36: =CHOOSE(Controls!$B$6,D1!O36,D2!O36,D3!O36,D4!O36,D5!O36,D6!O36)
A37: Active developer seats | B37: IN | C37: Count | D37: Claude Code seats (Feb-2025). | E37: =CHOOSE(Controls!$B$6,D1!E37,D2!E37,D3!E37,D4!E37,D5!E37,D6!E37) | F37: =CHOOSE(Controls!$B$6,D1!F37,D2!F37,D3!F37,D4!F37,D5!F37,D6!F37) | G37: =CHOOSE(Controls!$B$6,D1!G37,D2!G37,D3!G37,D4!G37,D5!G37,D6!G37) | H37: =CHOOSE(Controls!$B$6,D1!H37,D2!H37,D3!H37,D4!H37,D5!H37,D6!H37) | I37: =CHOOSE(Controls!$B$6,D1!I37,D2!I37,D3!I37,D4!I37,D5!I37,D6!I37) | J37: =CHOOSE(Controls!$B$6,D1!J37,D2!J37,D3!J37,D4!J37,D5!J37,D6!J37) | K37: =CHOOSE(Controls!$B$6,D1!K37,D2!K37,D3!K37,D4!K37,D5!K37,D6!K37) | L37: =CHOOSE(Controls!$B$6,D1!L37,D2!L37,D3!L37,D4!L37,D5!L37,D6!L37) | ... O37: =CHOOSE(Controls!$B$6,D1!O37,D2!O37,D3!O37,D4!O37,D5!O37,D6!O37)
A38: Base seat fee ($/mo) | B38: IN | C38: $ | D38: Claude Code base seat fee. | E38: =CHOOSE(Controls!$B$6,D1!E38,D2!E38,D3!E38,D4!E38,D5!E38,D6!E38) | F38: =CHOOSE(Controls!$B$6,D1!F38,D2!F38,D3!F38,D4!F38,D5!F38,D6!F38) | G38: =CHOOSE(Controls!$B$6,D1!G38,D2!G38,D3!G38,D4!G38,D5!G38,D6!G38) | H38: =CHOOSE(Controls!$B$6,D1!H38,D2!H38,D3!H38,D4!H38,D5!H38,D6!H38) | I38: =CHOOSE(Controls!$B$6,D1!I38,D2!I38,D3!I38,D4!I38,D5!I38,D6!I38) | J38: =CHOOSE(Controls!$B$6,D1!J38,D2!J38,D3!J38,D4!J38,D5!J38,D6!J38) | K38: =CHOOSE(Controls!$B$6,D1!K38,D2!K38,D3!K38,D4!K38,D5!K38,D6!K38) | L38: =CHOOSE(Controls!$B$6,D1!L38,D2!L38,D3!L38,D4!L38,D5!L38,D6!L38) | ... O38: =CHOOSE(Controls!$B$6,D1!O38,D2!O38,D3!O38,D4!O38,D5!O38,D6!O38)
A39: Claude Code base seat revenue | B39: CALC | C39: $M | D39: seats x fee x 12. | E39: =CHOOSE(Controls!$B$6,D1!E39,D2!E39,D3!E39,D4!E39,D5!E39,D6!E39) | F39: =CHOOSE(Controls!$B$6,D1!F39,D2!F39,D3!F39,D4!F39,D5!F39,D6!F39) | G39: =CHOOSE(Controls!$B$6,D1!G39,D2!G39,D3!G39,D4!G39,D5!G39,D6!G39) | H39: =CHOOSE(Controls!$B$6,D1!H39,D2!H39,D3!H39,D4!H39,D5!H39,D6!H39) | I39: =CHOOSE(Controls!$B$6,D1!I39,D2!I39,D3!I39,D4!I39,D5!I39,D6!I39) | J39: =CHOOSE(Controls!$B$6,D1!J39,D2!J39,D3!J39,D4!J39,D5!J39,D6!J39) | K39: =CHOOSE(Controls!$B$6,D1!K39,D2!K39,D3!K39,D4!K39,D5!K39,D6!K39) | L39: =CHOOSE(Controls!$B$6,D1!L39,D2!L39,D3!L39,D4!L39,D5!L39,D6!L39) | ... O39: =CHOOSE(Controls!$B$6,D1!O39,D2!O39,D3!O39,D4!O39,D5!O39,D6!O39)
A40: Avg overage tokens / dev / mo | B40: IN | C40: Mtok | D40: Usage above base seat. | E40: =CHOOSE(Controls!$B$6,D1!E40,D2!E40,D3!E40,D4!E40,D5!E40,D6!E40) | F40: =CHOOSE(Controls!$B$6,D1!F40,D2!F40,D3!F40,D4!F40,D5!F40,D6!F40) | G40: =CHOOSE(Controls!$B$6,D1!G40,D2!G40,D3!G40,D4!G40,D5!G40,D6!G40) | H40: =CHOOSE(Controls!$B$6,D1!H40,D2!H40,D3!H40,D4!H40,D5!H40,D6!H40) | I40: =CHOOSE(Controls!$B$6,D1!I40,D2!I40,D3!I40,D4!I40,D5!I40,D6!I40) | J40: =CHOOSE(Controls!$B$6,D1!J40,D2!J40,D3!J40,D4!J40,D5!J40,D6!J40) | K40: =CHOOSE(Controls!$B$6,D1!K40,D2!K40,D3!K40,D4!K40,D5!K40,D6!K40) | L40: =CHOOSE(Controls!$B$6,D1!L40,D2!L40,D3!L40,D4!L40,D5!L40,D6!L40) | ... O40: =CHOOSE(Controls!$B$6,D1!O40,D2!O40,D3!O40,D4!O40,D5!O40,D6!O40)
... A60: Total non-API revenue | B60: CALC | C60: $M | D60: Sum of non-API streams. | E60: =CHOOSE(Controls!$B$6,D1!E60,D2!E60,D3!E60,D4!E60,D5!E60,D6!E60) | F60: =CHOOSE(Controls!$B$6,D1!F60,D2!F60,D3!F60,D4!F60,D5!F60,D6!F60) | G60: =CHOOSE(Controls!$B$6,D1!G60,D2!G60,D3!G60,D4!G60,D5!G60,D6!G60) | H60: =CHOOSE(Controls!$B$6,D1!H60,D2!H60,D3!H60,D4!H60,D5!H60,D6!H60) | I60: =CHOOSE(Controls!$B$6,D1!I60,D2!I60,D3!I60,D4!I60,D5!I60,D6!I60) | J60: =CHOOSE(Controls!$B$6,D1!J60,D2!J60,D3!J60,D4!J60,D5!J60,D6!J60) | K60: =CHOOSE(Controls!$B$6,D1!K60,D2!K60,D3!K60,D4!K60,D5!K60,D6!K60) | L60: =CHOOSE(Controls!$B$6,D1!L60,D2!L60,D3!L60,D4!L60,D5!L60,D6!L60) | ... O60: =CHOOSE(Controls!$B$6,D1!O60,D2!O60,D3!O60,D4!O60,D5!O60,D6!O60)
A61: FIRST PARTY DIRECT API REVENUE
A62: First-party API revenue | B62: PLUG | C62: $M | D62: Booked revenue minus non-API streams. | E62: =CHOOSE(Controls!$B$6,D1!E62,D2!E62,D3!E62,D4!E62,D5!E62,D6!E62) | F62: =CHOOSE(Controls!$B$6,D1!F62,D2!F62,D3!F62,D4!F62,D5!F62,D6!F62) | G62: =CHOOSE(Controls!$B$6,D1!G62,D2!G62,D3!G62,D4!G62,D5!G62,D6!G62) | H62: =CHOOSE(Controls!$B$6,D1!H62,D2!H62,D3!H62,D4!H62,D5!H62,D6!H62) | I62: =CHOOSE(Controls!$B$6,D1!I62,D2!I62,D3!I62,D4!I62,D5!I62,D6!I62) | J62: =CHOOSE(Controls!$B$6,D1!J62,D2!J62,D3!J62,D4!J62,D5!J62,D6!J62) | K62: =CHOOSE(Controls!$B$6,D1!K62,D2!K62,D3!K62,D4!K62,D5!K62,D6!K62) | L62: =CHOOSE(Controls!$B$6,D1!L62,D2!L62,D3!L62,D4!L62,D5!L62,D6!L62) | ... O62: =CHOOSE(Controls!$B$6,D1!O62,D2!O62,D3!O62,D4!O62,D5!O62,D6!O62)
A63: API TOKEN ENGINE
A64: Total tokens processed (all) | B64: PLUG | C64: T | D64: API revenue / blended $/Mtok (trillions). | E64: =CHOOSE(Controls!$B$6,D1!E64,D2!E64,D3!E64,D4!E64,D5!E64,D6!E64) | F64: =CHOOSE(Controls!$B$6,D1!F64,D2!F64,D3!F64,D4!F64,D5!F64,D6!F64) | G64: =CHOOSE(Controls!$B$6,D1!G64,D2!G64,D3!G64,D4!G64,D5!G64,D6!G64) | H64: =CHOOSE(Controls!$B$6,D1!H64,D2!H64,D3!H64,D4!H64,D5!H64,D6!H64) | I64: =CHOOSE(Controls!$B$6,D1!I64,D2!I64,D3!I64,D4!I64,D5!I64,D6!I64) | J64: =CHOOSE(Controls!$B$6,D1!J64,D2!J64,D3!J64,D4!J64,D5!J64,D6!J64) | K64: =CHOOSE(Controls!$B$6,D1!K64,D2!K64,D3!K64,D4!K64,D5!K64,D6!K64) | L64: =CHOOSE(Controls!$B$6,D1!L64,D2!L64,D3!L64,D4!L64,D5!L64,D6!L64) | ... O64: =CHOOSE(Controls!$B$6,D1!O64,D2!O64,D3!O64,D4!O64,D5!O64,D6!O64)
A65: Total input tokens | B65: CALC | C65: T | D65: tokens x input share. | E65: =CHOOSE(Controls!$B$6,D1!E65,D2!E65,D3!E65,D4!E65,D5!E65,D6!E65) | F65: =CHOOSE(Controls!$B$6,D1!F65,D2!F65,D3!F65,D4!F65,D5!F65,D6!F65) | G65: =CHOOSE(Controls!$B$6,D1!G65,D2!G65,D3!G65,D4!G65,D5!G65,D6!G65) | H65: =CHOOSE(Controls!$B$6,D1!H65,D2!H65,D3!H65,D4!H65,D5!H65,D6!H65) | I65: =CHOOSE(Controls!$B$6,D1!I65,D2!I65,D3!I65,D4!I65,D5!I65,D6!I65) | J65: =CHOOSE(Controls!$B$6,D1!J65,D2!J65,D3!J65,D4!J65,D5!J65,D6!J65) | K65: =CHOOSE(Controls!$B$6,D1!K65,D2!K65,D3!K65,D4!K65,D5!K65,D6!K65) | L65: =CHOOSE(Controls!$B$6,D1!L65,D2!L65,D3!L65,D4!L65,D5!L65,D6!L65) | ... O65: =CHOOSE(Controls!$B$6,D1!O65,D2!O65,D3!O65,D4!O65,D5!O65,D6!O65)
A66: Total output tokens | B66: CALC | C66: T | D66: tokens x (1 - input share). | E66: =CHOOSE(Controls!$B$6,D1!E66,D2!E66,D3!E66,D4!E66,D5!E66,D6!E66) | F66: =CHOOSE(Controls!$B$6,D1!F66,D2!F66,D3!F66,D4!F66,D5!F66,D6!F66) | G66: =CHOOSE(Controls!$B$6,D1!G66,D2!G66,D3!G66,D4!G66,D5!G66,D6!G66) | H66: =CHOOSE(Controls!$B$6,D1!H66,D2!H66,D3!H66,D4!H66,D5!H66,D6!H66) | I66: =CHOOSE(Controls!$B$6,D1!I66,D2!I66,D3!I66,D4!I66,D5!I66,D6!I66) | J66: =CHOOSE(Controls!$B$6,D1!J66,D2!J66,D3!J66,D4!J66,D5!J66,D6!J66) | K66: =CHOOSE(Controls!$B$6,D1!K66,D2!K66,D3!K66,D4!K66,D5!K66,D6!K66) | L66: =CHOOSE(Controls!$B$6,D1!L66,D2!L66,D3!L66,D4!L66,D5!L66,D6!L66) | ... O66: =CHOOSE(Controls!$B$6,D1!O66,D2!O66,D3!O66,D4!O66,D5!O66,D6!O66)
A67: Total first-party API calls | B67: CALC | C67: B | D67: tokens / tokens-per-call (billions). | E67: =CHOOSE(Controls!$B$6,D1!E67,D2!E67,D3!E67,D4!E67,D5!E67,D6!E67) | F67: =CHOOSE(Controls!$B$6,D1!F67,D2!F67,D3!F67,D4!F67,D5!F67,D6!F67) | G67: =CHOOSE(Controls!$B$6,D1!G67,D2!G67,D3!G67,D4!G67,D5!G67,D6!G67) | H67: =CHOOSE(Controls!$B$6,D1!H67,D2!H67,D3!H67,D4!H67,D5!H67,D6!H67) | I67: =CHOOSE(Controls!$B$6,D1!I67,D2!I67,D3!I67,D4!I67,D5!I67,D6!I67) | J67: =CHOOSE(Controls!$B$6,D1!J67,D2!J67,D3!J67,D4!J67,D5!J67,D6!J67) | K67: =CHOOSE(Controls!$B$6,D1!K67,D2!K67,D3!K67,D4!K67,D5!K67,D6!K67) | L67: =CHOOSE(Controls!$B$6,D1!L67,D2!L67,D3!L67,D4!L67,D5!L67,D6!L67) | ... O67: =CHOOSE(Controls!$B$6,D1!O67,D2!O67,D3!O67,D4!O67,D5!O67,D6!O67)
A68: Memo: calls / contract / day | B68: CALC | C68: # | D68: calls / contracts / 365. | E68: =CHOOSE(Controls!$B$6,D1!E68,D2!E68,D3!E68,D4!E68,D5!E68,D6!E68) | F68: =CHOOSE(Controls!$B$6,D1!F68,D2!F68,D3!F68,D4!F68,D5!F68,D6!F68) | G68: =CHOOSE(Controls!$B$6,D1!G68,D2!G68,D3!G68,D4!G68,D5!G68,D6!G68) | H68: =CHOOSE(Controls!$B$6,D1!H68,D2!H68,D3!H68,D4!H68,D5!H68,D6!H68) | I68: =CHOOSE(Controls!$B$6,D1!I68,D2!I68,D3!I68,D4!I68,D5!I68,D6!I68) | J68: =CHOOSE(Controls!$B$6,D1!J68,D2!J68,D3!J68,D4!J68,D5!J68,D6!J68) | K68: =CHOOSE(Controls!$B$6,D1!K68,D2!K68,D3!K68,D4!K68,D5!K68,D6!K68) | L68: =CHOOSE(Controls!$B$6,D1!L68,D2!L68,D3!L68,D4!L68,D5!L68,D6!L68) | ... O68: =CHOOSE(Controls!$B$6,D1!O68,D2!O68,D3!O68,D4!O68,D5!O68,D6!O68)
...

Sheet D1
A1: Base/Run-rate (data block D1)
A2: Line Item | B2: Type | C2: Unit | D2: What it is | E2: 2022 | F2: 2023 | G2: 2024 | H2: 2025 | I2: 2026 | J2: 2027 | K2: 2028 | L2: 2029 | M2: 2030 | N2: 2031 | O2: 2032
A3: REVENUE
A4: Booked revenue | B4: IN | C4: $M | D4: Anchor. 2022-26 PitchBook TTM (10/100/1,000/9,000/47,000); 2027-32 base case. PB carries 55,000 for 2027 as a conservative mark. | E4: 10 | F4: 100 | G4: 1000 | H4: 9000 | I4: 47000 | J4: 80000 | K4: 115000 | L4: 150000 | M4: 185000 | N4: 215000 | O4: 245000
A5: API PRICING AND BLENDED EFFECTIVE RATE
A6: Model mix % - Mythos | B6: IN | C6: % | D6: Token share, flagship tier (Fable 5 / Mythos 5, $10/$50). Introduced 2026. | E6: 0 | F6: 0 | G6: 0 | H6: 0 | I6: 0.03 | J6: 0.05 | K6: 0.06 | L6: 0.07 | M6: 0.08 | N6: 0.09 | O6: 0.1
A7: Model mix % - Opus | B7: IN | C7: % | D7: Token share, Opus ($15/$75 to Aug-2025, cut to $5/$25 at Opus 4.5). | E7: 0 | F7: 0.1 | G7: 0.08 | H7: 0.1 | I7: 0.12 | J7: 0.12 | K7: 0.12 | L7: 0.12 | M7: 0.12 | N7: 0.12 | O7: 0.12
A8: Model mix % - Sonnet | B8: IN | C8: % | D8: Token share, Sonnet workhorse ($3/$15). | E8: 0.4 | F8: 0.3 | G8: 0.32 | H8: 0.45 | I8: 0.45 | J8: 0.44 | K8: 0.43 | L8: 0.42 | M8: 0.41 | N8: 0.4 | O8: 0.4
A9: Model mix % - Haiku | B9: IN | C9: % | D9: Token share, Haiku ($0.25/$1.25 -> $1/$5). | E9: 0.6 | F9: 0.6 | G9: 0.6 | H9: 0.45 | I9: 0.4 | J9: 0.39 | K9: 0.39 | L9: 0.39 | M9: 0.39 | N9: 0.39 | O9: 0.38
A10: List input $/Mtok - Mythos | B10: IN | C10: $ | D10: List input price, flagship. | E10: 15 | F10: 15 | G10: 15 | H10: 15 | I10: 15 | J10: 15 | K10: 14 | L10: 13 | M10: 12 | N10: 12 | O10: 11
A11: List input $/Mtok - Opus | B11: IN | C11: $ | D11: List input price, Opus. | E11: 11 | F11: 8 | G11: 15 | H11: 15 | I11: 5 | J11: 5 | K11: 5 | L11: 4.5 | M11: 4.5 | N11: 4 | O11: 4
A12: List input $/Mtok - Sonnet | B12: IN | C12: $ | D12: List input price, Sonnet. | E12: 3 | F12: 3 | G12: 3 | H12: 3 | I12: 3 | J12: 3 | K12: 3 | L12: 2.5 | M12: 2.5 | N12: 2 | O12: 2
A13: List input $/Mtok - Haiku | B13: IN | C13: $ | D13: List input price, Haiku. | E13: 0.8 | F13: 0.8 | G13: 0.25 | H13: 0.8 | I13: 1 | J13: 1 | K13: 1 | L13: 0.9 | M13: 0.9 | N13: 0.8 | O13: 0.8
A14: List output $/Mtok - Mythos | B14: IN | C14: $ | D14: List output price, flagship. | E14: 75 | F14: 75 | G14: 75 | H14: 75 | I14: 75 | J14: 70 | K14: 65 | L14: 60 | M14: 55 | N14: 55 | O14: 50
A15: List output $/Mtok - Opus | B15: IN | C15: $ | D15: List output price, Opus. | E15: 33 | F15: 24 | G15: 75 | H15: 75 | I15: 25 | J15: 25 | K15: 22 | L15: 22 | M15: 20 | N15: 20 | O15: 18
A16: List output $/Mtok - Sonnet | B16: IN | C16: $ | D16: List output price, Sonnet. | E16: 15 | F16: 15 | G16: 15 | H16: 15 | I16: 15 | J16: 15 | K16: 13 | L16: 13 | M16: 12 | N16: 10 | O16: 10
A17: List output $/Mtok - Haiku | B17: IN | C17: $ | D17: List output price, Haiku. | E17: 2.4 | F17: 2.4 | G17: 1.25 | H17: 4 | I17: 5 | J17: 5 | K17: 4.5 | L17: 4.5 | M17: 4 | N17: 4 | O17: 3.6
... A27: Blended effective $/Mtok | B27: CALC | C27: $ | D27: Mix-weighted, adjusted for input share, caching, batch. | E27: 2.9806452 | F27: 3.4768421 | G27: 3.793749 | H27: 4.1467112 | I27: 3.0571739 | J27: 2.9587834 | K27: 2.6527823 | L27: 2.3780343 | M27: 2.2407352 | N27: 2.0581018 | O27: 1.9921081
A28: NON-API REVENUE STREAMS
A29: # Enterprise contracts (>$1M ARR) | B29: IN | C29: count | D29: ~1,000+ at $1M+ ACV by 2026. | E29: 0 | F29: 5 | G29: 60 | H29: 300 | I29: 1000 | J29: 1700 | K29: 2400 | L29: 3100 | M29: 3700 | N29: 4200 | O29: 4600
A30: Committed-use discount % (memo) | B30: IN | C30: % | D30: Volume discount realized on enterprise API. | E30: 0 | F30: 0.05 | G30: 0.1 | H30: 0.12 | I30: 0.15 | J30: 0.15 | K30: 0.16 | L30: 0.16 | M30: 0.17 | N30: 0.17 | O30: 0.18
A31: Active enterprise dashboard seats | B31: IN | C31: count | D31: Console/admin seats. | E31: 0 | F31: 2000 | G31: 40000 | H31: 250000 | I31: 900000 | J31: 1600000 | K31: 2300000 | L31: 3000000 | M31: 3600000 | N31: 4100000 | O31: 4500000
A32: Enterprise platform fee / seat / mo | B32: IN | C32: $ | D32: Monthly platform fee per seat. | E32: 0 | F32: 30 | G32: 35 | H32: 40 | I32: 45 | J32: 48 | K32: 50 | L32: 52 | M32: 54 | N32: 55 | O32: 56
A33: Enterprise seat revenue | B33: CALC | C33: $M | D33: seats x fee x 12. | E33: 0 | F33: 0.72 | G33: 16.8 | H33: 120 | I33: 486 | J33: 921.6 | K33: 1380 | L33: 1872 | M33: 2332.8 | N33: 2706 | O33: 3024
A34: Consumer subscription revenue (anchor) | B34: IN | C34: $M | D34: Claude Pro ($20) + Max ($100/$200). | E34: 0 | F34: 8 | G34: 120 | H34: 1300 | I34: 6600 | J34: 11200 | K34: 16100 | L34: 21000 | M34: 25900 | N34: 30100 | O34: 34300
A35: Blended consumer ARPU ($/mo) | B35: IN | C35: $ | D35: Blend of Pro and Max. | E35: 20 | F35: 20 | G35: 21 | H35: 23 | I35: 26 | J35: 28 | K35: 29 | L35: 30 | M35: 31 | N35: 32 | O35: 33
A36: Paying consumer subs (implied) | B36: PLUG | C36: Count | D36: consumer rev / (ARPU x 12). | E36: 0 | F36: 33333.333 | G36: 476190.48 | H36: 4710144.9 | I36: 21153846 | J36: 33333333 | K36: 46264368 | L36: 58333333 | M36: 69623656 | N36: 78385417 | O36: 86616162
A37: Active developer seats | B37: IN | C37: Count | D37: Claude Code seats (Feb-2025). | E37: 0 | F37: 0 | G37: 0 | H37: 350000 | I37: 1100000 | J37: 1800000 | K37: 2500000 | L37: 3100000 | M37: 3600000 | N37: 4000000 | O37: 4300000
A38: Base seat fee ($/mo) | B38: IN | C38: $ | D38: Claude Code base seat fee. | E38: 0 | F38: 0 | G38: 0 | H38: 20 | I38: 22 | J38: 24 | K38: 25 | L38: 26 | M38: 27 | N38: 28 | O38: 28
A39: Claude Code base seat revenue | B39: CALC | C39: $M | D39: seats x fee x 12. | E39: 0 | F39: 0 | G39: 0 | H39: 84 | I39: 290.4 | J39: 518.4 | K39: 750 | L39: 967.2 | M39: 1166.4 | N39: 1344 | O39: 1444.8
A40: Avg overage tokens / dev / mo | B40: IN | C40: Mtok | D40: Usage above base seat. | E40: 0 | F40: 0 | G40: 0 | H40: 12 | I40: 20 | J40: 26 | K40: 30 | L40: 33 | M40: 36 | N40: 38 | O40: 40
... A60: Total non-API revenue | B60: CALC | C60: $M | D60: Sum of non-API streams. | E60: 0 | F60: 17.72 | G60: 300.115 | H60: 3188.7792 | I60: 13998.754 | J60: 23319.133 | K60: 32789.275 | L60: 41925.307 | M60: 50563.131 | N60: 57976.56 | O60: 64889.009
A61: FIRST PARTY DIRECT API REVENUE
A62: First-party API revenue | B62: PLUG | C62: $M | D62: Booked revenue minus non-API streams. | E62: 10 | F62: 82.28 | G62: 699.885 | H62: 5811.2208 | I62: 33001.246 | J62: 56680.867 | K62: 82210.725 | L62: 108074.69 | M62: 134436.87 | N62: 157023.44 | O62: 180110.99
A63: API TOKEN ENGINE
A64: Total tokens processed (all) | B64: PLUG | C64: T | D64: API revenue / blended $/Mtok (trillions). | E64: 3.3549784 | F64: 23.665153 | G64: 184.48374 | H64: 1401.4047 | I64: 10794.69 | J64: 19156.816 | K64: 30990.377 | L64: 45447.071 | M64: 59996.768 | N64: 76295.274 | O64: 90412.257
A65: Total input tokens | B65: CALC | C65: T | D65: tokens x input share. | E65: 2.5974026 | F65: 18.683015 | G65: 151.21618 | H65: 1208.1075 | I65: 9386.6874 | J65: 16857.998 | K65: 27459.828 | L65: 40663.169 | M65: 53770.689 | N65: 68470.117 | O65: 81229.762
A66: Total output tokens | B66: CALC | C66: T | D66: tokens x (1 - input share). | E66: 0.75757576 | F66: 4.9821375 | G66: 33.26756 | H66: 193.29721 | I66: 1408.0031 | J66: 2298.8179 | K66: 3530.5493 | L66: 4783.9022 | M66: 6226.0797 | N66: 7825.1563 | O66: 9182.4948
A67: Total first-party API calls | B67: CALC | C67: B | D67: tokens / tokens-per-call (billions). | E67: 2.1645022 | F67: 12.455344 | G67: 60.486472 | H67: 241.62151 | I67: 1173.3359 | J67: 1532.5452 | K67: 1961.4163 | L67: 2391.9511 | M67: 2830.0362 | N67: 3260.4818 | O67: 3531.7288
A68: Memo: calls / contract / day | B68: CALC | C68: # | D68: calls / contracts / 365. | E68: 5930142.9 | F68: 6824845.8 | G68: 2761939.4 | H68: 2206589.1 | I68: 3214619 | J68: 2469855.4 | K68: 2239059.7 | L68: 2113964.8 | M68: 2095547 | N68: 2126863.5 | O68: 2103471.6
...

Sheet D2
A1: Base/Recognized (data block D2)
A2: Line Item | B2: Type | C2: Unit | D2: What it is | E2: 2022 | F2: 2023 | G2: 2024 | H2: 2025 | I2: 2026 | J2: 2027 | K2: 2028 | L2: 2029 | M2: 2030 | N2: 2031 | O2: 2032
A3: REVENUE
A4: Booked revenue | B4: IN | C4: $M | D4: Anchor. 2022-26 PitchBook TTM (10/100/1,000/9,000/47,000); 2027-32 base case. PB carries 55,000 for 2027 as a conservative mark. | E4: 10 | F4: 85 | G4: 600 | H4: 4680 | I4: 23500 | J4: 49600 | K4: 82800 | L4: 120000 | M4: 157250 | N4: 189200 | O4: 220500
A5: API PRICING AND BLENDED EFFECTIVE RATE
A6: Model mix % - Mythos | B6: IN | C6: % | D6: Token share, flagship tier (Fable 5 / Mythos 5, $10/$50). Introduced 2026. | E6: 0 | F6: 0 | G6: 0 | H6: 0 | I6: 0.03 | J6: 0.05 | K6: 0.06 | L6: 0.07 | M6: 0.08 | N6: 0.09 | O6: 0.1
A7: Model mix % - Opus | B7: IN | C7: % | D7: Token share, Opus ($15/$75 to Aug-2025, cut to $5/$25 at Opus 4.5). | E7: 0 | F7: 0.1 | G7: 0.08 | H7: 0.1 | I7: 0.12 | J7: 0.12 | K7: 0.12 | L7: 0.12 | M7: 0.12 | N7: 0.12 | O7: 0.12
A8: Model mix % - Sonnet | B8: IN | C8: % | D8: Token share, Sonnet workhorse ($3/$15). | E8: 0.4 | F8: 0.3 | G8: 0.32 | H8: 0.45 | I8: 0.45 | J8: 0.44 | K8: 0.43 | L8: 0.42 | M8: 0.41 | N8: 0.4 | O8: 0.4
A9: Model mix % - Haiku | B9: IN | C9: % | D9: Token share, Haiku ($0.25/$1.25 -> $1/$5). | E9: 0.6 | F9: 0.6 | G9: 0.6 | H9: 0.45 | I9: 0.4 | J9: 0.39 | K9: 0.39 | L9: 0.39 | M9: 0.39 | N9: 0.39 | O9: 0.38
A10: List input $/Mtok - Mythos | B10: IN | C10: $ | D10: List input price, flagship. | E10: 15 | F10: 15 | G10: 15 | H10: 15 | I10: 15 | J10: 15 | K10: 14 | L10: 13 | M10: 12 | N10: 12 | O10: 11
A11: List input $/Mtok - Opus | B11: IN | C11: $ | D11: List input price, Opus. | E11: 11 | F11: 8 | G11: 15 | H11: 15 | I11: 5 | J11: 5 | K11: 5 | L11: 4.5 | M11: 4.5 | N11: 4 | O11: 4
A12: List input $/Mtok - Sonnet | B12: IN | C12: $ | D12: List input price, Sonnet. | E12: 3 | F12: 3 | G12: 3 | H12: 3 | I12: 3 | J12: 3 | K12: 3 | L12: 2.5 | M12: 2.5 | N12: 2 | O12: 2
A13: List input $/Mtok - Haiku | B13: IN | C13: $ | D13: List input price, Haiku. | E13: 0.8 | F13: 0.8 | G13: 0.25 | H13: 0.8 | I13: 1 | J13: 1 | K13: 1 | L13: 0.9 | M13: 0.9 | N13: 0.8 | O13: 0.8
A14: List output $/Mtok - Mythos | B14: IN | C14: $ | D14: List output price, flagship. | E14: 75 | F14: 75 | G14: 75 | H14: 75 | I14: 75 | J14: 70 | K14: 65 | L14: 60 | M14: 55 | N14: 55 | O14: 50
A15: List output $/Mtok - Opus | B15: IN | C15: $ | D15: List output price, Opus. | E15: 33 | F15: 24 | G15: 75 | H15: 75 | I15: 25 | J15: 25 | K15: 22 | L15: 22 | M15: 20 | N15: 20 | O15: 18
A16: List output $/Mtok - Sonnet | B16: IN | C16: $ | D16: List output price, Sonnet. | E16: 15 | F16: 15 | G16: 15 | H16: 15 | I16: 15 | J16: 15 | K16: 13 | L16: 13 | M16: 12 | N16: 10 | O16: 10
A17: List output $/Mtok - Haiku | B17: IN | C17: $ | D17: List output price, Haiku. | E17: 2.4 | F17: 2.4 | G17: 1.25 | H17: 4 | I17: 5 | J17: 5 | K17: 4.5 | L17: 4.5 | M17: 4 | N17: 4 | O17: 3.6
... A27: Blended effective $/Mtok | B27: CALC | C27: $ | D27: Mix-weighted, adjusted for input share, caching, batch. | E27: 2.9806452 | F27: 3.4768421 | G27: 3.793749 | H27: 4.1467112 | I27: 3.0571739 | J27: 2.9587834 | K27: 2.6527823 | L27: 2.3780343 | M27: 2.2407352 | N27: 2.0581018 | O27: 1.9921081
A28: NON-API REVENUE STREAMS
A29: # Enterprise contracts (>$1M ARR) | B29: IN | C29: count | D29: ~1,000+ at $1M+ ACV by 2026. | E29: 0 | F29: 4.25 | G29: 36 | H29: 156 | I29: 500 | J29: 1054 | K29: 1728 | L29: 2480 | M29: 3145 | N29: 3696 | O29: 4140
A30: Committed-use discount % (memo) | B30: IN | C30: % | D30: Volume discount realized on enterprise API. | E30: 0 | F30: 0.05 | G30: 0.1 | H30: 0.12 | I30: 0.15 | J30: 0.15 | K30: 0.16 | L30: 0.16 | M30: 0.17 | N30: 0.17 | O30: 0.18
A31: Active enterprise dashboard seats | B31: IN | C31: count | D31: Console/admin seats. | E31: 0 | F31: 1700 | G31: 24000 | H31: 130000 | I31: 450000 | J31: 992000 | K31: 1656000 | L31: 2400000 | M31: 3060000 | N31: 3608000 | O31: 4050000
A32: Enterprise platform fee / seat / mo | B32: IN | C32: $ | D32: Monthly platform fee per seat. | E32: 0 | F32: 30 | G32: 35 | H32: 40 | I32: 45 | J32: 48 | K32: 50 | L32: 52 | M32: 54 | N32: 55 | O32: 56
A33: Enterprise seat revenue | B33: CALC | C33: $M | D33: seats x fee x 12. | E33: 0 | F33: 0.612 | G33: 10.08 | H33: 62.4 | I33: 243 | J33: 571.392 | K33: 993.6 | L33: 1497.6 | M33: 1982.88 | N33: 2381.28 | O33: 2721.6
A34: Consumer subscription revenue (anchor) | B34: IN | C34: $M | D34: Claude Pro ($20) + Max ($100/$200). | E34: 0 | F34: 6.8 | G34: 72 | H34: 676 | I34: 3300 | J34: 6944 | K34: 11592 | L34: 16800 | M34: 22015 | N34: 26488 | O34: 30870
A35: Blended consumer ARPU ($/mo) | B35: IN | C35: $ | D35: Blend of Pro and Max. | E35: 20 | F35: 20 | G35: 21 | H35: 23 | I35: 26 | J35: 28 | K35: 29 | L35: 30 | M35: 31 | N35: 32 | O35: 33
A36: Paying consumer subs (implied) | B36: PLUG | C36: Count | D36: consumer rev / (ARPU x 12). | E36: 0 | F36: 28333.333 | G36: 285714.29 | H36: 2449275.4 | I36: 10576923 | J36: 20666667 | K36: 33310345 | L36: 46666667 | M36: 59180108 | N36: 68979167 | O36: 77954545
A37: Active developer seats | B37: IN | C37: Count | D37: Claude Code seats (Feb-2025). | E37: 0 | F37: 0 | G37: 0 | H37: 182000 | I37: 550000 | J37: 1116000 | K37: 1800000 | L37: 2480000 | M37: 3060000 | N37: 3520000 | O37: 3870000
A38: Base seat fee ($/mo) | B38: IN | C38: $ | D38: Claude Code base seat fee. | E38: 0 | F38: 0 | G38: 0 | H38: 20 | I38: 22 | J38: 24 | K38: 25 | L38: 26 | M38: 27 | N38: 28 | O38: 28
A39: Claude Code base seat revenue | B39: CALC | C39: $M | D39: seats x fee x 12. | E39: 0 | F39: 0 | G39: 0 | H39: 43.68 | I39: 145.2 | J39: 321.408 | K39: 540 | L39: 773.76 | M39: 991.44 | N39: 1182.72 | O39: 1300.32
A40: Avg overage tokens / dev / mo | B40: IN | C40: Mtok | D40: Usage above base seat. | E40: 0 | F40: 0 | G40: 0 | H40: 12 | I40: 20 | J40: 26 | K40: 30 | L40: 33 | M40: 36 | N40: 38 | O40: 40
... A60: Total non-API revenue | B60: CALC | C60: $M | D60: Sum of non-API streams. | E60: 0 | F60: 15.062 | G60: 180.069 | H60: 1658.1352 | I60: 6999.323 | J60: 14458.798 | K60: 23609.622 | L60: 33541.679 | M60: 42979.835 | N60: 51020.189 | O60: 58400.731
A61: FIRST PARTY DIRECT API REVENUE
A62: First-party API revenue | B62: PLUG | C62: $M | D62: Booked revenue minus non-API streams. | E62: 10 | F62: 69.938 | G62: 419.931 | H62: 3021.8648 | I62: 16500.677 | J62: 35141.202 | K62: 59190.378 | L62: 86458.321 | M62: 114270.17 | N62: 138179.81 | O62: 162099.27
A63: API TOKEN ENGINE
A64: Total tokens processed (all) | B64: PLUG | C64: T | D64: API revenue / blended $/Mtok (trillions). | E64: 3.3549784 | F64: 20.11538 | G64: 110.69024 | H64: 728.7377 | I64: 5397.3629 | J64: 11876.909 | K64: 22312.565 | L64: 36357.054 | M64: 50996.73 | N64: 67139.444 | O64: 81370.718
A65: Total input tokens | B65: CALC | C65: T | D65: tokens x input share. | E65: 2.5974026 | F65: 15.880563 | G65: 90.729708 | H65: 628.22216 | I65: 4693.359 | J65: 10451.68 | K65: 19770.627 | L65: 32529.996 | M65: 45704.616 | N65: 60253.347 | O65: 73106.505
A66: Total output tokens | B66: CALC | C66: T | D66: tokens x (1 - input share). | E66: 0.75757576 | F66: 4.2348168 | G66: 19.960536 | H66: 100.51555 | I66: 704.00386 | J66: 1425.2291 | K66: 2541.9378 | L66: 3827.0583 | M66: 5292.1134 | N66: 6886.0968 | O66: 8264.2136
A67: Total first-party API calls | B67: CALC | C67: B | D67: tokens / tokens-per-call (billions). | E67: 2.1645022 | F67: 10.587042 | G67: 36.291883 | H67: 125.64443 | I67: 586.66988 | J67: 950.15275 | K67: 1412.1877 | L67: 1913.5292 | M67: 2405.5061 | N67: 2869.207 | O67: 3178.5437
A68: Memo: calls / contract / day | B68: CALC | C68: # | D68: calls / contracts / 365. | E68: 5930142.9 | F68: 6824845.8 | G68: 2761939.4 | H68: 2206611 | I68: 3214629.5 | J68: 2469789.6 | K68: 2239008.8 | L68: 2113929.7 | M68: 2095525.5 | N68: 2126851 | O68: 2103463.5
...

Sheet D3
A1: Best/Run-rate (data block D3)
A2: Line Item | B2: Type | C2: Unit | D2: What it is | E2: 2022 | F2: 2023 | G2: 2024 | H2: 2025 | I2: 2026 | J2: 2027 | K2: 2028 | L2: 2029 | M2: 2030 | N2: 2031 | O2: 2032
A3: REVENUE
A4: Booked revenue | B4: IN | C4: $M | D4: Anchor. 2022-26 PitchBook TTM (10/100/1,000/9,000/47,000); 2027-32 base case. PB carries 55,000 for 2027 as a conservative mark. | E4: 10 | F4: 100 | G4: 1000 | H4: 9000 | I4: 47000 | J4: 92000 | K4: 140000 | L4: 190000 | M4: 245000 | N4: 300000 | O4: 355000
A5: API PRICING AND BLENDED EFFECTIVE RATE
A6: Model mix % - Mythos | B6: IN | C6: % | D6: Token share, flagship tier (Fable 5 / Mythos 5, $10/$50). Introduced 2026. | E6: 0 | F6: 0 | G6: 0 | H6: 0 | I6: 0.03 | J6: 0.05 | K6: 0.06 | L6: 0.07 | M6: 0.08 | N6: 0.09 | O6: 0.1
A7: Model mix % - Opus | B7: IN | C7: % | D7: Token share, Opus ($15/$75 to Aug-2025, cut to $5/$25 at Opus 4.5). | E7: 0 | F7: 0.1 | G7: 0.08 | H7: 0.1 | I7: 0.12 | J7: 0.12 | K7: 0.12 | L7: 0.12 | M7: 0.12 | N7: 0.12 | O7: 0.12
A8: Model mix % - Sonnet | B8: IN | C8: % | D8: Token share, Sonnet workhorse ($3/$15). | E8: 0.4 | F8: 0.3 | G8: 0.32 | H8: 0.45 | I8: 0.45 | J8: 0.44 | K8: 0.43 | L8: 0.42 | M8: 0.41 | N8: 0.4 | O8: 0.4
A9: Model mix % - Haiku | B9: IN | C9: % | D9: Token share, Haiku ($0.25/$1.25 -> $1/$5). | E9: 0.6 | F9: 0.6 | G9: 0.6 | H9: 0.45 | I9: 0.4 | J9: 0.39 | K9: 0.39 | L9: 0.39 | M9: 0.39 | N9: 0.39 | O9: 0.38
A10: List input $/Mtok - Mythos | B10: IN | C10: $ | D10: List input price, flagship. | E10: 15 | F10: 15 | G10: 15 | H10: 15 | I10: 15 | J10: 15 | K10: 14 | L10: 13 | M10: 12 | N10: 12 | O10: 11
A11: List input $/Mtok - Opus | B11: IN | C11: $ | D11: List input price, Opus. | E11: 11 | F11: 8 | G11: 15 | H11: 15 | I11: 5 | J11: 5 | K11: 5 | L11: 4.5 | M11: 4.5 | N11: 4 | O11: 4
A12: List input $/Mtok - Sonnet | B12: IN | C12: $ | D12: List input price, Sonnet. | E12: 3 | F12: 3 | G12: 3 | H12: 3 | I12: 3 | J12: 3 | K12: 3 | L12: 2.5 | M12: 2.5 | N12: 2 | O12: 2
A13: List input $/Mtok - Haiku | B13: IN | C13: $ | D13: List input price, Haiku. | E13: 0.8 | F13: 0.8 | G13: 0.25 | H13: 0.8 | I13: 1 | J13: 1 | K13: 1 | L13: 0.9 | M13: 0.9 | N13: 0.8 | O13: 0.8
A14: List output $/Mtok - Mythos | B14: IN | C14: $ | D14: List output price, flagship. | E14: 75 | F14: 75 | G14: 75 | H14: 75 | I14: 75 | J14: 70 | K14: 65 | L14: 60 | M14: 55 | N14: 55 | O14: 50
A15: List output $/Mtok - Opus | B15: IN | C15: $ | D15: List output price, Opus. | E15: 33 | F15: 24 | G15: 75 | H15: 75 | I15: 25 | J15: 25 | K15: 22 | L15: 22 | M15: 20 | N15: 20 | O15: 18
A16: List output $/Mtok - Sonnet | B16: IN | C16: $ | D16: List output price, Sonnet. | E16: 15 | F16: 15 | G16: 15 | H16: 15 | I16: 15 | J16: 15 | K16: 13 | L16: 13 | M16: 12 | N16: 10 | O16: 10
A17: List output $/Mtok - Haiku | B17: IN | C17: $ | D17: List output price, Haiku. | E17: 2.4 | F17: 2.4 | G17: 1.25 | H17: 4 | I17: 5 | J17: 5 | K17: 4.5 | L17: 4.5 | M17: 4 | N17: 4 | O17: 3.6
... A27: Blended effective $/Mtok | B27: CALC | C27: $ | D27: Mix-weighted, adjusted for input share, caching, batch. | E27: 2.9806452 | F27: 3.4768421 | G27: 3.793749 | H27: 4.1467112 | I27: 3.0571739 | J27: 2.9587834 | K27: 2.6527823 | L27: 2.3780343 | M27: 2.2407352 | N27: 2.0581018 | O27: 1.9921081
A28: NON-API REVENUE STREAMS
A29: # Enterprise contracts (>$1M ARR) | B29: IN | C29: count | D29: ~1,000+ at $1M+ ACV by 2026. | E29: 0 | F29: 5 | G29: 60 | H29: 300 | I29: 1000 | J29: 1700 | K29: 2400 | L29: 3100 | M29: 3700 | N29: 4200 | O29: 4600
A30: Committed-use discount % (memo) | B30: IN | C30: % | D30: Volume discount realized on enterprise API. | E30: 0 | F30: 0.05 | G30: 0.1 | H30: 0.12 | I30: 0.15 | J30: 0.15 | K30: 0.16 | L30: 0.16 | M30: 0.17 | N30: 0.17 | O30: 0.18
A31: Active enterprise dashboard seats | B31: IN | C31: count | D31: Console/admin seats. | E31: 0 | F31: 2000 | G31: 40000 | H31: 250000 | I31: 900000 | J31: 1600000 | K31: 2300000 | L31: 3000000 | M31: 3600000 | N31: 4100000 | O31: 4500000
A32: Enterprise platform fee / seat / mo | B32: IN | C32: $ | D32: Monthly platform fee per seat. | E32: 0 | F32: 30 | G32: 35 | H32: 40 | I32: 45 | J32: 48 | K32: 50 | L32: 52 | M32: 54 | N32: 55 | O32: 56
A33: Enterprise seat revenue | B33: CALC | C33: $M | D33: seats x fee x 12. | E33: 0 | F33: 0.72 | G33: 16.8 | H33: 120 | I33: 486 | J33: 921.6 | K33: 1380 | L33: 1872 | M33: 2332.8 | N33: 2706 | O33: 3024
A34: Consumer subscription revenue (anchor) | B34: IN | C34: $M | D34: Claude Pro ($20) + Max ($100/$200). | E34: 0 | F34: 8 | G34: 120 | H34: 1300 | I34: 6600 | J34: 11200 | K34: 16100 | L34: 21000 | M34: 25900 | N34: 30100 | O34: 34300
A35: Blended consumer ARPU ($/mo) | B35: IN | C35: $ | D35: Blend of Pro and Max. | E35: 20 | F35: 20 | G35: 21 | H35: 23 | I35: 26 | J35: 28 | K35: 29 | L35: 30 | M35: 31 | N35: 32 | O35: 33
A36: Paying consumer subs (implied) | B36: PLUG | C36: Count | D36: consumer rev / (ARPU x 12). | E36: 0 | F36: 33333.333 | G36: 476190.48 | H36: 4710144.9 | I36: 21153846 | J36: 33333333 | K36: 46264368 | L36: 58333333 | M36: 69623656 | N36: 78385417 | O36: 86616162
A37: Active developer seats | B37: IN | C37: Count | D37: Claude Code seats (Feb-2025). | E37: 0 | F37: 0 | G37: 0 | H37: 350000 | I37: 1100000 | J37: 1800000 | K37: 2500000 | L37: 3100000 | M37: 3600000 | N37: 4000000 | O37: 4300000
A38: Base seat fee ($/mo) | B38: IN | C38: $ | D38: Claude Code base seat fee. | E38: 0 | F38: 0 | G38: 0 | H38: 20 | I38: 22 | J38: 24 | K38: 25 | L38: 26 | M38: 27 | N38: 28 | O38: 28
A39: Claude Code base seat revenue | B39: CALC | C39: $M | D39: seats x fee x 12. | E39: 0 | F39: 0 | G39: 0 | H39: 84 | I39: 290.4 | J39: 518.4 | K39: 750 | L39: 967.2 | M39: 1166.4 | N39: 1344 | O39: 1444.8
A40: Avg overage tokens / dev / mo | B40: IN | C40: Mtok | D40: Usage above base seat. | E40: 0 | F40: 0 | G40: 0 | H40: 12 | I40: 20 | J40: 26 | K40: 30 | L40: 33 | M40: 36 | N40: 38 | O40: 40
... A60: Total non-API revenue | B60: CALC | C60: $M | D60: Sum of non-API streams. | E60: 0 | F60: 17.72 | G60: 300.115 | H60: 3188.7792 | I60: 13998.754 | J60: 23319.133 | K60: 32789.275 | L60: 41925.307 | M60: 50563.131 | N60: 57976.56 | O60: 64889.009
A61: FIRST PARTY DIRECT API REVENUE
A62: First-party API revenue | B62: PLUG | C62: $M | D62: Booked revenue minus non-API streams. | E62: 10 | F62: 82.28 | G62: 699.885 | H62: 5811.2208 | I62: 33001.246 | J62: 68680.867 | K62: 107210.72 | L62: 148074.69 | M62: 194436.87 | N62: 242023.44 | O62: 290110.99
A63: API TOKEN ENGINE
A64: Total tokens processed (all) | B64: PLUG | C64: T | D64: API revenue / blended $/Mtok (trillions). | E64: 3.3549784 | F64: 23.665153 | G64: 184.48374 | H64: 1401.4047 | I64: 10794.69 | J64: 23212.537 | K64: 40414.445 | L64: 62267.687 | M64: 86773.694 | N64: 117595.47 | O64: 145630.14
A65: Total input tokens | B65: CALC | C65: T | D65: tokens x input share. | E65: 2.5974026 | F65: 18.683015 | G65: 151.21618 | H65: 1208.1075 | I65: 9386.6874 | J65: 20427.032 | K65: 35810.268 | L65: 55713.193 | M65: 77768.877 | N65: 105534.39 | O65: 130839.58
A66: Total output tokens | B66: CALC | C66: T | D66: tokens x (1 - input share). | E66: 0.75757576 | F66: 4.9821375 | G66: 33.26756 | H66: 193.29721 | I66: 1408.0031 | J66: 2785.5044 | K66: 4604.1773 | L66: 6554.4933 | M66: 9004.8173 | N66: 12061.073 | O66: 14790.561
A67: Total first-party API calls | B67: CALC | C67: B | D67: tokens / tokens-per-call (billions). | E67: 2.1645022 | F67: 12.455344 | G67: 60.486472 | H67: 241.62151 | I67: 1173.3359 | J67: 1857.0029 | K67: 2557.8763 | L67: 3277.2467 | M67: 4093.0988 | N67: 5025.4473 | O67: 5688.6775
A68: Memo: calls / contract / day | B68: CALC | C68: # | D68: calls / contracts / 365. | E68: 5930142.9 | F68: 6824845.8 | G68: 2761939.4 | H68: 2206589.1 | I68: 3214619 | J68: 2992752.5 | K68: 2919950.1 | L68: 2896373.5 | M68: 3030802.5 | N68: 3278178.2 | O68: 3388134.3
...

Sheet D4
A1: Best/Recognized (data block D4)
A2: Line Item | B2: Type | C2: Unit | D2: What it is | E2: 2022 | F2: 2023 | G2: 2024 | H2: 2025 | I2: 2026 | J2: 2027 | K2: 2028 | L2: 2029 | M2: 2030 | N2: 2031 | O2: 2032
A3: REVENUE
A4: Booked revenue | B4: IN | C4: $M | D4: Anchor. 2022-26 PitchBook TTM (10/100/1,000/9,000/47,000); 2027-32 base case. PB carries 55,000 for 2027 as a conservative mark. | E4: 10 | F4: 85 | G4: 600 | H4: 4680 | I4: 23500 | J4: 57040 | K4: 100800 | L4: 152000 | M4: 208250 | N4: 264000 | O4: 319500
A5: API PRICING AND BLENDED EFFECTIVE RATE
A6: Model mix % - Mythos | B6: IN | C6: % | D6: Token share, flagship tier (Fable 5 / Mythos 5, $10/$50). Introduced 2026. | E6: 0 | F6: 0 | G6: 0 | H6: 0 | I6: 0.03 | J6: 0.05 | K6: 0.06 | L6: 0.07 | M6: 0.08 | N6: 0.09 | O6: 0.1
A7: Model mix % - Opus | B7: IN | C7: % | D7: Token share, Opus ($15/$75 to Aug-2025, cut to $5/$25 at Opus 4.5). | E7: 0 | F7: 0.1 | G7: 0.08 | H7: 0.1 | I7: 0.12 | J7: 0.12 | K7: 0.12 | L7: 0.12 | M7: 0.12 | N7: 0.12 | O7: 0.12
A8: Model mix % - Sonnet | B8: IN | C8: % | D8: Token share, Sonnet workhorse ($3/$15). | E8: 0.4 | F8: 0.3 | G8: 0.32 | H8: 0.45 | I8: 0.45 | J8: 0.44 | K8: 0.43 | L8: 0.42 | M8: 0.41 | N8: 0.4 | O8: 0.4
A9: Model mix % - Haiku | B9: IN | C9: % | D9: Token share, Haiku ($0.25/$1.25 -> $1/$5). | E9: 0.6 | F9: 0.6 | G9: 0.6 | H9: 0.45 | I9: 0.4 | J9: 0.39 | K9: 0.39 | L9: 0.39 | M9: 0.39 | N9: 0.39 | O9: 0.38
A10: List input $/Mtok - Mythos | B10: IN | C10: $ | D10: List input price, flagship. | E10: 15 | F10: 15 | G10: 15 | H10: 15 | I10: 15 | J10: 15 | K10: 14 | L10: 13 | M10: 12 | N10: 12 | O10: 11
A11: List input $/Mtok - Opus | B11: IN | C11: $ | D11: List input price, Opus. | E11: 11 | F11: 8 | G11: 15 | H11: 15 | I11: 5 | J11: 5 | K11: 5 | L11: 4.5 | M11: 4.5 | N11: 4 | O11: 4
A12: List input $/Mtok - Sonnet | B12: IN | C12: $ | D12: List input price, Sonnet. | E12: 3 | F12: 3 | G12: 3 | H12: 3 | I12: 3 | J12: 3 | K12: 3 | L12: 2.5 | M12: 2.5 | N12: 2 | O12: 2
A13: List input $/Mtok - Haiku | B13: IN | C13: $ | D13: List input price, Haiku. | E13: 0.8 | F13: 0.8 | G13: 0.25 | H13: 0.8 | I13: 1 | J13: 1 | K13: 1 | L13: 0.9 | M13: 0.9 | N13: 0.8 | O13: 0.8
