Workbook
Name __123Graph_B: #REF!
Name __123Graph_D: #REF!
Name _2_0__123Grap: #REF!
Name _4_0__123Grap: #REF!
Name _fff2: #REF!
Name _fff2: #REF!
Name _fff2: #REF!
Name _Fil1: #REF!
Name _Fill: #REF!
Name _ggg2: #REF!
Name _ggg2: #REF!
Name _ggg2: #REF!
Name _Key1: #REF!
Name _Key2: #REF!
Name _Key5: #REF!
Name _Key6: #REF!
Name _Key8: #REF!
Name _Key9: #REF!
Name _MRG2: #REF!
Name _MRG2: #REF!
Name _MRG2: #REF!
Name _Sort: #REF!
Name _Table2_In1: #REF!
Name _Table2_In2: #REF!
Name _Table2_Out: #REF!
Name a: #REF!
Name aaaaaa: #REF!
Name aaaaaaa: #REF!
Name aaaaaaa: #REF!
Name aaaaaaa: #REF!
Name aasdfa: #REF!
Name aasdfa: #REF!
Name aasdfa: #REF!
Name as: #REF!
Name as: #REF!
Name as: #REF!
Name asdfas: #REF!
Name asdfas: #REF!
Name asdfas: #REF!
Name asdfasaa: #REF!
Name asdfasaa: #REF!
Name asdfasaa: #REF!
Name asdfasdf: #REF!
Name asdfasdf: #REF!
Name asdfasdf: #REF!
Name asfag2: #REF!
Name asfag2: #REF!
Name asfag2: #REF!
Name asfasg: #REF!
Name asfasg: #REF!
Name asfasg: #REF!
Name ass: #REF!
Name ass: #REF!
Name ass: #REF!
Name asss: #REF!
Name asss: #REF!
Name asss: #REF!
Name az: #REF!
Name az: #REF!
Name az: #REF!

Sheet Cover
C11: SaaS Financial Model | M11: Strictly Confidential
C13: Table of Contents
C15: Monthly Schedule
C16: Financial Model
C31: © 2015 to 2024 CFI Education Inc.
C32: This Excel model is for educational purposes only and should not be used for any other reason. All content is Copyright material of CFI Education Inc.
C33: All rights reserved. The contents of this publication, including but not limited to all written material, content layout, images, formulas, and code, are protected
C34: under international copyright and trademark laws. No part of this publication may be modified, manipulated, reproduced, distributed, or transmitted in any
C35: form by any means, including photocopying, recording, or other electronic or mechanical methods, without prior written permission of the publisher,
C36: except in the case of certain noncommercial uses permitted by copyright law.
C38: https://corporatefinanceinstitute.com/

Sheet Monthly Schedule
B4: Assumptions
B6: Customer Churn rate | C6: 0.03
B7: Average months paid upfront | C7: 12
B8: Renewal rate | C8: 0.95
B9: ARPA (Average Revenue per Account per Month)- New Accounts | C9: 100
B11: Customer Churn rate | C11: 0.03
B12: Average months paid upfront | C12: 12
B13: Renewal rate | C13: 0.95
B14: ARPA (Average Revenue per Account per Month)- New Accounts | C14: 100
B16: Customer Churn rate | C16: 0.03
B17: Average months paid upfront | C17: 12
B18: Renewal rate | C18: 0.95
B19: ARPA (Average Revenue per Account per Month)- New Accounts | C19: 100
B21: 2017 | D21: 42736 | E21: =EDATE(D21,1) -> 42767 | F21: =EDATE(E21,1) -> 42795 | G21: =EDATE(F21,1) -> 42826 | H21: =EDATE(G21,1) -> 42856 | I21: =EDATE(H21,1) -> 42887 | J21: =EDATE(I21,1) -> 42917 | K21: =EDATE(J21,1) -> 42948 | L21: =EDATE(K21,1) -> 42979 | ... O21: =EDATE(N21,1) -> 43070
B22: Number of customer accounts
B23: Opening balance | D23: 100 | E23: =D26 -> 107 | F23: =E26 -> 113.79 | G23: =F26 -> 120.3763 | H23: =G26 -> 126.76501 | I23: =H26 -> 132.96206 | J23: =I26 -> 138.9732 | K23: =J26 -> 144.804 | L23: =K26 -> 150.45988 | ... O23: =N26 -> 166.42967
B24: New customer additions | D24: 10 | E24: 10 | F24: 10 | G24: 10 | H24: 10 | I24: 10 | J24: 10 | K24: 10 | L24: 10 | M24: 10 | N24: 10 | O24: 10
B25: Customer churn | D25: =-$C$16*D23 -> -3 | E25: =-$C$16*E23 -> -3.21 | F25: =-$C$16*F23 -> -3.4137 | G25: =-$C$16*G23 -> -3.611289 | H25: =-$C$16*H23 -> -3.8029503 | I25: =-$C$16*I23 -> -3.9888618 | J25: =-$C$16*J23 -> -4.169196 | K25: =-$C$16*K23 -> -4.3441201 | ... O25: =-$C$16*O23 -> -4.9928902
B26: Total number of customer accounts | D26: =SUM(D23:D25) -> 107 | E26: =SUM(E23:E25) -> 113.79 | F26: =SUM(F23:F25) -> 120.3763 | G26: =SUM(G23:G25) -> 126.76501 | H26: =SUM(H23:H25) -> 132.96206 | I26: =SUM(I23:I25) -> 138.9732 | J26: =SUM(J23:J25) -> 144.804 | K26: =SUM(K23:K25) -> 150.45988 | ... O26: =SUM(O23:O25) -> 171.43678
B28: MRR opening balance | D28: 10000 | E28: =D32 -> 10850 | F28: =E32 -> 11687.25 | G28: =F32 -> 12511.941 | H28: =G32 -> 13324.262 | I28: =H32 -> 14124.398 | J28: =I32 -> 14912.532 | K28: =J32 -> 15688.844 | L28: =K32 -> 16453.512 | ... O28: =N32 -> 18679.379
B29: New MRR | D29: =+D24*$C$19 -> 1000 | E29: =+E24*$C$19 -> 1000 | F29: =+F24*$C$19 -> 1000 | G29: =+G24*$C$19 -> 1000 | H29: =+H24*$C$19 -> 1000 | I29: =+I24*$C$19 -> 1000 | J29: =+J24*$C$19 -> 1000 | K29: =+K24*$C$19 -> 1000 | ... O29: =+O24*$C$19 -> 1000
B30: Churned MRR | D30: =+-D37*D28 -> -200 | E30: =+-E37*E28 -> -217 | F30: =+-F37*F28 -> -233.745 | G30: =+-G37*G28 -> -250.23882 | H30: =+-H37*H28 -> -266.48524 | I30: =+-I37*I28 -> -282.48796 | J30: =+-J37*J28 -> -298.25064 | K30: =+-K37*K28 -> -313.77688 | ... O30: =+-O37*O28 -> -373.58758
B31: Expansion MRR | D31: =+D38*D28 -> 50 | E31: =+E38*E28 -> 54.25 | F31: =+F38*F28 -> 58.43625 | G31: =+G38*G28 -> 62.559706 | H31: =+H38*H28 -> 66.621311 | I31: =+I38*I28 -> 70.621991 | J31: =+J38*J28 -> 74.562661 | K31: =+K38*K28 -> 78.444221 | ... O31: =+O38*O28 -> 93.396896
B32: Net MRR | D32: =SUM(D28:D31) -> 10850 | E32: =SUM(E28:E31) -> 11687.25 | F32: =SUM(F28:F31) -> 12511.941 | G32: =SUM(G28:G31) -> 13324.262 | H32: =SUM(H28:H31) -> 14124.398 | I32: =SUM(I28:I31) -> 14912.532 | J32: =SUM(J28:J31) -> 15688.844 | K32: =SUM(K28:K31) -> 16453.512 | ... O32: =SUM(O28:O31) -> 19399.188
B33: % growth | E33: =E32/D32-1 -> 0.077165899 | F33: =F32/E32-1 -> 0.070563328 | G33: =G32/F32-1 -> 0.064923649 | H33: =H32/G32-1 -> 0.06005106 | I33: =I32/H32-1 -> 0.055799477 | J33: =J32/I32-1 -> 0.052057692 | K33: =K32/J32-1 -> 0.048739558 | L33: =L32/K32-1 -> 0.045777299 | ... O33: =O32/N32-1 -> 0.03853497
B35: ARPA (Average Revenue per Account per Month) - across installed based | D35: =+D32/D26 -> 101.40187 | E35: =+E32/E26 -> 102.70894 | F35: =+F32/F26 -> 103.94024 | G35: =+G32/G26 -> 105.10994 | H35: =+H32/H26 -> 106.22879 | I35: =+I32/I26 -> 107.30509 | J35: =+J32/J26 -> 108.34538 | K35: =+K32/K26 -> 109.35481 | ... O35: =+O32/O26 -> 113.15651
B37: % MRR Churn Rate | D37: 0.02 | E37: 0.02 | F37: 0.02 | G37: 0.02 | H37: 0.02 | I37: 0.02 | J37: 0.02 | K37: 0.02 | L37: 0.02 | M37: 0.02 | N37: 0.02 | O37: 0.02
B38: % MRR Expansion Rate | D38: 0.005 | E38: 0.005 | F38: 0.005 | G38: 0.005 | H38: 0.005 | I38: 0.005 | J38: 0.005 | K38: 0.005 | L38: 0.005 | M38: 0.005 | N38: 0.005 | O38: 0.005
B39: % Net MRR Churn Rate | D39: =+(-D30-D31)/D28 -> 0.015 | E39: =+(-E30-E31)/E28 -> 0.015 | F39: =+(-F30-F31)/F28 -> 0.015 | G39: =+(-G30-G31)/G28 -> 0.015 | H39: =+(-H30-H31)/H28 -> 0.015 | I39: =+(-I30-I31)/I28 -> 0.015 | J39: =+(-J30-J31)/J28 -> 0.015 | K39: =+(-K30-K31)/K28 -> 0.015 | ... O39: =+(-O30-O31)/O28 -> 0.015
B41: Subscription billings | D41: =D29*$C$17 -> 12000 | E41: =E29*$C$17 -> 12000 | F41: =F29*$C$17 -> 12000 | G41: =G29*$C$17 -> 12000 | H41: =H29*$C$17 -> 12000 | I41: =I29*$C$17 -> 12000 | J41: =J29*$C$17 -> 12000 | K41: =K29*$C$17 -> 12000 | ... O41: =O29*$C$17 -> 12000
B43: Annualized run rate in 2017 | D43: =SUM(D32:O32) -> 182786.62
B44: Subscription billings in 2017 | D44: =SUM(D41:O41) -> 144000
B46: =B21+1 -> 2018 | D46: =EDATE(D21,12) -> 43101 | E46: =EDATE(E21,12) -> 43132 | F46: =EDATE(F21,12) -> 43160 | G46: =EDATE(G21,12) -> 43191 | H46: =EDATE(H21,12) -> 43221 | I46: =EDATE(I21,12) -> 43252 | J46: =EDATE(J21,12) -> 43282 | K46: =EDATE(K21,12) -> 43313 | ... O46: =EDATE(O21,12) -> 43435
B47: Number of customer accounts
B48: Opening balance | D48: =O26 -> 171.43678 | E48: =D51 -> 181.29368 | F48: =E51 -> 190.85487 | G48: =F51 -> 200.12922 | H48: =G51 -> 209.12535 | I48: =H51 -> 217.85159 | J48: =I51 -> 226.31604 | K48: =J51 -> 234.52656 | L48: =K51 -> 242.49076 | ... O48: =N51 -> 264.97827
B49: New customer additions | D49: 15 | E49: 15 | F49: 15 | G49: 15 | H49: 15 | I49: 15 | J49: 15 | K49: 15 | L49: 15 | M49: 15 | N49: 15 | O49: 15
B50: Customer churn | D50: =-$C$16*D48 -> -5.1431035 | E50: =-$C$16*E48 -> -5.4388104 | F50: =-$C$16*F48 -> -5.7256461 | G50: =-$C$16*G48 -> -6.0038767 | H50: =-$C$16*H48 -> -6.2737604 | I50: =-$C$16*I48 -> -6.5355476 | J50: =-$C$16*J48 -> -6.7894811 | K50: =-$C$16*K48 -> -7.0357967 | ... O50: =-$C$16*O48 -> -7.9493481
B51: Total number of customer accounts | D51: =SUM(D48:D50) -> 181.29368 | E51: =SUM(E48:E50) -> 190.85487 | F51: =SUM(F48:F50) -> 200.12922 | G51: =SUM(G48:G50) -> 209.12535 | H51: =SUM(H48:H50) -> 217.85159 | I51: =SUM(I48:I50) -> 226.31604 | J51: =SUM(J48:J50) -> 234.52656 | K51: =SUM(K48:K50) -> 242.49076 | ... O51: =SUM(O48:O50) -> 272.02892
B53: MRR opening balance | D53: =O32 -> 19399.188 | E53: =D57 -> 20608.201 | F53: =E57 -> 21799.078 | G53: =F57 -> 22972.091 | H53: =G57 -> 24127.51 | I53: =H57 -> 25265.597 | J53: =I57 -> 26386.613 | K53: =J57 -> 27490.814 | L53: =K57 -> 28578.452 | ... O53: =N57 -> 31744.453
B54: New MRR | D54: =D49*$C$19 -> 1500 | E54: =E49*$C$19 -> 1500 | F54: =F49*$C$19 -> 1500 | G54: =G49*$C$19 -> 1500 | H54: =H49*$C$19 -> 1500 | I54: =I49*$C$19 -> 1500 | J54: =J49*$C$19 -> 1500 | K54: =K49*$C$19 -> 1500 | ... O54: =O49*$C$19 -> 1500
...

Sheet Financial Model
B3: Other assumptions
D5: ='Monthly Schedule'!B21 -> 2017 | E5: =+D5+1 -> 2018 | F5: =+E5+1 -> 2019 | G5: =+F5+1 -> 2020 | H5: =+G5+1 -> 2021 | I5: =+H5+1 -> 2022
B7: Total number of customer accounts | D7: ='Monthly Schedule'!O26 -> 171.43678 | E7: ='Monthly Schedule'!O51 -> 272.02892 | F7: ='Monthly Schedule'!O76 -> 392.85028 | G7: ='Monthly Schedule'!O101 -> 527.70753 | H7: ='Monthly Schedule'!O126 -> 672.30348 | I7: ='Monthly Schedule'!O151 -> 823.65655
B9: Subscription billings | D9: ='Monthly Schedule'!D44 -> 144000 | E9: ='Monthly Schedule'!D69 -> 216000 | F9: ='Monthly Schedule'!D94 -> 333600 | G9: ='Monthly Schedule'!D119 -> 656400 | H9: ='Monthly Schedule'!D144 -> 865200 | I9: ='Monthly Schedule'!D169 -> 1117320
B10: Average bill size for professional services and other per account | D10: 50 | E10: 50 | F10: 50 | G10: 50 | H10: 50 | I10: 50
B11: Professional services and other billings | D11: =D10*D7 -> 8571.8391 | E11: =E10*E7 -> 13601.446 | F11: =F10*F7 -> 19642.514 | G11: =G10*G7 -> 26385.377 | H11: =H10*H7 -> 33615.174 | I11: =I10*I7 -> 41182.827
B12: Total billings | D12: =D9+D11 -> 152571.84 | E12: =E9+E11 -> 229601.45 | F12: =F9+F11 -> 353242.51 | G12: =G9+G11 -> 682785.38 | H12: =H9+H11 -> 898815.17 | I12: =I9+I11 -> 1158502.8
B14: Revenue
B16: Subscription revenue | D16: ='Monthly Schedule'!D43 -> 182786.62 | E16: ='Monthly Schedule'!D68 -> 322095.9 | F16: ='Monthly Schedule'!D93 -> 504645.43 | G16: ='Monthly Schedule'!D118 -> 723263.05 | H16: ='Monthly Schedule'!D143 -> 971966.2 | I16: ='Monthly Schedule'!D168 -> 1245764.7
B17: Professional services and other revenue | D17: =D11 -> 8571.8391 | E17: =E11 -> 13601.446 | F17: =F11 -> 19642.514 | G17: =G11 -> 26385.377 | H17: =H11 -> 33615.174 | I17: =I11 -> 41182.827
B19: Cost of revenue
B21: Cost of subscription revenue | D21: =+D22*D16 -> 27417.994 | E21: =+E22*E16 -> 48314.385 | F21: =+F22*F16 -> 75696.815 | G21: =+G22*G16 -> 108489.46 | H21: =+H22*H16 -> 145794.93 | I21: =+I22*I16 -> 186864.7
B22: % of subscription revenue | D22: 0.15 | E22: 0.15 | F22: 0.15 | G22: 0.15 | H22: 0.15 | I22: 0.15
B23: Cost of professional services and other revenue | D23: =+D24*D17 -> 7286.0633 | E23: =+E24*E17 -> 11561.229 | F23: =+F24*F17 -> 16696.137 | G23: =+G24*G17 -> 22427.57 | H23: =+H24*H17 -> 28572.898 | I23: =+I24*I17 -> 35005.403
B24: % of professional services and other revenue | D24: 0.85 | E24: 0.85 | F24: 0.85 | G24: 0.85 | H24: 0.85 | I24: 0.85
B26: Sales and marketing expenses
B28: Sales and marketing staff headcount | D28: 45 | E28: =+(E7-D7)/E29 -> 63.365763 | F28: =+(F7-E7)/F29 -> 76.108708 | G28: =+(G7-F7)/G29 -> 84.950303 | H28: =+(H7-G7)/H29 -> 91.084976 | I28: =+(I7-H7)/I29 -> 95.341472
B29: New accounts per headcount | D29: =+(D7-'Monthly Schedule'!$D$23)/D28 -> 1.5874841 | E29: =+D29 -> 1.5874841 | F29: =+E29 -> 1.5874841 | G29: =+F29 -> 1.5874841 | H29: =+G29 -> 1.5874841 | I29: =+H29 -> 1.5874841
B30: Salary (fixed component) | D30: 1000 | E30: 1000 | F30: 1000 | G30: 1000 | H30: 1000 | I30: 1000
B31: Fixed component of sales and marketing expenses | D31: =+D28*D30 -> 45000 | E31: =+E28*E30 -> 63365.763 | F31: =+F28*F30 -> 76108.708 | G31: =+G28*G30 -> 84950.303 | H31: =+H28*H30 -> 91084.976 | I31: =+I28*I30 -> 95341.472
B33: Commission rate | C33: 0.05
B34: Total commissions (including deferred portion) | D34: =+$C$33*D12 -> 7628.592 | E34: =+$C$33*E12 -> 11480.072 | F34: =+$C$33*F12 -> 17662.126 | G34: =+$C$33*G12 -> 34139.269 | H34: =+$C$33*H12 -> 44940.759 | I34: =+$C$33*I12 -> 57925.141
B35: Annual commission expense (excludes deferred portion) | D35: =$C$33*D16 -> 9139.3312 | E35: =$C$33*E16 -> 16104.795 | F35: =$C$33*F16 -> 25232.272 | G35: =$C$33*G16 -> 36163.152 | H35: =$C$33*H16 -> 48598.31 | I35: =$C$33*I16 -> 62288.233
B37: Total sales and marketing expense | D37: =+D35+D31 -> 54139.331 | E37: =+E35+E31 -> 79470.558 | F37: =+F35+F31 -> 101340.98 | G37: =+G35+G31 -> 121113.46 | H37: =+H35+H31 -> 139683.29 | I37: =+I35+I31 -> 157629.71
B39: Research and development expenses
B41: Research and development headcount | D41: 15 | E41: =D41+5 -> 20 | F41: =E41+5 -> 25 | G41: =F41+5 -> 30 | H41: =G41+5 -> 35 | I41: =H41+5 -> 40
B42: Salary (fixed component) | D42: 1500 | E42: 1500 | F42: 1500 | G42: 1500 | H42: 1500 | I42: 1500
B43: Personnel related research and development expense | D43: =+D41*D42 -> 22500 | E43: =+E41*E42 -> 30000 | F43: =+F41*F42 -> 37500 | G43: =+G41*G42 -> 45000 | H43: =+H41*H42 -> 52500 | I43: =+I41*I42 -> 60000
B44: Data center and infrastructure related costs | D44: 100 | E44: 100 | F44: 100 | G44: 100 | H44: 100 | I44: 100
B45: Total research and development expense | D45: =+D43+D44 -> 22600 | E45: =+E43+E44 -> 30100 | F45: =+F43+F44 -> 37600 | G45: =+G43+G44 -> 45100 | H45: =+H43+H44 -> 52600 | I45: =+I43+I44 -> 60100
B47: General and administrative expenses
B49: General and administrative headcount | D49: 8 | E49: =D49+1 -> 9 | F49: =E49+1 -> 10 | G49: =F49+1 -> 11 | H49: =G49+1 -> 12 | I49: =H49+1 -> 13
B50: Salary (fixed component) | D50: 1000 | E50: 1000 | F50: 1000 | G50: 1000 | H50: 1000 | I50: 1000
B51: Personnel related research and development expense | D51: =+D49*D50 -> 8000 | E51: =+E49*E50 -> 9000 | F51: =+F49*F50 -> 10000 | G51: =+G49*G50 -> 11000 | H51: =+H49*H50 -> 12000 | I51: =+I49*I50 -> 13000
B52: Rental expense and other | D52: 100 | E52: 100 | F52: 100 | G52: 100 | H52: 100 | I52: 100
B53: Total research and development expense | D53: =D51+D52 -> 8100 | E53: =E51+E52 -> 9100 | F53: =F51+F52 -> 10100 | G53: =G51+G52 -> 11100 | H53: =H51+H52 -> 12100 | I53: =I51+I52 -> 13100
B55: Balance sheet items
B57: Number of days in a year | C57: 365
B58: Current Assets
B59: Accounts Receivable Days (billings based) | D59: 45 | E59: 45 | F59: 45 | G59: 45 | H59: 45 | I59: 45
...
