Workbook

Sheet Cover
C4: Databricks, Inc.
C5: Three-Statement Operating Model
C6: Companion to: Brick by Brick, an institutional deep dive. July 10, 2026; updated July 21, 2026.
C7: All figures USD millions; fiscal years end January 31. FY2025A / FY2026A are estimates calibrated to disclosed run-rates; Databricks publishes no financial statements.
C10: Table of Contents
C11: Outputs | E11: Dashboard: summary statements, margins, charts
C12: Inputs | E12: Driver switch (Best / Base / Worst), sourced assumptions, opening balance sheet
C13: Model | E13: Income statement, cash flow, balance sheet + Schedules A-D
C14: Valuation | E14: Sensitivity grid, per-point pricing, growth-adjusted comparison
C16: Model Checks
C17: Balance sheet balanced in every year? | E17: =IF(AND(MAX(Outputs!E17:K17)<0.001,MIN(Outputs!E17:K17)>-0.001),"OK","ERROR")
C18: Scenario in use (1 Best / 2 Base / 3 Worst) | E18: =Inputs!E5
C19: FCF positive in FY2025A/FY2026A (disclosed fact)? | E19: =IF(AND(Model!E45>0,Model!F45>0),"OK","REVIEW")
C21: Sourcing: company press releases and disclosures (Sep 2024 to Jun 2026); PitchBook deal records (entity 59199-40, retrieved Jul 21, 2026); SEC EDGAR (CIK 1587468); public cloud price lists. All non-disclosed lines are labeled estimates.

Sheet Outputs
B2: Dashboard
B3: All figures USD millions unless stated; scenario per Inputs!E5 Driver Switch.
B5: All figures in USD millions unless stated | E5: FY2025A | F5: FY2026A | G5: FY2027E | H5: FY2028E | I5: FY2029E | J5: FY2030E | K5: FY2031E
B6: Revenue | E6: =Model!E9 | F6: =Model!F9 | G6: =Model!G9 | H6: =Model!H9 | I6: =Model!I9 | J6: =Model!J9 | K6: =Model!K9
B7: Revenue growth | E7: =Model!E8 | F7: =Model!F8 | G7: =Model!G8 | H7: =Model!H8 | I7: =Model!I8 | J7: =Model!J8 | K7: =Model!K8
B8: Gross margin | E8: =Model!E10 | F8: =Model!F10 | G8: =Model!G10 | H8: =Model!H10 | I8: =Model!I10 | J8: =Model!J10 | K8: =Model!K10
B9: EBITDA | E9: =Model!E20 | F9: =Model!F20 | G9: =Model!G20 | H9: =Model!H20 | I9: =Model!I20 | J9: =Model!J20 | K9: =Model!K20
B10: EBIT | E10: =Model!E19 | F10: =Model!F19 | G10: =Model!G19 | H10: =Model!H19 | I10: =Model!I19 | J10: =Model!J19 | K10: =Model!K19
B11: Net income | E11: =Model!E26 | F11: =Model!F26 | G11: =Model!G26 | H11: =Model!H26 | I11: =Model!I26 | J11: =Model!J26 | K11: =Model!K26
B12: Free cash flow | E12: =Model!E45 | F12: =Model!F45 | G12: =Model!G45 | H12: =Model!H45 | I12: =Model!I45 | J12: =Model!J45 | K12: =Model!K45
B13: FCF margin | E13: =Model!E46 | F13: =Model!F46 | G13: =Model!G46 | H13: =Model!H46 | I13: =Model!I46 | J13: =Model!J46 | K13: =Model!K46
B14: Cash & investments (closing) | E14: =Model!E49 | F14: =Model!F49 | G14: =Model!G49 | H14: =Model!H49 | I14: =Model!I49 | J14: =Model!J49 | K14: =Model!K49
B15: Debt (closing) | E15: =Model!E58 | F15: =Model!F58 | G15: =Model!G58 | H15: =Model!H58 | I15: =Model!I58 | J15: =Model!J58 | K15: =Model!K58
B16: Deferred revenue (closing) | E16: =Model!E56 | F16: =Model!F56 | G16: =Model!G56 | H16: =Model!H56 | I16: =Model!I56 | J16: =Model!J56 | K16: =Model!K56
B17: Balance sheet check (0 = balanced) | E17: =Model!E64 | F17: =Model!F64 | G17: =Model!G64 | H17: =Model!H64 | I17: =Model!I64 | J17: =Model!J64 | K17: =Model!K64

Sheet Inputs
B2: Drivers and Assumptions
B3: Every assumption carries its source in column M. Estimates are labeled; Databricks is private and discloses no audited financials.
B5: Driver Switch (1 = Best, 2 = Base, 3 = Worst) | E5: 2 | M5: Scenario flexes revenue growth and gross margin only; cost ratios below are held.
B7: All figures in USD millions unless stated | E7: FY2025A | F7: FY2026A | G7: FY2027E | H7: FY2028E | I7: FY2029E | J7: FY2030E | K7: FY2031E
B8: Revenue growth, year over year (historical years fixed)
B9: Revenue growth - Best | E9: 0.59 | F9: 0.588 | G9: 0.85 | H9: 0.62 | I9: 0.45 | J9: 0.34 | K9: 0.27
B10: Revenue growth - Base | E10: 0.59 | F10: 0.588 | G10: 0.77 | H10: 0.57 | I10: 0.4 | J10: 0.3 | K10: 0.24 | M10: Calibrated to disclosed run-rate ladder: $4.0B/+50% Sep-25, $4.8B/+55% Dec-25, $5.4B/+65% Feb-26, $6.9B/+80% Jun-26 (company press releases; company disclosure Jun 16, 2026). Base decelerates gracefully; NRR >140% alone sustains ~40%+ (company, Feb 9, 2026).
B11: Revenue growth - Worst | E11: 0.59 | F11: 0.588 | G11: 0.55 | H11: 0.38 | I11: 0.26 | J11: 0.18 | K11: 0.14
B13: Gross margin
B14: Gross margin - Best | E14: 0.8 | F14: 0.78 | G14: 0.745 | H14: 0.74 | I14: 0.745 | J14: 0.75 | K14: 0.755
B15: Gross margin - Base | E15: 0.8 | F15: 0.78 | G15: 0.735 | H15: 0.725 | I15: 0.73 | J15: 0.735 | K15: 0.74 | M15: 74% at Jun-2026, down from >80%, guided lower on agentic compute (company disclosure, Jun 16, 2026). Base holds above the 70% quality gate; Worst breaks it in FY2028E.
B16: Gross margin - Worst | E16: 0.8 | F16: 0.78 | G16: 0.71 | H16: 0.695 | I16: 0.69 | J16: 0.695 | K16: 0.7
B18: Operating cost ratios, % of revenue (single path)
B19: R&D (ex-SBC) | E19: 0.2 | F19: 0.19 | G19: 0.18 | H19: 0.175 | I19: 0.17 | J19: 0.165 | K19: 0.16 | M19: Estimate; benchmarked to public consumption-software comps at similar scale (no company disclosure).
B20: Sales & marketing (ex-SBC) | E20: 0.36 | F20: 0.33 | G20: 0.3 | H20: 0.28 | I20: 0.26 | J20: 0.245 | K20: 0.23 | M20: Estimate; consumption billing lowers S&M intensity as expansion is product-driven (NRR >140%, company, Feb 9, 2026).
B21: General & administrative (ex-SBC) | E21: 0.08 | F21: 0.075 | G21: 0.07 | H21: 0.065 | I21: 0.06 | J21: 0.055 | K21: 0.05 | M21: Estimate; scale leverage typical of late-stage software.
B22: Stock-based compensation | E22: 0.24 | F22: 0.22 | G22: 0.19 | H22: 0.17 | I22: 0.155 | J22: 0.14 | K22: 0.13 | M22: Estimate; company runs recurring employee tender programs (Series J use of proceeds, Dec 2024). Public comps at IPO ran 20%+ of revenue.
B23: Depreciation & amortization | E23: 0.02 | F23: 0.02 | G23: 0.02 | H23: 0.02 | I23: 0.02 | J23: 0.02 | K23: 0.02 | M23: Estimate; asset-light (compute rented from hyperscalers).
B24: Capital expenditure | E24: 0.025 | F24: 0.025 | G24: 0.025 | H24: 0.025 | I24: 0.025 | J24: 0.025 | K24: 0.025 | M24: Estimate; asset-light model.
B26: Working capital, balance sheet and other
B27: Days sales outstanding (days) | E27: 80 | F27: 80 | G27: 80 | H27: 80 | I27: 80 | J27: 80 | K27: 80 | M27: Estimate; enterprise annual invoicing.
B28: Deferred revenue (days of revenue) | E28: 100 | F28: 100 | G28: 100 | H28: 100 | I28: 100 | J28: 100 | K28: 100 | M28: Estimate; committed-use contracts are prepaid then drawn down (company pricing model).
B29: Interest rate on debt | E29: 0.0675 | F29: 0.0675 | G29: 0.0675 | H29: 0.0675 | I29: 0.0675 | J29: 0.0675 | K29: 0.0675 | M29: Estimate; ~$9.3B private facilities led by major banks, Jan 2025 to Feb 2026 (PitchBook deal records).
B30: Yield on cash | E30: 0.04 | F30: 0.04 | G30: 0.04 | H30: 0.04 | I30: 0.04 | J30: 0.04 | K30: 0.04 | M30: Estimate; short-duration treasury yields.
B31: Effective tax rate (on positive EBT) | E31: 0 | F31: 0 | G31: 0 | H31: 0.08 | I31: 0.08 | J31: 0.18 | K31: 0.18 | M31: Estimate; NOL shield from accumulated losses, stepping up as it exhausts.
B33: Financing events (announced; USD millions)
B34: Equity issuance | E34: 10060 | F34: 5000 | G34: 1000 | H34: 0 | I34: 0 | J34: 0 | K34: 0 | M34: Series J $10.1B Dec-2024 ($62B post); Series K $1.0B Sep-2025 (>$100B); Series L $5.0B equity across Dec-2025/Feb-2026 closes ($134B). Company press releases; PitchBook.
B35: Debt drawn | E35: 5420 | F35: 1854 | G35: 2000 | H35: 0 | I35: 0 | J35: 0 | K35: 0 | M35: $5.25B facility Jan-2025; $1.8B addition + $54M refi Jan-2026; $2.0B Series L tranche Feb-2026; ~$170M Series J embedded (PitchBook deal records).
B36: Employee liquidity / tender programs (est.) | E36: -6000 | F36: -2000 | G36: -4000 | H36: -1000 | I36: -1000 | J36: -1000 | K36: -1000 | M36: Estimate; Series J and the reported next round are explicitly tied to employee liquidity (company statements, Dec 2024; press reports, Jun 2026).
B37: Acquisitions & strategic investments (est.) | E37: -300 | F37: -1200 | G37: -1500 | H37: -1000 | I37: -1000 | J37: -1000 | K37: -1000 | M37: Estimate of cash portion; ~19 acquisitions to date incl. MosaicML 2023, Tabular 2024, Neon 2025, Panther announced Jun 16, 2026 (terms undisclosed).
B39: Opening balance sheet, Feb 1, 2024 (estimated; no company disclosure)
B40: Cash & investments | E40: 1500
B41: Accounts receivable | E41: 400
B42: PP&E, net | E42: 300
B43: Goodwill & intangibles | E43: 2600
B44: Other assets | E44: 250
B45: Deferred revenue | E45: 700
B46: Other liabilities | E46: 250
B47: Debt | E47: 0
B48: Paid-in capital (incl. accumulated SBC) | E48: 6000
...

Sheet Model
B2: Model: Income Statement, Cash Flow, Balance Sheet
B3: FY ends January 31. FY2025A and FY2026A are estimates calibrated to disclosed run-rates (company does not publish financial statements).
B5: All figures in USD millions unless stated | E5: FY2025A | F5: FY2026A | G5: FY2027E | H5: FY2028E | I5: FY2029E | J5: FY2030E | K5: FY2031E
B7: INCOME STATEMENT
B8: Revenue growth | E8: =CHOOSE(Inputs!$E$5,Inputs!E9,Inputs!E10,Inputs!E11) | F8: =CHOOSE(Inputs!$E$5,Inputs!F9,Inputs!F10,Inputs!F11) | G8: =CHOOSE(Inputs!$E$5,Inputs!G9,Inputs!G10,Inputs!G11) | H8: =CHOOSE(Inputs!$E$5,Inputs!H9,Inputs!H10,Inputs!H11) | I8: =CHOOSE(Inputs!$E$5,Inputs!I9,Inputs!I10,Inputs!I11) | J8: =CHOOSE(Inputs!$E$5,Inputs!J9,Inputs!J10,Inputs!J11) | K8: =CHOOSE(Inputs!$E$5,Inputs!K9,Inputs!K10,Inputs!K11) | M8: Scenario via Driver Switch; see Inputs for calibration sources.
B9: Revenue | E9: 2550 | F9: 4050 | G9: =F9*(1+G8) | H9: =G9*(1+H8) | I9: =H9*(1+I8) | J9: =I9*(1+J8) | K9: =J9*(1+K8) | M9: FY25A/FY26A estimated from run-rate ladder: revenue approx. average of opening and closing annualized run-rate (company press releases, Sep 2024 to Feb 2026).
B10: Gross margin % | E10: =CHOOSE(Inputs!$E$5,Inputs!E14,Inputs!E15,Inputs!E16) | F10: =CHOOSE(Inputs!$E$5,Inputs!F14,Inputs!F15,Inputs!F16) | G10: =CHOOSE(Inputs!$E$5,Inputs!G14,Inputs!G15,Inputs!G16) | H10: =CHOOSE(Inputs!$E$5,Inputs!H14,Inputs!H15,Inputs!H16) | I10: =CHOOSE(Inputs!$E$5,Inputs!I14,Inputs!I15,Inputs!I16) | J10: =CHOOSE(Inputs!$E$5,Inputs!J14,Inputs!J15,Inputs!J16) | K10: =CHOOSE(Inputs!$E$5,Inputs!K14,Inputs!K15,Inputs!K16) | M10: 74% Jun-2026, guided lower (company disclosure, Jun 16, 2026).
B11: Cost of revenue | E11: =-E9*(1-E10) | F11: =-F9*(1-F10) | G11: =-G9*(1-G10) | H11: =-H9*(1-H10) | I11: =-I9*(1-I10) | J11: =-J9*(1-J10) | K11: =-K9*(1-K10)
B12: Gross profit | E12: =E9+E11 | F12: =F9+F11 | G12: =G9+G11 | H12: =H9+H11 | I12: =I9+I11 | J12: =J9+J11 | K12: =K9+K11
B14: R&D (ex-SBC) | E14: =-E9*Inputs!E19 | F14: =-F9*Inputs!F19 | G14: =-G9*Inputs!G19 | H14: =-H9*Inputs!H19 | I14: =-I9*Inputs!I19 | J14: =-J9*Inputs!J19 | K14: =-K9*Inputs!K19
B15: Sales & marketing (ex-SBC) | E15: =-E9*Inputs!E20 | F15: =-F9*Inputs!F20 | G15: =-G9*Inputs!G20 | H15: =-H9*Inputs!H20 | I15: =-I9*Inputs!I20 | J15: =-J9*Inputs!J20 | K15: =-K9*Inputs!K20
B16: General & administrative (ex-SBC) | E16: =-E9*Inputs!E21 | F16: =-F9*Inputs!F21 | G16: =-G9*Inputs!G21 | H16: =-H9*Inputs!H21 | I16: =-I9*Inputs!I21 | J16: =-J9*Inputs!J21 | K16: =-K9*Inputs!K21
B17: Stock-based compensation | E17: =-E9*Inputs!E22 | F17: =-F9*Inputs!F22 | G17: =-G9*Inputs!G22 | H17: =-H9*Inputs!H22 | I17: =-I9*Inputs!I22 | J17: =-J9*Inputs!J22 | K17: =-K9*Inputs!K22
B18: Depreciation & amortization | E18: =-E9*Inputs!E23 | F18: =-F9*Inputs!F23 | G18: =-G9*Inputs!G23 | H18: =-H9*Inputs!H23 | I18: =-I9*Inputs!I23 | J18: =-J9*Inputs!J23 | K18: =-K9*Inputs!K23
B19: EBIT (GAAP basis, est.) | E19: =E12+SUM(E14:E18) | F19: =F12+SUM(F14:F18) | G19: =G12+SUM(G14:G18) | H19: =H12+SUM(H14:H18) | I19: =I12+SUM(I14:I18) | J19: =J12+SUM(J14:J18) | K19: =K12+SUM(K14:K18)
B20: EBITDA | E20: =E19-E18 | F20: =F19-F18 | G20: =G19-G18 | H20: =H19-H18 | I20: =I19-I18 | J20: =J19-J18 | K20: =K19-K18
B22: Interest expense (on opening debt) | E22: =-Inputs!$E$47*Inputs!E29 | F22: =-E58*Inputs!F29 | G22: =-F58*Inputs!G29 | H22: =-G58*Inputs!H29 | I22: =-H58*Inputs!I29 | J22: =-I58*Inputs!J29 | K22: =-J58*Inputs!K29 | M22: Convention: interest on opening balances avoids circularity.
B23: Interest income (on opening cash) | E23: =Inputs!$E$40*Inputs!E30 | F23: =E49*Inputs!F30 | G23: =F49*Inputs!G30 | H23: =G49*Inputs!H30 | I23: =H49*Inputs!I30 | J23: =I49*Inputs!J30 | K23: =J49*Inputs!K30
B24: Pre-tax income | E24: =E19+E22+E23 | F24: =F19+F22+F23 | G24: =G19+G22+G23 | H24: =H19+H22+H23 | I24: =I19+I22+I23 | J24: =J19+J22+J23 | K24: =K19+K22+K23
B25: Tax | E25: =-MAX(E24,0)*Inputs!E31 | F25: =-MAX(F24,0)*Inputs!F31 | G25: =-MAX(G24,0)*Inputs!G31 | H25: =-MAX(H24,0)*Inputs!H31 | I25: =-MAX(I24,0)*Inputs!I31 | J25: =-MAX(J24,0)*Inputs!J31 | K25: =-MAX(K24,0)*Inputs!K31
B26: Net income | E26: =E24+E25 | F26: =F24+F25 | G26: =G24+G25 | H26: =H24+H25 | I26: =I24+I25 | J26: =J24+J25 | K26: =K24+K25
B28: CASH FLOW STATEMENT
B29: Net income | E29: =E26 | F29: =F26 | G29: =G26 | H29: =H26 | I29: =I26 | J29: =J26 | K29: =K26
B30: Add back: D&A | E30: =-E18 | F30: =-F18 | G30: =-G18 | H30: =-H18 | I30: =-I18 | J30: =-J18 | K30: =-K18
B31: Add back: SBC | E31: =-E17 | F31: =-F17 | G31: =-G17 | H31: =-H17 | I31: =-I17 | J31: =-J17 | K31: =-K17
B32: Change in accounts receivable | E32: =-(E50-Inputs!$E$41) | F32: =-(F50-E50) | G32: =-(G50-F50) | H32: =-(H50-G50) | I32: =-(I50-H50) | J32: =-(J50-I50) | K32: =-(K50-J50)
B33: Change in deferred revenue | E33: =E56-Inputs!$E$45 | F33: =F56-E56 | G33: =G56-F56 | H33: =H56-G56 | I33: =I56-H56 | J33: =J56-I56 | K33: =K56-J56
B34: Cash from operations | E34: =SUM(E29:E33) | F34: =SUM(F29:F33) | G34: =SUM(G29:G33) | H34: =SUM(H29:H33) | I34: =SUM(I29:I33) | J34: =SUM(J29:J33) | K34: =SUM(K29:K33)
B36: Capital expenditure | E36: =-E9*Inputs!E24 | F36: =-F9*Inputs!F24 | G36: =-G9*Inputs!G24 | H36: =-H9*Inputs!H24 | I36: =-I9*Inputs!I24 | J36: =-J9*Inputs!J24 | K36: =-K9*Inputs!K24
B37: Acquisitions & strategic investments (est.) | E37: =Inputs!E37 | F37: =Inputs!F37 | G37: =Inputs!G37 | H37: =Inputs!H37 | I37: =Inputs!I37 | J37: =Inputs!J37 | K37: =Inputs!K37
B38: Cash from investing | E38: =SUM(E36:E37) | F38: =SUM(F36:F37) | G38: =SUM(G36:G37) | H38: =SUM(H36:H37) | I38: =SUM(I36:I37) | J38: =SUM(J36:J37) | K38: =SUM(K36:K37)
B40: Equity issuance | E40: =Inputs!E34 | F40: =Inputs!F34 | G40: =Inputs!G34 | H40: =Inputs!H34 | I40: =Inputs!I34 | J40: =Inputs!J34 | K40: =Inputs!K34
B41: Debt drawn | E41: =Inputs!E35 | F41: =Inputs!F35 | G41: =Inputs!G35 | H41: =Inputs!H35 | I41: =Inputs!I35 | J41: =Inputs!J35 | K41: =Inputs!K35
B42: Employee liquidity / tenders (est.) | E42: =Inputs!E36 | F42: =Inputs!F36 | G42: =Inputs!G36 | H42: =Inputs!H36 | I42: =Inputs!I36 | J42: =Inputs!J36 | K42: =Inputs!K36
B43: Cash from financing | E43: =SUM(E40:E42) | F43: =SUM(F40:F42) | G43: =SUM(G40:G42) | H43: =SUM(H40:H42) | I43: =SUM(I40:I42) | J43: =SUM(J40:J42) | K43: =SUM(K40:K42)
B44: Change in cash | E44: =E34+E38+E43 | F44: =F34+F38+F43 | G44: =G34+G38+G43 | H44: =H34+H38+H43 | I44: =I34+I38+I43 | J44: =J34+J38+J43 | K44: =K34+K38+K43
B45: Free cash flow (CFO + capex) | E45: =E34+E36 | F45: =F34+F36 | G45: =G34+G36 | H45: =H34+H36 | I45: =I34+I36 | J45: =J34+J36 | K45: =K34+K36 | M45: Company confirms FCF positive on TTM and FY2025 bases without magnitude (Feb 9, 2026); level shown is a model output, not a disclosure.
B46: FCF margin | E46: =E45/E9 | F46: =F45/F9 | G46: =G45/G9 | H46: =H45/H9 | I46: =I45/I9 | J46: =J45/J9 | K46: =K45/K9
B48: BALANCE SHEET (closing)
B49: Cash & investments | E49: =Inputs!$E$40+E44 | F49: =E49+F44 | G49: =F49+G44 | H49: =G49+H44 | I49: =H49+I44 | J49: =I49+J44 | K49: =J49+K44
...

Sheet Valuation
B2: Valuation
B3: Anchored on the completed $134B mark (Feb 9, 2026). The announced $188B round (signed Jul 16, 2026, unclosed) is a reference, not an input. The quality-valuation correlation is embargoed; only the per-point spread is expressed.
B5: Sensitivity: implied valuation ($B) = mid-2027E run-rate x multiple
B6: Multiple \ Run-rate ($B) | C6: 9.5 | D6: 10.5 | E6: 11.5 | F6: 12.5 | G6: 13.5
B7: 20 | C7: =C$6*$B7 | D7: =D$6*$B7 | E7: =E$6*$B7 | F7: =F$6*$B7 | G7: =G$6*$B7
B8: 18 | C8: =C$6*$B8 | D8: =D$6*$B8 | E8: =E$6*$B8 | F8: =F$6*$B8 | G8: =G$6*$B8
B9: 16 | C9: =C$6*$B9 | D9: =D$6*$B9 | E9: =E$6*$B9 | F9: =F$6*$B9 | G9: =G$6*$B9
B10: 14 | C10: =C$6*$B10 | D10: =D$6*$B10 | E10: =E$6*$B10 | F10: =F$6*$B10 | G10: =G$6*$B10
B11: 12 | C11: =C$6*$B11 | D11: =D$6*$B11 | E11: =E$6*$B11 | F11: =F$6*$B11 | G11: =G$6*$B11
B12: 10 | C12: =C$6*$B12 | D12: =D$6*$B12 | E12: =E$6*$B12 | F12: =F$6*$B12 | G12: =G$6*$B12
B13: Green: base intersection (~$11.5B at 14-16x, a de-rate from today's 19.4x). Bear $115-130B; Bull $205B+.
B15: Quality-adjusted pricing (per-point; the only cleared expression)
B16: Company | C16: Mark ($B) | D16: AIBQ | E16: $B per point
B17: Databricks | C17: 134 | D17: 8.81 | E17: =C17/D17
B18: Anthropic | C18: 965 | D18: 8.2 | E18: =C18/D18
B19: OpenAI | C19: 852 | D19: 4.53 | E19: =C19/D19
B20: xAI (implied, est.) | C20: 1550 | D20: 4.49 | E20: =C20/D20
B21: Marks per company announcements / PitchBook, Mar-Jul 2026; xAI slice inside listed SpaceX is an estimate. No correlation statistic is computed or derivable from this table.
B23: Growth-adjusted comparison
C24: EV / mark ($B) | D24: Fwd revenue ($B) | E24: Multiple | F24: Growth | G24: x per growth pt
B25: Databricks | C25: 134 | D25: 6.9 | E25: =C25/D25 | F25: 0.8 | G25: =E25/(F25*100)
B26: Snowflake | C26: 89 | D26: 5.84 | E26: =C26/D26 | F26: 0.31 | G26: =E26/(F26*100)
B27: Snowflake: FY27 product revenue guide raised May 27, 2026 (8-K); EV from market data less est. net cash, Jul 7, 2026. Growth-adjusted, the buyer pays ~half as much per point of growth for Databricks.
