Workbook

Sheet Cover
C4: Databricks, Inc.
C5: Granular Bottom-Up Operating Model
C6: FY2022A to FY2032E | revenue and costs built from the ground up | USD millions, fiscal year ends January 31
C7: Prepared by Harrison Rolfes, Senior Research Director. July 21, 2026. Companion to Brick by Brick.
C10: Contents
C11: Guide | E11: Plain-English map of how revenue and costs are built
C12: Assumptions | E12: Every driver, sourced; the one orange scenario switch; blue input cells
C13: Revenue | E13: Product-line build, plus customer-tier and DBU-consumption cross-checks
C14: Costs | E14: Cost of revenue by component (margin is an output); opex decomposed; headcount bridge
C15: Financials | E15: Income statement, cash flow, balance sheet, balance check
C16: KPIs | E16: Growth, margins, Rule of 40, revenue per head, capital efficiency
C18: Model checks
C19: Balance sheet balanced every year? | D19: =IF(AND(MAX(Financials!D56:N56)<0.001,MIN(Financials!D56:N56)>-0.001),"OK","ERROR")
C20: Revenue ties to product-line sum? | D20: =IF(ABS(Revenue!N12-SUM(Revenue!N7:Revenue!N11))<0.01,"OK","ERROR")
C21: Scenario in use (1 Best / 2 Base / 3 Worst) | D21: =Assumptions!D5
C23: Sources: company press releases and disclosures (2021 to Jun 2026); PitchBook deal records (entity 59199-40, retrieved Jul 21, 2026); SEC EDGAR (CIK 1587468); public cloud price lists. Not investment advice; private-company figures are estimates unless disclosed.

Sheet Dashboard
B2: Databricks | Model Dashboard
B3: One-page read-through of the granular model. Base case unless the scenario switch is changed. USD millions unless stated. Every figure is a live link.
B5: Scenario in use | C5: =CHOOSE(Assumptions!D5,"Best","Base","Worst") | D5: (change on the Assumptions tab, cell D5)
B7: Headline metrics
C8: FY2026A | D8: FY2027E | E8: FY2032E
B9: Revenue | C9: =Financials!H7 | D9: =Financials!I7 | E9: =Financials!N7
B10: Revenue growth (YoY) | C10: =Financials!H7/Financials!G7-1 | D10: =Financials!I7/Financials!H7-1 | E10: =Financials!N7/Financials!M7-1
B11: Gross margin | C11: =Financials!H9/Financials!H7 | D11: =Financials!I9/Financials!I7 | E11: =Financials!N9/Financials!N7
B12: Operating (EBIT) margin | C12: =Financials!H16/Financials!H7 | D12: =Financials!I16/Financials!I7 | E12: =Financials!N16/Financials!N7
B13: Net income (GAAP est.) | C13: =Financials!H22 | D13: =Financials!I22 | E13: =Financials!N22
B14: Free cash flow | C14: =Financials!H39 | D14: =Financials!I39 | E14: =Financials!N39
B15: FCF margin | C15: =Financials!H39/Financials!H7 | D15: =Financials!I39/Financials!I7 | E15: =Financials!N39/Financials!N7
B16: Rule of 40 (growth + FCF margin) | C16: =(Financials!H7/Financials!G7-1)+Financials!H39/Financials!H7 | D16: =(Financials!I7/Financials!H7-1)+Financials!I39/Financials!I7 | E16: =(Financials!N7/Financials!M7-1)+Financials!N39/Financials!N7
B17: Implied headcount (year end) | C17: =Costs!H39 | D17: =Costs!I39 | E17: =Costs!N39
B18: Revenue per head (USD 000) | C18: =Costs!H7*1000/Costs!H39 | D18: =Costs!I7*1000/Costs!I39 | E18: =Costs!N7*1000/Costs!N39
B19: Customers >$1M / yr | C19: =Assumptions!H62+Assumptions!H64 | D19: =Assumptions!I62+Assumptions!I64 | E19: =Assumptions!N62+Assumptions!N64 | G19: 300+ Sep-2023, 500+ Dec-2024, 800+ Feb-2026 (company).
B20: Cash and investments (close) | C20: =Financials!H43 | D20: =Financials!I43 | E20: =Financials!N43
B21: Debt (close) | C21: =Financials!H51 | D21: =Financials!I51 | E21: =Financials!N51
B23: Where revenue comes from (product line)
C24: FY2026A $ / % | D24: FY2027E $ / % | E24: FY2032E $ / %
B25: Core | C25: =TEXT(Revenue!H7,"#,##0")&" ("&TEXT(Revenue!H7/Revenue!H12,"0%")&")" | D25: =TEXT(Revenue!I7,"#,##0")&" ("&TEXT(Revenue!I7/Revenue!I12,"0%")&")" | E25: =TEXT(Revenue!N7,"#,##0")&" ("&TEXT(Revenue!N7/Revenue!N12,"0%")&")"
B26: SQL | C26: =TEXT(Revenue!H8,"#,##0")&" ("&TEXT(Revenue!H8/Revenue!H12,"0%")&")" | D26: =TEXT(Revenue!I8,"#,##0")&" ("&TEXT(Revenue!I8/Revenue!I12,"0%")&")" | E26: =TEXT(Revenue!N8,"#,##0")&" ("&TEXT(Revenue!N8/Revenue!N12,"0%")&")"
B27: AI | C27: =TEXT(Revenue!H9,"#,##0")&" ("&TEXT(Revenue!H9/Revenue!H12,"0%")&")" | D27: =TEXT(Revenue!I9,"#,##0")&" ("&TEXT(Revenue!I9/Revenue!I12,"0%")&")" | E27: =TEXT(Revenue!N9,"#,##0")&" ("&TEXT(Revenue!N9/Revenue!N12,"0%")&")"
B28: Lakebase | C28: =TEXT(Revenue!H10,"#,##0")&" ("&TEXT(Revenue!H10/Revenue!H12,"0%")&")" | D28: =TEXT(Revenue!I10,"#,##0")&" ("&TEXT(Revenue!I10/Revenue!I12,"0%")&")" | E28: =TEXT(Revenue!N10,"#,##0")&" ("&TEXT(Revenue!N10/Revenue!N12,"0%")&")"
B29: Platform | C29: =TEXT(Revenue!H11,"#,##0")&" ("&TEXT(Revenue!H11/Revenue!H12,"0%")&")" | D29: =TEXT(Revenue!I11,"#,##0")&" ("&TEXT(Revenue!I11/Revenue!I12,"0%")&")" | E29: =TEXT(Revenue!N11,"#,##0")&" ("&TEXT(Revenue!N11/Revenue!N12,"0%")&")"
B30: Total revenue | C30: =Revenue!H12 | D30: =Revenue!I12 | E30: =Revenue!N12
B32: Margin path (for chart) | D32: FY2022A | E32: FY2023A | F32: FY2024A | G32: FY2025A | H32: FY2026A | I32: FY2027E | J32: FY2028E | K32: FY2029E | L32: FY2030E | M32: FY2031E | N32: FY2032E
B33: Gross margin | D33: =Financials!D9/Financials!D7 | E33: =Financials!E9/Financials!E7 | F33: =Financials!F9/Financials!F7 | G33: =Financials!G9/Financials!G7 | H33: =Financials!H9/Financials!H7 | I33: =Financials!I9/Financials!I7 | J33: =Financials!J9/Financials!J7 | K33: =Financials!K9/Financials!K7 | ... N33: =Financials!N9/Financials!N7
B34: Operating margin | D34: =Financials!D16/Financials!D7 | E34: =Financials!E16/Financials!E7 | F34: =Financials!F16/Financials!F7 | G34: =Financials!G16/Financials!G7 | H34: =Financials!H16/Financials!H7 | I34: =Financials!I16/Financials!I7 | J34: =Financials!J16/Financials!J7 | K34: =Financials!K16/Financials!K7 | ... N34: =Financials!N16/Financials!N7
B35: FCF margin | D35: =Financials!D39/Financials!D7 | E35: =Financials!E39/Financials!E7 | F35: =Financials!F39/Financials!F7 | G35: =Financials!G39/Financials!G7 | H35: =Financials!H39/Financials!H7 | I35: =Financials!I39/Financials!I7 | J35: =Financials!J39/Financials!J7 | K35: =Financials!K39/Financials!K7 | ... N35: =Financials!N39/Financials!N7

Sheet Guide
B2: How this model is built
B5: The one-line logic
B6: Revenue is built bottom-up from five product lines and summed. Costs are built bottom-up from their components, so gross margin and operating margin fall out as results, not inputs. The three statements then assemble from those two builds and balance to zero every year.
B7: Where revenue comes from (Revenue tab)
B8: 1. Product line (primary): Data engineering / core compute, Databricks SQL, AI products (Mosaic AI), Lakebase, and Platform / other. Each is anchored to disclosed run-rates through FY2027E, then grows at a scenario-driven rate. The five sum to total revenue.
B9: 2. Customer tier (cross-check): the same total split across customers above $10M a year, $1-10M, and the long tail. The top two tiers are anchored to disclosed counts (300+ above $1M in 2023, 800+ by 2026); the long-tail average spend is the implied residual.
B10: 3. Consumption (cross-check): revenue divided by the blended price per DBU gives implied platform usage. This is the consumption identity the whole business runs on: revenue = DBUs consumed x price.
B11: Where costs come from (Costs tab)
B12: Cost of revenue = cloud and serverless compute (the hyperscaler bill) + third-party AI model costs + support and delivery + amortization of acquired technology. Gross margin is whatever those leave behind. This is why margin compresses as AI and serverless grow, exactly as the company guided in June 2026.
B13: Operating expense = R&D + Sales and marketing + G&A + stock comp + depreciation, each set as a percent of revenue and then decomposed into people, programs and facilities. The personnel dollars imply a headcount, shown as a bridge, so the cost base ties back to a believable number of employees.
B14: How to use it
B15: Change the one orange cell (Assumptions!D5): 1 = Best, 2 = Base, 3 = Worst. It flexes each product line's forecast growth. Every blue cell on the Assumptions tab is an input you can change; everything else is a formula. The balance check on the Financials tab stays at zero.
... B19: The operating-margin path is calibrated to match the validated companion model (Brick by Brick, July 2026) from FY2025 on: this is the same business, seen bottom-up. It extends back to FY2022 and out to FY2032 to cover the full window requested.

Sheet Assumptions
B2: Assumptions and Drivers
B3: Every driver carries its source in the far-right column. Estimates are labeled; Databricks is private and publishes no audited financials. Blue cells are the only inputs.
B5: DRIVER SWITCH 1 = Best 2 = Base 3 = Worst | D5: 2 | P5: Flexes the forecast growth of each product line (FY2028E onward). Historical years and all cost ratios are held across scenarios.
D7: FY2022A | E7: FY2023A | F7: FY2024A | G7: FY2025A | H7: FY2026A | I7: FY2027E | J7: FY2028E | K7: FY2029E | L7: FY2030E | M7: FY2031E | N7: FY2032E
B8: 1. Revenue by product line, historical anchors (USD M, FY2022A to FY2027E fixed)
B9: Data engineering and core compute (Jobs, ETL, Lakeflow, streaming) | D9: 720 | E9: 1090 | F9: 1230 | G9: 1730 | H9: 2450 | I9: 3750 | P9: Historic majority of consumption (Jobs/ETL). Residual of total less other lines; total calibrated to disclosed run-rate ladder.
B10: Databricks SQL (data warehousing) | D10: 70 | E10: 190 | F10: 300 | G10: 480 | H10: 830 | I10: 1500 | P10: Databricks SQL run-rate $1.5B Jun-2026, doubled YoY (company disclosure, Jun 16, 2026); ramped back from launch (Nov 2020).
B11: AI products (Mosaic AI: training, serving, Agent Bricks, tokens) | D11: 0 | E11: 0 | F11: 40 | G11: 280 | H11: 620 | I11: 1600 | P11: AI run-rate $1.0B Sep-2025, $1.4B Feb-2026, $1.7B Jun-2026 (company). MosaicML acquired 2023 seeds the line.
B12: Lakebase (managed Postgres OLTP) | D12: 0 | E12: 0 | F12: 0 | G12: 0 | H12: 40 | I12: 130 | P12: GA early 2026 off the Neon acquisition (May 2025); company: thousands of customers in 6 months, ~2x DBSQL's early pace.
B13: Platform and other (governance premium, security lakehouse, marketplace) | D13: 10 | E13: 20 | F13: 30 | G13: 60 | H13: 110 | I13: 220 | P13: Governance premium, security lakehouse (Panther, announced Jun-2026), marketplace-adjacent. Estimate.
B15: 2. Product-line forecast growth, FY2028E to FY2032E (Best / Base / Worst)
B16: Core growth - Best | J16: 0.38 | K16: 0.31 | L16: 0.26 | M16: 0.22 | N16: 0.19
B17: Core growth - Base | J17: 0.32 | K17: 0.25 | L17: 0.2 | M17: 0.16 | N17: 0.13 | P17: Base path; graceful deceleration. AI and Lakebase fastest; Core matures.
B18: Core growth - Worst | J18: 0.24 | K18: 0.17 | L18: 0.12 | M18: 0.08 | N18: 0.05
B19: SQL growth - Best | J19: 0.51 | K19: 0.42 | L19: 0.34 | M19: 0.28 | N19: 0.24
B20: SQL growth - Base | J20: 0.45 | K20: 0.36 | L20: 0.28 | M20: 0.22 | N20: 0.18 | P20: Base path; graceful deceleration. AI and Lakebase fastest; Core matures.
B21: SQL growth - Worst | J21: 0.37 | K21: 0.28 | L21: 0.2 | M21: 0.14 | N21: 0.1
B22: AI growth - Best | J22: 0.71 | K22: 0.56 | L22: 0.44 | M22: 0.36 | N22: 0.3
B23: AI growth - Base | J23: 0.65 | K23: 0.5 | L23: 0.38 | M23: 0.3 | N23: 0.24 | P23: Base path; graceful deceleration. AI and Lakebase fastest; Core matures.
B24: AI growth - Worst | J24: 0.57 | K24: 0.42 | L24: 0.3 | M24: 0.22 | N24: 0.16
B25: Lakebase growth - Best | J25: 1.46 | K25: 0.96 | L25: 0.71 | M25: 0.51 | N25: 0.39
B26: Lakebase growth - Base | J26: 1.4 | K26: 0.9 | L26: 0.65 | M26: 0.45 | N26: 0.33 | P26: Base path; graceful deceleration. AI and Lakebase fastest; Core matures.
B27: Lakebase growth - Worst | J27: 1.32 | K27: 0.82 | L27: 0.57 | M27: 0.37 | N27: 0.25
B28: Platform growth - Best | J28: 0.56 | K28: 0.48 | L28: 0.4 | M28: 0.33 | N28: 0.28
B29: Platform growth - Base | J29: 0.5 | K29: 0.42 | L29: 0.34 | M29: 0.27 | N29: 0.22 | P29: Base path; graceful deceleration. AI and Lakebase fastest; Core matures.
B30: Platform growth - Worst | J30: 0.42 | K30: 0.34 | L30: 0.26 | M30: 0.19 | N30: 0.14
B32: 3. Cost of revenue components (gross margin is an OUTPUT)
B33: Cloud and serverless compute, % of revenue | D33: 0.09 | E33: 0.095 | F33: 0.1 | G33: 0.11 | H33: 0.14 | I33: 0.175 | J33: 0.185 | K33: 0.183 | L33: 0.178 | M33: 0.175 | N33: 0.17 | P33: Compute Databricks itself buys from AWS/Azure/GCP for serverless and AI SKUs. Rises as serverless/agent mix grows (drives the margin compression the company guided, Jun 16, 2026).
B34: Third-party AI model and API costs, % of AI revenue | D34: 0 | E34: 0 | F34: 0.05 | G34: 0.08 | H34: 0.1 | I34: 0.12 | J34: 0.13 | K34: 0.13 | L34: 0.125 | M34: 0.12 | N34: 0.115 | P34: Cost of serving external frontier models (OpenAI/Anthropic/Google) inside the platform. Estimate.
B35: Support, delivery and platform ops, % of revenue | D35: 0.03 | E35: 0.03 | F35: 0.029 | G35: 0.028 | H35: 0.027 | I35: 0.026 | J35: 0.025 | K35: 0.024 | L35: 0.023 | M35: 0.022 | N35: 0.021 | P35: Personnel cost in cost of revenue (solutions, support, DevOps). Estimate.
B36: Amortization of acquired technology, USD M | D36: 20 | E36: 30 | F36: 90 | G36: 130 | H36: 170 | I36: 230 | J36: 250 | K36: 250 | L36: 240 | M36: 220 | N36: 200 | P36: Developed-tech intangibles from ~19 acquisitions (MosaicML, Tabular, Neon, etc.). Estimate.
B38: 4. Operating expense ratios, % of revenue (ex stock comp)
B39: Research and development | D39: 0.3 | E39: 0.27 | F39: 0.22 | G39: 0.2 | H39: 0.19 | I39: 0.18 | J39: 0.175 | K39: 0.17 | L39: 0.165 | M39: 0.16 | N39: 0.155 | P39: Estimate; R&D-led culture. FY2025E+ calibrated to the validated companion model.
B40: Sales and marketing | D40: 0.6 | E40: 0.5 | F40: 0.42 | G40: 0.36 | H40: 0.33 | I40: 0.3 | J40: 0.28 | K40: 0.26 | L40: 0.245 | M40: 0.23 | N40: 0.215 | P40: Estimate; heavy in land phase, falling as consumption expansion (NRR >140%, company Feb-2026) does the work.
B41: General and administrative | D41: 0.14 | E41: 0.12 | F41: 0.1 | G41: 0.08 | H41: 0.075 | I41: 0.07 | J41: 0.065 | K41: 0.06 | L41: 0.055 | M41: 0.05 | N41: 0.048 | P41: Estimate; scale leverage typical of late-stage software.
B42: Stock-based compensation | D42: 0.2 | E42: 0.21 | F42: 0.22 | G42: 0.24 | H42: 0.22 | I42: 0.19 | J42: 0.17 | K42: 0.155 | L42: 0.14 | M42: 0.13 | N42: 0.115 | P42: Estimate; recurring employee tenders (Series J use of proceeds, Dec-2024). Non-cash; added back in cash flow.
B43: Depreciation and other amortization | D43: 0.02 | E43: 0.02 | F43: 0.02 | G43: 0.02 | H43: 0.02 | I43: 0.02 | J43: 0.02 | K43: 0.02 | L43: 0.02 | M43: 0.02 | N43: 0.02 | P43: Estimate; asset-light (compute rented).
B44: Capital expenditure | D44: 0.025 | E44: 0.025 | F44: 0.025 | G44: 0.025 | H44: 0.025 | I44: 0.025 | J44: 0.025 | K44: 0.025 | L44: 0.025 | M44: 0.025 | N44: 0.025 | P44: Estimate; asset-light model.
B46: 5. Opex decomposition and headcount bridge
B47: Engineering personnel, % of R&D | D47: 0.85 | E47: 0.85 | F47: 0.85 | G47: 0.85 | H47: 0.85 | I47: 0.85 | J47: 0.85 | K47: 0.85 | L47: 0.85 | M47: 0.85 | N47: 0.85 | P47: Remainder is dev cloud, tooling, licences. Estimate.
...

Sheet Revenue
B2: Revenue Build: where every dollar comes from
B3: Primary build is by product line (sums to total). Below it, the same total is decomposed two ways: by customer tier, and by platform consumption (DBUs). USD M unless stated.
D5: FY2022A | E5: FY2023A | F5: FY2024A | G5: FY2025A | H5: FY2026A | I5: FY2027E | J5: FY2028E | K5: FY2029E | L5: FY2030E | M5: FY2031E | N5: FY2032E
B6: A. BY PRODUCT LINE (the primary build)
B7: Data engineering and core compute (Jobs, ETL, Lakeflow, streaming) | D7: =Assumptions!D9 | E7: =Assumptions!E9 | F7: =Assumptions!F9 | G7: =Assumptions!G9 | H7: =Assumptions!H9 | I7: =Assumptions!I9 | J7: =I7*(1+CHOOSE(Assumptions!$D$5,Assumptions!J16,Assumptions!J17,Assumptions!J18)) | K7: =J7*(1+CHOOSE(Assumptions!$D$5,Assumptions!K16,Assumptions!K17,Assumptions!K18)) | L7: =K7*(1+CHOOSE(Assumptions!$D$5,Assumptions!L16,Assumptions!L17,Assumptions!L18)) | M7: =L7*(1+CHOOSE(Assumptions!$D$5,Assumptions!M16,Assumptions!M17,Assumptions!M18)) | N7: =M7*(1+CHOOSE(Assumptions!$D$5,Assumptions!N16,Assumptions!N17,Assumptions!N18))
B8: Databricks SQL (data warehousing) | D8: =Assumptions!D10 | E8: =Assumptions!E10 | F8: =Assumptions!F10 | G8: =Assumptions!G10 | H8: =Assumptions!H10 | I8: =Assumptions!I10 | J8: =I8*(1+CHOOSE(Assumptions!$D$5,Assumptions!J19,Assumptions!J20,Assumptions!J21)) | K8: =J8*(1+CHOOSE(Assumptions!$D$5,Assumptions!K19,Assumptions!K20,Assumptions!K21)) | L8: =K8*(1+CHOOSE(Assumptions!$D$5,Assumptions!L19,Assumptions!L20,Assumptions!L21)) | M8: =L8*(1+CHOOSE(Assumptions!$D$5,Assumptions!M19,Assumptions!M20,Assumptions!M21)) | N8: =M8*(1+CHOOSE(Assumptions!$D$5,Assumptions!N19,Assumptions!N20,Assumptions!N21))
B9: AI products (Mosaic AI: training, serving, Agent Bricks, tokens) | D9: =Assumptions!D11 | E9: =Assumptions!E11 | F9: =Assumptions!F11 | G9: =Assumptions!G11 | H9: =Assumptions!H11 | I9: =Assumptions!I11 | J9: =I9*(1+CHOOSE(Assumptions!$D$5,Assumptions!J22,Assumptions!J23,Assumptions!J24)) | K9: =J9*(1+CHOOSE(Assumptions!$D$5,Assumptions!K22,Assumptions!K23,Assumptions!K24)) | L9: =K9*(1+CHOOSE(Assumptions!$D$5,Assumptions!L22,Assumptions!L23,Assumptions!L24)) | M9: =L9*(1+CHOOSE(Assumptions!$D$5,Assumptions!M22,Assumptions!M23,Assumptions!M24)) | N9: =M9*(1+CHOOSE(Assumptions!$D$5,Assumptions!N22,Assumptions!N23,Assumptions!N24))
B10: Lakebase (managed Postgres OLTP) | D10: =Assumptions!D12 | E10: =Assumptions!E12 | F10: =Assumptions!F12 | G10: =Assumptions!G12 | H10: =Assumptions!H12 | I10: =Assumptions!I12 | J10: =I10*(1+CHOOSE(Assumptions!$D$5,Assumptions!J25,Assumptions!J26,Assumptions!J27)) | K10: =J10*(1+CHOOSE(Assumptions!$D$5,Assumptions!K25,Assumptions!K26,Assumptions!K27)) | L10: =K10*(1+CHOOSE(Assumptions!$D$5,Assumptions!L25,Assumptions!L26,Assumptions!L27)) | M10: =L10*(1+CHOOSE(Assumptions!$D$5,Assumptions!M25,Assumptions!M26,Assumptions!M27)) | N10: =M10*(1+CHOOSE(Assumptions!$D$5,Assumptions!N25,Assumptions!N26,Assumptions!N27))
B11: Platform and other (governance premium, security lakehouse, marketplace) | D11: =Assumptions!D13 | E11: =Assumptions!E13 | F11: =Assumptions!F13 | G11: =Assumptions!G13 | H11: =Assumptions!H13 | I11: =Assumptions!I13 | J11: =I11*(1+CHOOSE(Assumptions!$D$5,Assumptions!J28,Assumptions!J29,Assumptions!J30)) | K11: =J11*(1+CHOOSE(Assumptions!$D$5,Assumptions!K28,Assumptions!K29,Assumptions!K30)) | L11: =K11*(1+CHOOSE(Assumptions!$D$5,Assumptions!L28,Assumptions!L29,Assumptions!L30)) | M11: =L11*(1+CHOOSE(Assumptions!$D$5,Assumptions!M28,Assumptions!M29,Assumptions!M30)) | N11: =M11*(1+CHOOSE(Assumptions!$D$5,Assumptions!N28,Assumptions!N29,Assumptions!N30))
B12: Total revenue | D12: =SUM(D7:D11) | E12: =SUM(E7:E11) | F12: =SUM(F7:F11) | G12: =SUM(G7:G11) | H12: =SUM(H7:H11) | I12: =SUM(I7:I11) | J12: =SUM(J7:J11) | K12: =SUM(K7:K11) | ... N12: =SUM(N7:N11) | P12: Sum of product lines. Calibrated to disclosed run-rates: ~$1.6B FY24 (press, Mar-2024); run-rate $4.0B Sep-25, $4.8B Dec-25, $5.4B Feb-26, $6.9B Jun-26 (company).
B13: Total growth, year over year | E13: =E12/D12-1 | F13: =F12/E12-1 | G13: =G12/F12-1 | H13: =H12/G12-1 | I13: =I12/H12-1 | J13: =J12/I12-1 | K13: =K12/J12-1 | L13: =L12/K12-1 | ... N13: =N12/M12-1
B15: Product mix, % of revenue
B16: Core | D16: =D7/D12 | E16: =E7/E12 | F16: =F7/F12 | G16: =G7/G12 | H16: =H7/H12 | I16: =I7/I12 | J16: =J7/J12 | K16: =K7/K12 | ... N16: =N7/N12
B17: SQL | D17: =D8/D12 | E17: =E8/E12 | F17: =F8/F12 | G17: =G8/G12 | H17: =H8/H12 | I17: =I8/I12 | J17: =J8/J12 | K17: =K8/K12 | ... N17: =N8/N12
B18: AI | D18: =D9/D12 | E18: =E9/E12 | F18: =F9/F12 | G18: =G9/G12 | H18: =H9/H12 | I18: =I9/I12 | J18: =J9/J12 | K18: =K9/K12 | ... N18: =N9/N12
B19: Lakebase | D19: =D10/D12 | E19: =E10/E12 | F19: =F10/F12 | G19: =G10/G12 | H19: =H10/H12 | I19: =I10/I12 | J19: =J10/J12 | K19: =K10/K12 | ... N19: =N10/N12
B20: Platform | D20: =D11/D12 | E20: =E11/E12 | F20: =F11/F12 | G20: =G11/G12 | H20: =H11/H12 | I20: =I11/I12 | J20: =J11/J12 | K20: =K11/K12 | ... N20: =N11/N12
B22: B. CROSS-CHECK: by customer tier (top tiers anchored to disclosure)
B23: Revenue from customers >$10M / yr | D23: =Assumptions!D62*Assumptions!D63 | E23: =Assumptions!E62*Assumptions!E63 | F23: =Assumptions!F62*Assumptions!F63 | G23: =Assumptions!G62*Assumptions!G63 | H23: =Assumptions!H62*Assumptions!H63 | I23: =Assumptions!I62*Assumptions!I63 | J23: =Assumptions!J62*Assumptions!J63 | K23: =Assumptions!K62*Assumptions!K63 | ... N23: =Assumptions!N62*Assumptions!N63
B24: Revenue from customers $1-10M / yr | D24: =Assumptions!D64*Assumptions!D65 | E24: =Assumptions!E64*Assumptions!E65 | F24: =Assumptions!F64*Assumptions!F65 | G24: =Assumptions!G64*Assumptions!G65 | H24: =Assumptions!H64*Assumptions!H65 | I24: =Assumptions!I64*Assumptions!I65 | J24: =Assumptions!J64*Assumptions!J65 | K24: =Assumptions!K64*Assumptions!K65 | ... N24: =Assumptions!N64*Assumptions!N65
B25: Revenue from the long tail (implied residual) | D25: =D12-D23-D24 | E25: =E12-E23-E24 | F25: =F12-F23-F24 | G25: =G12-G23-G24 | H25: =H12-H23-H24 | I25: =I12-I23-I24 | J25: =J12-J23-J24 | K25: =K12-K23-K24 | ... N25: =N12-N23-N24
B26: Memo: implied long-tail average spend (USD 000) | D26: =D25/Assumptions!D66 | E26: =E25/Assumptions!E66 | F26: =F25/Assumptions!F66 | G26: =G25/Assumptions!G66 | H26: =H25/Assumptions!H66 | I26: =I25/Assumptions!I66 | J26: =J25/Assumptions!J66 | K26: =K25/Assumptions!K66 | ... N26: =N25/Assumptions!N66 | P26: Given the disclosed large-account tiers, this is the average annual spend the total implies for the ~20k+ (rising) long-tail organizations.
B27: Check: tiers vs total revenue | D27: =D23+D24+D25-D12 | E27: =E23+E24+E25-E12 | F27: =F23+F24+F25-F12 | G27: =G23+G24+G25-G12 | H27: =H23+H24+H25-H12 | I27: =I23+I24+I25-I12 | J27: =J23+J24+J25-J12 | K27: =K23+K24+K25-K12 | ... N27: =N23+N24+N25-N12
B29: C. CROSS-CHECK: by platform consumption (the DBU meter)
B30: Blended realized price per DBU (USD) | D30: =Assumptions!D69 | E30: =Assumptions!E69 | F30: =Assumptions!F69 | G30: =Assumptions!G69 | H30: =Assumptions!H69 | I30: =Assumptions!I69 | J30: =Assumptions!J69 | K30: =Assumptions!K69 | ... N30: =Assumptions!N69
B31: Implied DBUs consumed (billions) | D31: =D12/D30/1000 | E31: =E12/E30/1000 | F31: =F12/F30/1000 | G31: =G12/G30/1000 | H31: =H12/H30/1000 | I31: =I12/I30/1000 | J31: =J12/J30/1000 | K31: =K12/K30/1000 | ... N31: =N12/N30/1000 | P31: Revenue divided by blended price. The consumption identity: revenue = DBUs x price. Shows platform usage scale.

Sheet Costs
B2: Cost Build: where every dollar goes
B3: Cost of revenue is built from four components, so gross margin is an output, not an input. Operating expense is built from ratios then decomposed into people, programs and facilities. USD M.
D5: FY2022A | E5: FY2023A | F5: FY2024A | G5: FY2025A | H5: FY2026A | I5: FY2027E | J5: FY2028E | K5: FY2029E | L5: FY2030E | M5: FY2031E | N5: FY2032E
B6: A. COST OF REVENUE (gross margin is the output)
B7: Revenue (from Revenue tab) | D7: =Revenue!D12 | E7: =Revenue!E12 | F7: =Revenue!F12 | G7: =Revenue!G12 | H7: =Revenue!H12 | I7: =Revenue!I12 | J7: =Revenue!J12 | K7: =Revenue!K12 | ... N7: =Revenue!N12
B8: Cloud and serverless compute | D8: =D7*Assumptions!D33 | E8: =E7*Assumptions!E33 | F8: =F7*Assumptions!F33 | G8: =G7*Assumptions!G33 | H8: =H7*Assumptions!H33 | I8: =I7*Assumptions!I33 | J8: =J7*Assumptions!J33 | K8: =K7*Assumptions!K33 | ... N8: =N7*Assumptions!N33 | P8: The hyperscaler bill Databricks pays for serverless and AI SKUs. Largest cost, and the one compressing margin.
B9: Third-party AI model and API costs | D9: =Revenue!D9*Assumptions!D34 | E9: =Revenue!E9*Assumptions!E34 | F9: =Revenue!F9*Assumptions!F34 | G9: =Revenue!G9*Assumptions!G34 | H9: =Revenue!H9*Assumptions!H34 | I9: =Revenue!I9*Assumptions!I34 | J9: =Revenue!J9*Assumptions!J34 | K9: =Revenue!K9*Assumptions!K34 | ... N9: =Revenue!N9*Assumptions!N34 | P9: Cost of serving external frontier models inside the platform (% of AI revenue).
B10: Support, delivery and platform ops | D10: =D7*Assumptions!D35 | E10: =E7*Assumptions!E35 | F10: =F7*Assumptions!F35 | G10: =G7*Assumptions!G35 | H10: =H7*Assumptions!H35 | I10: =I7*Assumptions!I35 | J10: =J7*Assumptions!J35 | K10: =K7*Assumptions!K35 | ... N10: =N7*Assumptions!N35
B11: Amortization of acquired technology | D11: =Assumptions!D36 | E11: =Assumptions!E36 | F11: =Assumptions!F36 | G11: =Assumptions!G36 | H11: =Assumptions!H36 | I11: =Assumptions!I36 | J11: =Assumptions!J36 | K11: =Assumptions!K36 | ... N11: =Assumptions!N36
B12: Total cost of revenue | D12: =SUM(D8:D11) | E12: =SUM(E8:E11) | F12: =SUM(F8:F11) | G12: =SUM(G8:G11) | H12: =SUM(H8:H11) | I12: =SUM(I8:I11) | J12: =SUM(J8:J11) | K12: =SUM(K8:K11) | ... N12: =SUM(N8:N11)
B13: Gross profit | D13: =D7-D12 | E13: =E7-E12 | F13: =F7-F12 | G13: =G7-G12 | H13: =H7-H12 | I13: =I7-I12 | J13: =J7-J12 | K13: =K7-K12 | ... N13: =N7-N12
B14: Gross margin % (OUTPUT) | D14: =D13/D7 | E14: =E13/E7 | F14: =F13/F7 | G14: =G13/G7 | H14: =H13/H7 | I14: =I13/I7 | J14: =J13/J7 | K14: =K13/K7 | ... N14: =N13/N7 | P14: Falls from ~85% to ~74% as serverless/AI mix grows (matches Jun-2026 disclosure), then recovers on scale efficiency.
B16: B. OPERATING EXPENSE (ratio, then decomposed)
B17: Research and development | D17: =D7*Assumptions!D39 | E17: =E7*Assumptions!E39 | F17: =F7*Assumptions!F39 | G17: =G7*Assumptions!G39 | H17: =H7*Assumptions!H39 | I17: =I7*Assumptions!I39 | J17: =J7*Assumptions!J39 | K17: =K7*Assumptions!K39 | ... N17: =N7*Assumptions!N39
B18: of which engineering personnel | D18: =D17*Assumptions!D47 | E18: =E17*Assumptions!E47 | F18: =F17*Assumptions!F47 | G18: =G17*Assumptions!G47 | H18: =H17*Assumptions!H47 | I18: =I17*Assumptions!I47 | J18: =J17*Assumptions!J47 | K18: =K17*Assumptions!K47 | ... N18: =N17*Assumptions!N47
B19: of which dev cloud, tooling, other | D19: =D17*(1-Assumptions!D47) | E19: =E17*(1-Assumptions!E47) | F19: =F17*(1-Assumptions!F47) | G19: =G17*(1-Assumptions!G47) | H19: =H17*(1-Assumptions!H47) | I19: =I17*(1-Assumptions!I47) | J19: =J17*(1-Assumptions!J47) | K19: =K17*(1-Assumptions!K47) | ... N19: =N17*(1-Assumptions!N47)
B20: Sales and marketing | D20: =D7*Assumptions!D40 | E20: =E7*Assumptions!E40 | F20: =F7*Assumptions!F40 | G20: =G7*Assumptions!G40 | H20: =H7*Assumptions!H40 | I20: =I7*Assumptions!I40 | J20: =J7*Assumptions!J40 | K20: =K7*Assumptions!K40 | ... N20: =N7*Assumptions!N40
B21: of which sales personnel (incl commission) | D21: =D20*Assumptions!D48 | E21: =E20*Assumptions!E48 | F21: =F20*Assumptions!F48 | G21: =G20*Assumptions!G48 | H21: =H20*Assumptions!H48 | I21: =I20*Assumptions!I48 | J21: =J20*Assumptions!J48 | K21: =K20*Assumptions!K48 | ... N21: =N20*Assumptions!N48
B22: of which marketing personnel | D22: =D20*Assumptions!D49 | E22: =E20*Assumptions!E49 | F22: =F20*Assumptions!F49 | G22: =G20*Assumptions!G49 | H22: =H20*Assumptions!H49 | I22: =I20*Assumptions!I49 | J22: =J20*Assumptions!J49 | K22: =K20*Assumptions!K49 | ... N22: =N20*Assumptions!N49
B23: of which marketing programs and events | D23: =D20*Assumptions!D50 | E23: =E20*Assumptions!E50 | F23: =F20*Assumptions!F50 | G23: =G20*Assumptions!G50 | H23: =H20*Assumptions!H50 | I23: =I20*Assumptions!I50 | J23: =J20*Assumptions!J50 | K23: =K20*Assumptions!K50 | ... N23: =N20*Assumptions!N50
B24: of which partner and field ops | D24: =D20*Assumptions!D51 | E24: =E20*Assumptions!E51 | F24: =F20*Assumptions!F51 | G24: =G20*Assumptions!G51 | H24: =H20*Assumptions!H51 | I24: =I20*Assumptions!I51 | J24: =J20*Assumptions!J51 | K24: =K20*Assumptions!K51 | ... N24: =N20*Assumptions!N51
B25: General and administrative | D25: =D7*Assumptions!D41 | E25: =E7*Assumptions!E41 | F25: =F7*Assumptions!F41 | G25: =G7*Assumptions!G41 | H25: =H7*Assumptions!H41 | I25: =I7*Assumptions!I41 | J25: =J7*Assumptions!J41 | K25: =K7*Assumptions!K41 | ... N25: =N7*Assumptions!N41
B26: of which G&A personnel | D26: =D25*Assumptions!D52 | E26: =E25*Assumptions!E52 | F26: =F25*Assumptions!F52 | G26: =G25*Assumptions!G52 | H26: =H25*Assumptions!H52 | I26: =I25*Assumptions!I52 | J26: =J25*Assumptions!J52 | K26: =K25*Assumptions!K52 | ... N26: =N25*Assumptions!N52
B27: of which facilities and IT | D27: =D25*Assumptions!D53 | E27: =E25*Assumptions!E53 | F27: =F25*Assumptions!F53 | G27: =G25*Assumptions!G53 | H27: =H25*Assumptions!H53 | I27: =I25*Assumptions!I53 | J27: =J25*Assumptions!J53 | K27: =K25*Assumptions!K53 | ... N27: =N25*Assumptions!N53
B28: of which professional, insurance, other | D28: =D25*Assumptions!D54 | E28: =E25*Assumptions!E54 | F28: =F25*Assumptions!F54 | G28: =G25*Assumptions!G54 | H28: =H25*Assumptions!H54 | I28: =I25*Assumptions!I54 | J28: =J25*Assumptions!J54 | K28: =K25*Assumptions!K54 | ... N28: =N25*Assumptions!N54
B29: Stock-based compensation (non-cash) | D29: =D7*Assumptions!D42 | E29: =E7*Assumptions!E42 | F29: =F7*Assumptions!F42 | G29: =G7*Assumptions!G42 | H29: =H7*Assumptions!H42 | I29: =I7*Assumptions!I42 | J29: =J7*Assumptions!J42 | K29: =K7*Assumptions!K42 | ... N29: =N7*Assumptions!N42
B30: Depreciation and other amortization | D30: =D7*Assumptions!D43 | E30: =E7*Assumptions!E43 | F30: =F7*Assumptions!F43 | G30: =G7*Assumptions!G43 | H30: =H7*Assumptions!H43 | I30: =I7*Assumptions!I43 | J30: =J7*Assumptions!J43 | K30: =K7*Assumptions!K43 | ... N30: =N7*Assumptions!N43
B31: Total operating expense | D31: =D17+D20+D25+D29+D30 | E31: =E17+E20+E25+E29+E30 | F31: =F17+F20+F25+F29+F30 | G31: =G17+G20+G25+G29+G30 | H31: =H17+H20+H25+H29+H30 | I31: =I17+I20+I25+I29+I30 | J31: =J17+J20+J25+J29+J30 | K31: =K17+K20+K25+K29+K30 | ... N31: =N17+N20+N25+N29+N30
B33: C. IMPLIED HEADCOUNT BRIDGE (from the personnel dollars above)
B34: Engineering heads | D34: =D18*1000/Assumptions!D55 | E34: =E18*1000/Assumptions!E55 | F34: =F18*1000/Assumptions!F55 | G34: =G18*1000/Assumptions!G55 | H34: =H18*1000/Assumptions!H55 | I34: =I18*1000/Assumptions!I55 | J34: =J18*1000/Assumptions!J55 | K34: =K18*1000/Assumptions!K55 | ... N34: =N18*1000/Assumptions!N55
B35: Sales heads | D35: =D21*1000/Assumptions!D56 | E35: =E21*1000/Assumptions!E56 | F35: =F21*1000/Assumptions!F56 | G35: =G21*1000/Assumptions!G56 | H35: =H21*1000/Assumptions!H56 | I35: =I21*1000/Assumptions!I56 | J35: =J21*1000/Assumptions!J56 | K35: =K21*1000/Assumptions!K56 | ... N35: =N21*1000/Assumptions!N56
B36: Marketing heads | D36: =D22*1000/Assumptions!D57 | E36: =E22*1000/Assumptions!E57 | F36: =F22*1000/Assumptions!F57 | G36: =G22*1000/Assumptions!G57 | H36: =H22*1000/Assumptions!H57 | I36: =I22*1000/Assumptions!I57 | J36: =J22*1000/Assumptions!J57 | K36: =K22*1000/Assumptions!K57 | ... N36: =N22*1000/Assumptions!N57
B37: G&A heads | D37: =D26*1000/Assumptions!D58 | E37: =E26*1000/Assumptions!E58 | F37: =F26*1000/Assumptions!F58 | G37: =G26*1000/Assumptions!G58 | H37: =H26*1000/Assumptions!H58 | I37: =I26*1000/Assumptions!I58 | J37: =J26*1000/Assumptions!J58 | K37: =K26*1000/Assumptions!K58 | ... N37: =N26*1000/Assumptions!N58
B38: Support/delivery heads (in cost of revenue) | D38: =D10*1000/Assumptions!D59 | E38: =E10*1000/Assumptions!E59 | F38: =F10*1000/Assumptions!F59 | G38: =G10*1000/Assumptions!G59 | H38: =H10*1000/Assumptions!H59 | I38: =I10*1000/Assumptions!I59 | J38: =J10*1000/Assumptions!J59 | K38: =K10*1000/Assumptions!K59 | ... N38: =N10*1000/Assumptions!N59
B39: Total implied headcount (year end) | D39: =SUM(D34:D38) | E39: =SUM(E34:E38) | F39: =SUM(F34:F38) | G39: =SUM(G34:G38) | H39: =SUM(H34:H38) | I39: =SUM(I34:I38) | J39: =SUM(J34:J38) | K39: =SUM(K34:K38) | ... N39: =SUM(N34:N38) | P39: Implied by the personnel dollars, not an input. Ties to ~9,000-10,000 in FY2026-27 range; third-party trackers span 9,000 (PitchBook) to ~15,800 (Revelio); company discloses no official figure.
B40: Revenue per head (USD 000) | D40: =D7*1000/D39 | E40: =E7*1000/E39 | F40: =F7*1000/F39 | G40: =G7*1000/G39 | H40: =H7*1000/H39 | I40: =I7*1000/I39 | J40: =J7*1000/J39 | K40: =K7*1000/K39 | ... N40: =N7*1000/N39 | P40: Rises with consumption expansion, the efficiency signature of the model.

Sheet Financials
B2: Financial Statements
B3: Income statement, cash flow and balance sheet, assembled from the Revenue and Cost builds. FY ends January 31. Balance check is zero in every year.
D5: FY2022A | E5: FY2023A | F5: FY2024A | G5: FY2025A | H5: FY2026A | I5: FY2027E | J5: FY2028E | K5: FY2029E | L5: FY2030E | M5: FY2031E | N5: FY2032E
B6: INCOME STATEMENT
B7: Revenue | D7: =Revenue!D12 | E7: =Revenue!E12 | F7: =Revenue!F12 | G7: =Revenue!G12 | H7: =Revenue!H12 | I7: =Revenue!I12 | J7: =Revenue!J12 | K7: =Revenue!K12 | ... N7: =Revenue!N12
B8: Cost of revenue | D8: =-Costs!D12 | E8: =-Costs!E12 | F8: =-Costs!F12 | G8: =-Costs!G12 | H8: =-Costs!H12 | I8: =-Costs!I12 | J8: =-Costs!J12 | K8: =-Costs!K12 | ... N8: =-Costs!N12
B9: Gross profit | D9: =D7+D8 | E9: =E7+E8 | F9: =F7+F8 | G9: =G7+G8 | H9: =H7+H8 | I9: =I7+I8 | J9: =J7+J8 | K9: =K7+K8 | ... N9: =N7+N8
B10: Gross margin % | D10: =D9/D7 | E10: =E9/E7 | F10: =F9/F7 | G10: =G9/G7 | H10: =H9/H7 | I10: =I9/I7 | J10: =J9/J7 | K10: =K9/K7 | ... N10: =N9/N7
B11: Research and development | D11: =-Costs!D17 | E11: =-Costs!E17 | F11: =-Costs!F17 | G11: =-Costs!G17 | H11: =-Costs!H17 | I11: =-Costs!I17 | J11: =-Costs!J17 | K11: =-Costs!K17 | ... N11: =-Costs!N17
B12: Sales and marketing | D12: =-Costs!D20 | E12: =-Costs!E20 | F12: =-Costs!F20 | G12: =-Costs!G20 | H12: =-Costs!H20 | I12: =-Costs!I20 | J12: =-Costs!J20 | K12: =-Costs!K20 | ... N12: =-Costs!N20
B13: General and administrative | D13: =-Costs!D25 | E13: =-Costs!E25 | F13: =-Costs!F25 | G13: =-Costs!G25 | H13: =-Costs!H25 | I13: =-Costs!I25 | J13: =-Costs!J25 | K13: =-Costs!K25 | ... N13: =-Costs!N25
B14: Stock-based compensation | D14: =-Costs!D29 | E14: =-Costs!E29 | F14: =-Costs!F29 | G14: =-Costs!G29 | H14: =-Costs!H29 | I14: =-Costs!I29 | J14: =-Costs!J29 | K14: =-Costs!K29 | ... N14: =-Costs!N29
B15: Depreciation and other amortization | D15: =-Costs!D30 | E15: =-Costs!E30 | F15: =-Costs!F30 | G15: =-Costs!G30 | H15: =-Costs!H30 | I15: =-Costs!I30 | J15: =-Costs!J30 | K15: =-Costs!K30 | ... N15: =-Costs!N30
B16: Operating income (EBIT) | D16: =D9+D11+D12+D13+D14+D15 | E16: =E9+E11+E12+E13+E14+E15 | F16: =F9+F11+F12+F13+F14+F15 | G16: =G9+G11+G12+G13+G14+G15 | H16: =H9+H11+H12+H13+H14+H15 | I16: =I9+I11+I12+I13+I14+I15 | J16: =J9+J11+J12+J13+J14+J15 | K16: =K9+K11+K12+K13+K14+K15 | ... N16: =N9+N11+N12+N13+N14+N15
B17: Operating margin % | D17: =D16/D7 | E17: =E16/E7 | F17: =F16/F7 | G17: =G16/G7 | H17: =H16/H7 | I17: =I16/I7 | J17: =J16/J7 | K17: =K16/K7 | ... N17: =N16/N7
B18: Interest expense (on opening debt) | D18: =-Assumptions!D90*Assumptions!D78 | E18: =-D51*Assumptions!E78 | F18: =-E51*Assumptions!F78 | G18: =-F51*Assumptions!G78 | H18: =-G51*Assumptions!H78 | I18: =-H51*Assumptions!I78 | J18: =-I51*Assumptions!J78 | K18: =-J51*Assumptions!K78 | L18: =-K51*Assumptions!L78 | ... N18: =-M51*Assumptions!N78 | P18: Interest on opening balances (avoids circularity).
B19: Interest income (on opening cash) | D19: =Assumptions!D83*Assumptions!D79 | E19: =D43*Assumptions!E79 | F19: =E43*Assumptions!F79 | G19: =F43*Assumptions!G79 | H19: =G43*Assumptions!H79 | I19: =H43*Assumptions!I79 | J19: =I43*Assumptions!J79 | K19: =J43*Assumptions!K79 | L19: =K43*Assumptions!L79 | ... N19: =M43*Assumptions!N79
B20: Pre-tax income | D20: =D16+D18+D19 | E20: =E16+E18+E19 | F20: =F16+F18+F19 | G20: =G16+G18+G19 | H20: =H16+H18+H19 | I20: =I16+I18+I19 | J20: =J16+J18+J19 | K20: =K16+K18+K19 | ... N20: =N16+N18+N19
B21: Income tax | D21: =-MAX(D20,0)*Assumptions!D80 | E21: =-MAX(E20,0)*Assumptions!E80 | F21: =-MAX(F20,0)*Assumptions!F80 | G21: =-MAX(G20,0)*Assumptions!G80 | H21: =-MAX(H20,0)*Assumptions!H80 | I21: =-MAX(I20,0)*Assumptions!I80 | J21: =-MAX(J20,0)*Assumptions!J80 | K21: =-MAX(K20,0)*Assumptions!K80 | ... N21: =-MAX(N20,0)*Assumptions!N80
B22: Net income (GAAP est.) | D22: =D20+D21 | E22: =E20+E21 | F22: =F20+F21 | G22: =G20+G21 | H22: =H20+H21 | I22: =I20+I21 | J22: =J20+J21 | K22: =K20+K21 | ... N22: =N20+N21
B24: CASH FLOW
B25: Net income | D25: =D22 | E25: =E22 | F25: =F22 | G25: =G22 | H25: =H22 | I25: =I22 | J25: =J22 | K25: =K22 | ... N25: =N22
B26: add back depreciation and amortization | D26: =-D15+Costs!D11 | E26: =-E15+Costs!E11 | F26: =-F15+Costs!F11 | G26: =-G15+Costs!G11 | H26: =-H15+Costs!H11 | I26: =-I15+Costs!I11 | J26: =-J15+Costs!J11 | K26: =-K15+Costs!K11 | ... N26: =-N15+Costs!N11
B27: add back stock-based compensation | D27: =-D14 | E27: =-E14 | F27: =-F14 | G27: =-G14 | H27: =-H14 | I27: =-I14 | J27: =-J14 | K27: =-K14 | ... N27: =-N14
B28: change in accounts receivable | D28: =-(D44-Assumptions!D84) | E28: =-(E44-D44) | F28: =-(F44-E44) | G28: =-(G44-F44) | H28: =-(H44-G44) | I28: =-(I44-H44) | J28: =-(J44-I44) | K28: =-(K44-J44) | L28: =-(L44-K44) | ... N28: =-(N44-M44)
B29: change in deferred revenue | D29: =D49-Assumptions!D88 | E29: =E49-D49 | F29: =F49-E49 | G29: =G49-F49 | H29: =H49-G49 | I29: =I49-H49 | J29: =J49-I49 | K29: =K49-J49 | L29: =L49-K49 | ... N29: =N49-M49
B30: Cash from operations | D30: =SUM(D25:D29) | E30: =SUM(E25:E29) | F30: =SUM(F25:F29) | G30: =SUM(G25:G29) | H30: =SUM(H25:H29) | I30: =SUM(I25:I29) | J30: =SUM(J25:J29) | K30: =SUM(K25:K29) | ... N30: =SUM(N25:N29)
B31: Capital expenditure | D31: =-D7*Assumptions!D44 | E31: =-E7*Assumptions!E44 | F31: =-F7*Assumptions!F44 | G31: =-G7*Assumptions!G44 | H31: =-H7*Assumptions!H44 | I31: =-I7*Assumptions!I44 | J31: =-J7*Assumptions!J44 | K31: =-K7*Assumptions!K44 | ... N31: =-N7*Assumptions!N44
B32: Acquisitions and strategic investments | D32: =Assumptions!D77 | E32: =Assumptions!E77 | F32: =Assumptions!F77 | G32: =Assumptions!G77 | H32: =Assumptions!H77 | I32: =Assumptions!I77 | J32: =Assumptions!J77 | K32: =Assumptions!K77 | ... N32: =Assumptions!N77
B33: Cash from investing | D33: =D31+D32 | E33: =E31+E32 | F33: =F31+F32 | G33: =G31+G32 | H33: =H31+H32 | I33: =I31+I32 | J33: =J31+J32 | K33: =K31+K32 | ... N33: =N31+N32
B34: Equity issuance | D34: =Assumptions!D74 | E34: =Assumptions!E74 | F34: =Assumptions!F74 | G34: =Assumptions!G74 | H34: =Assumptions!H74 | I34: =Assumptions!I74 | J34: =Assumptions!J74 | K34: =Assumptions!K74 | ... N34: =Assumptions!N74
B35: Debt drawn | D35: =Assumptions!D75 | E35: =Assumptions!E75 | F35: =Assumptions!F75 | G35: =Assumptions!G75 | H35: =Assumptions!H75 | I35: =Assumptions!I75 | J35: =Assumptions!J75 | K35: =Assumptions!K75 | ... N35: =Assumptions!N75
B36: Employee liquidity / tenders | D36: =Assumptions!D76 | E36: =Assumptions!E76 | F36: =Assumptions!F76 | G36: =Assumptions!G76 | H36: =Assumptions!H76 | I36: =Assumptions!I76 | J36: =Assumptions!J76 | K36: =Assumptions!K76 | ... N36: =Assumptions!N76
B37: Cash from financing | D37: =D34+D35+D36 | E37: =E34+E35+E36 | F37: =F34+F35+F36 | G37: =G34+G35+G36 | H37: =H34+H35+H36 | I37: =I34+I35+I36 | J37: =J34+J35+J36 | K37: =K34+K35+K36 | ... N37: =N34+N35+N36
B38: Net change in cash | D38: =D30+D33+D37 | E38: =E30+E33+E37 | F38: =F30+F33+F37 | G38: =G30+G33+G37 | H38: =H30+H33+H37 | I38: =I30+I33+I37 | J38: =J30+J33+J37 | K38: =K30+K33+K37 | ... N38: =N30+N33+N37
B39: Free cash flow (CFO + capex) | D39: =D30+D31 | E39: =E30+E31 | F39: =F30+F31 | G39: =G30+G31 | H39: =H30+H31 | I39: =I30+I31 | J39: =J30+J31 | K39: =K30+K31 | ... N39: =N30+N31 | P39: Company confirms first positive FCF quarter Q4 FY2025 and positive TTM FCF through 2025 (no magnitude). Level here is a model output; early years are estimates sensitive to deferred-revenue timing.
B40: FCF margin % | D40: =D39/D7 | E40: =E39/E7 | F40: =F39/F7 | G40: =G39/G7 | H40: =H39/H7 | I40: =I39/I7 | J40: =J39/J7 | K40: =K39/K7 | ... N40: =N39/N7
B42: BALANCE SHEET (closing)
B43: Cash and investments | D43: =Assumptions!D83+D38 | E43: =D43+E38 | F43: =E43+F38 | G43: =F43+G38 | H43: =G43+H38 | I43: =H43+I38 | J43: =I43+J38 | K43: =J43+K38 | L43: =K43+L38 | ... N43: =M43+N38
B44: Accounts receivable | D44: =D7*Assumptions!D70/365 | E44: =E7*Assumptions!E70/365 | F44: =F7*Assumptions!F70/365 | G44: =G7*Assumptions!G70/365 | H44: =H7*Assumptions!H70/365 | I44: =I7*Assumptions!I70/365 | J44: =J7*Assumptions!J70/365 | K44: =K7*Assumptions!K70/365 | ... N44: =N7*Assumptions!N70/365
...

Sheet KPIs
B2: KPIs and Unit Economics
B3: Read-through of the build. All linked to the model; nothing typed twice.
D5: FY2022A | E5: FY2023A | F5: FY2024A | G5: FY2025A | H5: FY2026A | I5: FY2027E | J5: FY2028E | K5: FY2029E | L5: FY2030E | M5: FY2031E | N5: FY2032E
B6: Growth and profitability
B7: Revenue | D7: =Financials!D7 | E7: =Financials!E7 | F7: =Financials!F7 | G7: =Financials!G7 | H7: =Financials!H7 | I7: =Financials!I7 | J7: =Financials!J7 | K7: =Financials!K7 | ... N7: =Financials!N7
B8: Revenue growth | E8: =Financials!E7/Financials!D7-1 | F8: =Financials!F7/Financials!E7-1 | G8: =Financials!G7/Financials!F7-1 | H8: =Financials!H7/Financials!G7-1 | I8: =Financials!I7/Financials!H7-1 | J8: =Financials!J7/Financials!I7-1 | K8: =Financials!K7/Financials!J7-1 | L8: =Financials!L7/Financials!K7-1 | ... N8: =Financials!N7/Financials!M7-1
B9: Gross margin | D9: =Financials!D9/Financials!D7 | E9: =Financials!E9/Financials!E7 | F9: =Financials!F9/Financials!F7 | G9: =Financials!G9/Financials!G7 | H9: =Financials!H9/Financials!H7 | I9: =Financials!I9/Financials!I7 | J9: =Financials!J9/Financials!J7 | K9: =Financials!K9/Financials!K7 | ... N9: =Financials!N9/Financials!N7
B10: Operating (EBIT) margin | D10: =Financials!D16/Financials!D7 | E10: =Financials!E16/Financials!E7 | F10: =Financials!F16/Financials!F7 | G10: =Financials!G16/Financials!G7 | H10: =Financials!H16/Financials!H7 | I10: =Financials!I16/Financials!I7 | J10: =Financials!J16/Financials!J7 | K10: =Financials!K16/Financials!K7 | ... N10: =Financials!N16/Financials!N7
B11: FCF margin | D11: =Financials!D39/Financials!D7 | E11: =Financials!E39/Financials!E7 | F11: =Financials!F39/Financials!F7 | G11: =Financials!G39/Financials!G7 | H11: =Financials!H39/Financials!H7 | I11: =Financials!I39/Financials!I7 | J11: =Financials!J39/Financials!J7 | K11: =Financials!K39/Financials!K7 | ... N11: =Financials!N39/Financials!N7
B12: Rule of 40 (growth + FCF margin) | E12: =(Financials!E7/Financials!D7-1)+Financials!E39/Financials!E7 | F12: =(Financials!F7/Financials!E7-1)+Financials!F39/Financials!F7 | G12: =(Financials!G7/Financials!F7-1)+Financials!G39/Financials!G7 | H12: =(Financials!H7/Financials!G7-1)+Financials!H39/Financials!H7 | I12: =(Financials!I7/Financials!H7-1)+Financials!I39/Financials!I7 | J12: =(Financials!J7/Financials!I7-1)+Financials!J39/Financials!J7 | K12: =(Financials!K7/Financials!J7-1)+Financials!K39/Financials!K7 | L12: =(Financials!L7/Financials!K7-1)+Financials!L39/Financials!L7 | ... N12: =(Financials!N7/Financials!M7-1)+Financials!N39/Financials!N7 | P12: Above 40% is the software health bar; the model clears it throughout the forecast.
B14: Efficiency and mix
B15: Revenue per head (USD 000) | D15: =Costs!D7*1000/Costs!D39 | E15: =Costs!E7*1000/Costs!E39 | F15: =Costs!F7*1000/Costs!F39 | G15: =Costs!G7*1000/Costs!G39 | H15: =Costs!H7*1000/Costs!H39 | I15: =Costs!I7*1000/Costs!I39 | J15: =Costs!J7*1000/Costs!J39 | K15: =Costs!K7*1000/Costs!K39 | ... N15: =Costs!N7*1000/Costs!N39
B16: Implied headcount (year end) | D16: =Costs!D39 | E16: =Costs!E39 | F16: =Costs!F39 | G16: =Costs!G39 | H16: =Costs!H39 | I16: =Costs!I39 | J16: =Costs!J39 | K16: =Costs!K39 | ... N16: =Costs!N39
B17: AI products, % of revenue | D17: =Revenue!D9/Revenue!D12 | E17: =Revenue!E9/Revenue!E12 | F17: =Revenue!F9/Revenue!F12 | G17: =Revenue!G9/Revenue!G12 | H17: =Revenue!H9/Revenue!H12 | I17: =Revenue!I9/Revenue!I12 | J17: =Revenue!J9/Revenue!J12 | K17: =Revenue!K9/Revenue!K12 | ... N17: =Revenue!N9/Revenue!N12
B18: Cloud/AI compute, % of revenue | D18: =(Costs!D8+Costs!D9)/Financials!D7 | E18: =(Costs!E8+Costs!E9)/Financials!E7 | F18: =(Costs!F8+Costs!F9)/Financials!F7 | G18: =(Costs!G8+Costs!G9)/Financials!G7 | H18: =(Costs!H8+Costs!H9)/Financials!H7 | I18: =(Costs!I8+Costs!I9)/Financials!I7 | J18: =(Costs!J8+Costs!J9)/Financials!J7 | K18: =(Costs!K8+Costs!K9)/Financials!K7 | ... N18: =(Costs!N8+Costs!N9)/Financials!N7
B19: Customers >$1M / yr (count) | D19: =Assumptions!D62+Assumptions!D64 | E19: =Assumptions!E62+Assumptions!E64 | F19: =Assumptions!F62+Assumptions!F64 | G19: =Assumptions!G62+Assumptions!G64 | H19: =Assumptions!H62+Assumptions!H64 | I19: =Assumptions!I62+Assumptions!I64 | J19: =Assumptions!J62+Assumptions!J64 | K19: =Assumptions!K62+Assumptions!K64 | ... N19: =Assumptions!N62+Assumptions!N64 | P19: 300+ Sep-2023, 500+ Dec-2024, 800+ Feb-2026 (company).
B21: Capital and liquidity
B22: Cash and investments (closing) | D22: =Financials!D43 | E22: =Financials!E43 | F22: =Financials!F43 | G22: =Financials!G43 | H22: =Financials!H43 | I22: =Financials!I43 | J22: =Financials!J43 | K22: =Financials!K43 | ... N22: =Financials!N43
B23: Debt (closing) | D23: =Financials!D51 | E23: =Financials!E51 | F23: =Financials!F51 | G23: =Financials!G51 | H23: =Financials!H51 | I23: =Financials!I51 | J23: =Financials!J51 | K23: =Financials!K51 | ... N23: =Financials!N51
B24: Deferred revenue (closing) | D24: =Financials!D49 | E24: =Financials!E49 | F24: =Financials!F49 | G24: =Financials!G49 | H24: =Financials!H49 | I24: =Financials!I49 | J24: =Financials!J49 | K24: =Financials!K49 | ... N24: =Financials!N49
B25: Cumulative paid-in equity (memo) | D25: =Assumptions!D91+Assumptions!D74 | E25: =D25+Assumptions!E74 | F25: =E25+Assumptions!F74 | G25: =F25+Assumptions!G74 | H25: =G25+Assumptions!H74 | I25: =H25+Assumptions!I74 | J25: =I25+Assumptions!J74 | K25: =J25+Assumptions!K74 | L25: =K25+Assumptions!L74 | ... N25: =M25+Assumptions!N74
B26: Capital efficiency (revenue / cumulative equity) | D26: =Financials!D7/D25 | E26: =Financials!E7/E25 | F26: =Financials!F7/F25 | G26: =Financials!G7/G25 | H26: =Financials!H7/H25 | I26: =Financials!I7/I25 | J26: =Financials!J7/J25 | K26: =Financials!K7/K25 | ... N26: =Financials!N7/N25 | P26: Equity-only denominator by house convention; debt informs compute independence, not this ratio.
