Workbook

Sheet Cover
C11: Anthropic — Operating Model & Valuation
C12: Teaching build v1.0 · 2026-08-19 · data: anthropic-model/DATA_PACK.md · all facts tiered on 01_Data
C14: Table of Contents | H14: Model Checks (0 = OK)
C16: 00_Assumptions — drivers, scenario switch, timeline | H16: Cumulative equity ties to $124.3B [CANONICAL]? | I16: ='05_Cash_Fund'!D27
C17: 01_Data — facts only, tiered | H17: 2026E recognized within run-rate bounds? | I17: =IF(AND('02_Revenue'!G17>='02_Revenue'!F9,'02_Revenue'!G17<='02_Revenue'!G9),0,1)
C18: 02_Revenue — run-rate curve → recognized revenue | H18: Terminal < 95% of operating EV (Gordon)? | I18: =IF('06_Valuation'!C42<0.95,0,1)
C19: 03_Costs — GM path, compute, opex | H19: P&L identity: GP − opex − EBIT = 0 (2030E)? | I19: ='04_PL'!K11-'04_PL'!K18-'04_PL'!K20
C20: 04_PL — dual-basis P&L, NOL schedule | H20: Cash walk continuity (EoY30 = BoY23 + Σflows)? | I20: ='05_Cash_Fund'!K25-('05_Cash_Fund'!D24+SUM('05_Cash_Fund'!D21:K21)+SUM('05_Cash_Fund'!D22:K22)+SUM('05_Cash_Fund'!D13:K13))
C21: 05_Cash_Fund — FCF, cash walk, capitalization
C22: 06_Valuation — marks ladder, comps, DCF
C23: 07_Sensitivity — r × g and multiple grids | H23: Colour Key
C24: 08_Output — dashboard & charts | H24: Blue — hardcoded input (fact or belief)
H25: Black — formula (logic only)
H26: Orange — flagged: DISPUTED / VERIFY / STALE / rumor
H27: Bold driver rows — active scenario (switch: 00_Assumptions!D7)
C31: HYPD · Harrison Rolfes — educational estimate built from public/reported data; not investment advice.

Sheet 00_Assumptions
B3: Scenario Control & Timeline
B5: All figures in USD millions unless stated
B7: Scenario Switch | D7: 2 | F7: 1 = Bear · 2 = Base · 3 = Bull
B8: Active Scenario | D8: =CHOOSE($D$7,"Bear","Base","Bull")
B10: Timeline (typed once — every tab links here) | D10: 2023 | E10: =D10+1 | F10: =E10+1 | G10: =F10+1 | H10: =G10+1 | I10: =H10+1 | J10: =I10+1 | K10: =J10+1
B13: Scalar Drivers (one value per scenario)
D15: Bear | E15: Base | F15: Bull | G15: Active
B16: 2026E exit run-rate — gross ($M) | D16: 95000 | E16: 110000 | F16: 125000 | G16: =CHOOSE($D$7,D16,E16,F16)
B17: Discount rate | D17: 0.22 | E17: 0.18 | F17: 0.15 | G17: =CHOOSE($D$7,D17,E17,F17)
B18: Terminal growth (Gordon) | D18: 0.025 | E18: 0.03 | F18: 0.035 | G18: =CHOOSE($D$7,D18,E18,F18)
B19: Terminal exit multiple (x 2030E FCF) | D19: 14 | E19: 18 | F19: 22 | G19: =CHOOSE($D$7,D19,E19,F19)
B21: Constants (not scenario-flexed)
B22: Equalization — net as % of gross (Ruling 5) | D22: 0.6025 | F22: 1 − 39.75% (Ruling 5) · gate-verified on May-26 mix · mix-stability assumed at later prints (est.)
B23: Tax rate (post-NOL) | D23: 0.18 | F23: blended fed+state, simplified
B24: Interest rate on debt | D24: 0.065 | F24: chip bonds + revolver, blended (est.)
B25: Yield on cash | D25: 0.04 | F25: T-bill proxy
B26: Owned-infra capex (% of revenue) | D26: 0.015 | F26: most compute is opex/prepay, not capex
B29: Per-Year Drivers — forecast 2026E–2030E (bold row = active scenario)
D31: ='00_Assumptions'!D$10 | E31: ='00_Assumptions'!E$10 | F31: ='00_Assumptions'!F$10 | G31: ='00_Assumptions'!G$10 | H31: ='00_Assumptions'!H$10 | I31: ='00_Assumptions'!I$10 | J31: ='00_Assumptions'!J$10 | K31: ='00_Assumptions'!K$10
B33: Exit run-rate growth (YoY, 2027E on) | H33: =CHOOSE($D$7,H35,H36,H37) | I33: =CHOOSE($D$7,I35,I36,I37) | J33: =CHOOSE($D$7,J35,J36,J37) | K33: =CHOOSE($D$7,K35,K36,K37)
B35: Bear | H35: 0.1 | I35: 0.05 | J35: 0.03 | K35: 0.02
B36: Base | H36: 0.5 | I36: 0.32 | J36: 0.22 | K36: 0.15
B37: Bull | H37: 0.8 | I37: 0.55 | J37: 0.4 | K37: 0.3
B39: Gross margin (gross-revenue basis) | G39: =CHOOSE($D$7,G41,G42,G43) | H39: =CHOOSE($D$7,H41,H42,H43) | I39: =CHOOSE($D$7,I41,I42,I43) | J39: =CHOOSE($D$7,J41,J42,J43) | K39: =CHOOSE($D$7,K41,K42,K43)
B41: Bear | G41: 0.46 | H41: 0.52 | I41: 0.6 | J41: 0.62 | K41: 0.63
B42: Base | G42: 0.52 | H42: 0.63 | I42: 0.77 | J42: 0.78 | K42: 0.8
B43: Bull | G43: 0.55 | H43: 0.67 | I43: 0.8 | J43: 0.81 | K43: 0.82
B45: R&D — training compute ($M) | G45: =CHOOSE($D$7,G47,G48,G49) | H45: =CHOOSE($D$7,H47,H48,H49) | I45: =CHOOSE($D$7,I47,I48,I49) | J45: =CHOOSE($D$7,J47,J48,J49) | K45: =CHOOSE($D$7,K47,K48,K49)
B47: Bear | G47: 11000 | H47: 14000 | I47: 16000 | J47: 18000 | K47: 20000
B48: Base | G48: 13000 | H48: 22000 | I48: 30000 | J48: 38000 | K48: 45000
B49: Bull | G49: 15000 | H49: 28000 | I49: 40000 | J49: 52000 | K49: 65000
B51: R&D — people & other ($M) | G51: =CHOOSE($D$7,G53,G54,G55) | H51: =CHOOSE($D$7,H53,H54,H55) | I51: =CHOOSE($D$7,I53,I54,I55) | J51: =CHOOSE($D$7,J53,J54,J55) | K51: =CHOOSE($D$7,K53,K54,K55)
B53: Bear | G53: 2800 | H53: 4000 | I53: 5500 | J53: 7000 | K53: 8500
B54: Base | G54: 3000 | H54: 5000 | I54: 7000 | J54: 9000 | K54: 11000
B55: Bull | G55: 3200 | H55: 6000 | I55: 8500 | J55: 11000 | K55: 13500
B57: S&M (% of revenue) | G57: =CHOOSE($D$7,G59,G60,G61) | H57: =CHOOSE($D$7,H59,H60,H61) | I57: =CHOOSE($D$7,I59,I60,I61) | J57: =CHOOSE($D$7,J59,J60,J61) | K57: =CHOOSE($D$7,K59,K60,K61)
B59: Bear | G59: 0.09 | H59: 0.08 | I59: 0.07 | J59: 0.065 | K59: 0.06
B60: Base | G60: 0.08 | H60: 0.07 | I60: 0.06 | J60: 0.055 | K60: 0.05
B61: Bull | G61: 0.07 | H61: 0.06 | I61: 0.05 | J61: 0.045 | K61: 0.04
B63: G&A (% of revenue) | G63: =CHOOSE($D$7,G65,G66,G67) | H63: =CHOOSE($D$7,H65,H66,H67) | I63: =CHOOSE($D$7,I65,I66,I67) | J63: =CHOOSE($D$7,J65,J66,J67) | K63: =CHOOSE($D$7,K65,K66,K67)
...

Sheet 01_Data
B3: Funding & Marks (STABLE decay) — PB re-pulled 2026-08-19
B5: Metric / Event | C5: Value | D5: Units | E5: As-of | F5: Basis / Round | G5: Tier | H5: Tag | I5: Source
B6: Series A | C6: 124 | D6: $M | E6: 2021-05-28 | F6: post $461M | G6: T2 | H6: CANONICAL | I6: PitchBook
B7: Series D (Menlo) | C7: 1200 | D7: $M | E7: 2024-07-01 | F7: $19.8B pre → $21B post | G7: T2 | H7: CANONICAL | I7: PitchBook
B8: Amazon round | C8: 8000 | D8: $M | E8: 2024-11-22 | F8: $46B pre · $1.3B conv. | G8: T2 | H8: CANONICAL | I8: PitchBook
B9: Series E (Lightspeed) | C9: 3500 | D9: $M | E9: 2025-03-03 | F9: $58B pre → $61.5B post | G9: T2 | H9: CANONICAL | I9: PitchBook
B10: Revolver (debt) | C10: 2500 | D10: $M | E10: 2025-05-16 | F10: debt facility | G10: T2 | H10: CANONICAL | I10: PB 295197-04T
B11: Series F (Lightspeed/Fidelity/ICONIQ) | C11: 13000 | D11: $M | E11: 2025-09-02 | F11: $170B pre → $183B post | G11: T2 | H11: CANONICAL | I11: PitchBook
B12: Series G (Coatue/GIC/ICONIQ e.a.) | C12: 30000 | D12: $M | E12: 2026-02-12 | F12: $350B pre → $380B post | G12: T2 | H12: CANONICAL | I12: PitchBook
B13: Series H (Dragoneer/Sequoia e.a.) | C13: 65000 | D13: $M | E13: 2026-05-28 | F13: $900B pre → $965B post · $589.0095/sh | G13: T2 | H13: CANONICAL | I13: PB 329489-02T
B14: Chip bonds (debt) | C14: 34500 | D14: $M | E14: 2026-06-09 | F14: $6.0B SP / $24.0B 1L / $4.5B 2L · Alphabet chips | G14: T2 | H14: CANONICAL | I14: PB 334763-02T
B15: Total equity raised | C15: 124300 | D15: $M | E15: 2026-07-02 | F15: equity-only (Ruling 1) | G15: T2 | H15: CANONICAL | I15: project-context v3.4 · PB tie
B16: Total debt | C16: 37000 | D16: $M | E16: 2026-07-02 | F16: bonds + revolver | G16: T2 | H16: CANONICAL | I16: project-context v3.4
B17: Total raised (PB) | C17: 161254 | D17: $M | E17: 2026-08-18 | F17: equity + debt | G17: T2 | H17: CANONICAL | I17: PB profile 466959-97
B19: Run-Rate Curve (VOLATILE decay) — annualized, GROSS basis
B21: Metric / Event | C21: Value | D21: Units | E21: As-of | F21: Basis / Round | G21: Tier | H21: Tag | I21: Source
B22: Run-rate — Dec 2024 | C22: 1000 | D22: $M | E22: 2024-12 | F22: exit run-rate | G22: T2 | H22: CANONICAL | I22: multi-outlet
B23: Run-rate — Jul 2025 | C23: 4000 | D23: $M | E23: 2025-07 | F23: run-rate | G23: T2/T3 | H23: est. | I23: press
B24: Run-rate — Dec 2025 | C24: 9000 | D24: $M | E24: 2025-12 | F24: exit run-rate | G24: T2 | H24: CANONICAL | I24: multi-outlet · PB FY25 field
B25: Run-rate — Feb 2026 | C25: 14000 | D25: $M | E25: 2026-02 | F25: run-rate | G25: T3 | H25: est. | I25: press
B26: Run-rate — ~Apr 2026 | C26: 30000 | D26: $M | E26: 2026-04 | F26: run-rate ('80x growth') | G26: T2 | H26: VERIFY date | I26: VentureBeat/company
B27: Run-rate — May 2026 | C27: 47000 | D27: $M | E27: 2026-05 | F27: run-rate (prior canonical) | G27: T2 | H27: CANONICAL | I27: company
B28: Run-rate — end-Jul 2026 | C28: 65000 | D28: $M | E28: 2026-08-17 | F28: run-rate, company-to-investors | G28: T2 | H28: PROPOSED CANONICAL | I28: CNBC·Bloomberg·Fortune·TechCrunch
B29: YE-2026 run-rate, investor expectation | C29: 110000 | D29: $M | E29: 2026-08-17 | F29: midpoint of $100–120B range | G29: T3 | H29: est. | I29: CNBC
B31: P&L, Margins, Burn, Ops (QUARTERLY decay)
B33: Metric / Event | C33: Value | D33: Units | E33: As-of | F33: Basis / Round | G33: Tier | H33: Tag | I33: Source
B34: FY2024 revenue (PB) | C34: 1000 | D34: $M | E34: FY2024 | F34: matches Dec-24 run-rate | G34: T2/T4 | H34: DISPUTED basis | I34: PitchBook
B35: FY2024 net loss (PB) | C35: -5300 | D35: $M | E35: FY2024 | F35: reported | G35: T2/T4 | H35: CANONICAL | I35: PitchBook
B36: FY2025 revenue (PB) | C36: 9000 | D36: $M | E36: FY2025 | F36: matches Dec-25 run-rate; guide implies ~$4.5–6B recognized | G36: T2/T4 | H36: DISPUTED basis | I36: PitchBook
B37: Gross margin 2025 | C37: 0.4 | D37: % | E37: FY2025 | F37: lowered vs plan · gross-rev basis | G37: T3 | H37: est. | I37: The Information
B38: GM path 2027E / 2028E | C38: 0.63 | D38: % | E38: plan | F38: 77% in 2028E · company plan | G38: T3 | H38: CANONICAL path | I38: The Information / WSJ
B39: Q2 2026 operating profit | C39: 559 | D39: $M | E39: Q2 2026 | F39: first op profit | G39: T3 | H39: unswept (FCF flag) | I39: CNBC
B40: FY2025 cash burn | C40: -5600 | D40: $M | E40: FY2025 | F40: operating burn | G40: T3 | H40: est. | I40: The Information
B41: FY2026 planned burn | C41: -3000 | D41: $M | E41: plan (pre-beat) | F41: vintage ~Jan-26 | G41: T3 | H41: superseded vintage | I41: The Information
B42: WSJ FCF trough (2027, scenario) | C42: -25000 | D42: $M | E42: 2026-04-06 | F42: incl.-training FCF basis | G42: T2 | H42: DISPUTED vintage/defn | I42: WSJ investor docs
B43: Net revenue retention | C43: 1.4 | D43: % | E43: 2026 | F43: 140%+ | G43: T2 | H43: CANONICAL | I43: company
B44: Enterprise share of revenue | C44: 0.8 | D44: % | E44: 2026 | G44: T2 | H44: CANONICAL | I44: company
B45: Claude Code ARR | C45: 2500 | D45: $M | E45: 2026-05 | F45: 54% coding share | G45: T2 | H45: CANONICAL | I45: company
B46: Employees | C46: 5000 | D46: count | E46: 2026-04-21 | G46: T2 | H46: CANONICAL | I46: PitchBook
B48: Forecast Vintages · Comps · Open Items
...

Sheet 02_Revenue
B3: Run-Rate Curve — annual exits (GROSS basis)
B5: All figures in USD millions unless stated
D7: ='00_Assumptions'!D$10 | E7: ='00_Assumptions'!E$10 | F7: ='00_Assumptions'!F$10 | G7: ='00_Assumptions'!G$10 | H7: ='00_Assumptions'!H$10 | I7: ='00_Assumptions'!I$10 | J7: ='00_Assumptions'!J$10 | K7: ='00_Assumptions'!K$10
B9: Exit run-rate — gross ($M) | D9: 200 | E9: ='01_Data'!$C$22 | F9: ='01_Data'!$C$24 | G9: ='00_Assumptions'!$G$16 | H9: =G9*(1+'00_Assumptions'!H$33) | I9: =H9*(1+'00_Assumptions'!I$33) | J9: =I9*(1+'00_Assumptions'!J$33) | K9: =J9*(1+'00_Assumptions'!K$33) | M9: 2023 exit = est. · 2024/2025 link 01_Data · 2026E = scenario scalar · 2027E+ = growth driver
B10: YoY growth | E10: =E9/D9-1 | F10: =F9/E9-1 | G10: =G9/F9-1 | H10: =H9/G9-1 | I10: =I9/H9-1 | J10: =J9/I9-1 | K10: =K9/J9-1
B11: Exit run-rate — net equalized ($M) | D11: =D9*'00_Assumptions'!$D$22 | E11: =E9*'00_Assumptions'!$D$22 | F11: =F9*'00_Assumptions'!$D$22 | G11: =G9*'00_Assumptions'!$D$22 | H11: =H9*'00_Assumptions'!$D$22 | I11: =I9*'00_Assumptions'!$D$22 | J11: =J9*'00_Assumptions'!$D$22 | K11: =K9*'00_Assumptions'!$D$22
B13: Recognized Revenue — derived (log-mean integration of the exit curve)
B15: All figures in USD millions unless stated
D16: ='00_Assumptions'!D$10 | E16: ='00_Assumptions'!E$10 | F16: ='00_Assumptions'!F$10 | G16: ='00_Assumptions'!G$10 | H16: ='00_Assumptions'!H$10 | I16: ='00_Assumptions'!I$10 | J16: ='00_Assumptions'!J$10 | K16: ='00_Assumptions'!K$10
B17: Recognized revenue — gross ($M) | D17: 100 | E17: =IFERROR((E9-D9)/LN(E9/D9),(E9+D9)/2) | F17: =IFERROR((F9-E9)/LN(F9/E9),(F9+E9)/2) | G17: =IFERROR((G9-F9)/LN(G9/F9),(G9+F9)/2) | H17: =IFERROR((H9-G9)/LN(H9/G9),(H9+G9)/2) | I17: =IFERROR((I9-H9)/LN(I9/H9),(I9+H9)/2) | J17: =IFERROR((J9-I9)/LN(J9/I9),(J9+I9)/2) | K17: =IFERROR((K9-J9)/LN(K9/J9),(K9+J9)/2) | M17: Recognized_t = (RR_t − RR_t-1)/ln(RR_t/RR_t-1) — exact integral of smooth exponential growth between exits
B18: YoY growth | E18: =E17/D17-1 | F18: =F17/E17-1 | G18: =G17/F17-1 | H18: =H17/G17-1 | I18: =I17/H17-1 | J18: =J17/I17-1 | K18: =K17/J17-1
B19: Recognized revenue — net equalized ($M) | D19: =D17*'00_Assumptions'!$D$22 | E19: =E17*'00_Assumptions'!$D$22 | F19: =F17*'00_Assumptions'!$D$22 | G19: =G17*'00_Assumptions'!$D$22 | H19: =H17*'00_Assumptions'!$D$22 | I19: =I17*'00_Assumptions'!$D$22 | J19: =J17*'00_Assumptions'!$D$22 | K19: =K17*'00_Assumptions'!$D$22
B21: PB reference: FY2024 $1.0B · FY2025 $9.0B — [DISPUTED basis: PB carries exit run-rates as fiscal revenue; see 01_Data rows 34/36]
B23: Derived 2025 recognized ≈ $3.6B vs $4.5–6B implied by the Jan-26 guide — gap is curve-shape uncertainty; both far below the $9.0B run-rate-as-fiscal print.

Sheet 03_Costs
B3: Gross Margin & COGS (inference compute + cloud rev-share)
B5: All figures in USD millions unless stated
D7: ='00_Assumptions'!D$10 | E7: ='00_Assumptions'!E$10 | F7: ='00_Assumptions'!F$10 | G7: ='00_Assumptions'!G$10 | H7: ='00_Assumptions'!H$10 | I7: ='00_Assumptions'!I$10 | J7: ='00_Assumptions'!J$10 | K7: ='00_Assumptions'!K$10
B9: Gross margin % (gross-revenue basis) | D9: -1.2 | E9: -0.94 | F9: 0.4 | G9: ='00_Assumptions'!G39 | H9: ='00_Assumptions'!H39 | I9: ='00_Assumptions'!I39 | J9: ='00_Assumptions'!J39 | K9: ='00_Assumptions'!K39 | M9: 2023 est. · 2024 −94% [CANONICAL] · 2025 40% (T3) · forecast = scenario driver
B10: Revenue — gross ($M) | D10: ='02_Revenue'!D17 | E10: ='02_Revenue'!E17 | F10: ='02_Revenue'!F17 | G10: ='02_Revenue'!G17 | H10: ='02_Revenue'!H17 | I10: ='02_Revenue'!I17 | J10: ='02_Revenue'!J17 | K10: ='02_Revenue'!K17
B11: COGS ($M) | D11: =D10*(1-D9) | E11: =E10*(1-E9) | F11: =F10*(1-F9) | G11: =G10*(1-G9) | H11: =H10*(1-H9) | I11: =I10*(1-I9) | J11: =J10*(1-J9) | K11: =K10*(1-K9)
B12: Gross profit ($M) | D12: =D10-D11 | E12: =E10-E11 | F12: =F10-F11 | G12: =G10-G11 | H12: =H10-H11 | I12: =I10-I11 | J12: =J10-J11 | K12: =K10-K11
B15: Operating Expenses
B17: All figures in USD millions unless stated
D18: ='00_Assumptions'!D$10 | E18: ='00_Assumptions'!E$10 | F18: ='00_Assumptions'!F$10 | G18: ='00_Assumptions'!G$10 | H18: ='00_Assumptions'!H$10 | I18: ='00_Assumptions'!I$10 | J18: ='00_Assumptions'!J$10 | K18: ='00_Assumptions'!K$10
B20: R&D — training compute ($M) | D20: 1200 | E20: 4000 | F20: 6000 | G20: ='00_Assumptions'!G45 | H20: ='00_Assumptions'!H45 | I20: ='00_Assumptions'!I45 | J20: ='00_Assumptions'!J45 | K20: ='00_Assumptions'!K45 | M20: hist. est. (calibrated to PB FY24 loss + WSJ dual-P&L) · forecast = driver · expensed, never capitalized
B21: R&D — people & other ($M) | D21: 400 | E21: 800 | F21: 1500 | G21: ='00_Assumptions'!G51 | H21: ='00_Assumptions'!H51 | I21: ='00_Assumptions'!I51 | J21: ='00_Assumptions'!J51 | K21: ='00_Assumptions'!K51
B22: S&M ($M) | D22: 50 | E22: 150 | F22: 400 | G22: ='00_Assumptions'!G57*'02_Revenue'!G17 | H22: ='00_Assumptions'!H57*'02_Revenue'!H17 | I22: ='00_Assumptions'!I57*'02_Revenue'!I17 | J22: ='00_Assumptions'!J57*'02_Revenue'!J17 | K22: ='00_Assumptions'!K57*'02_Revenue'!K17
B23: G&A ($M) | D23: 50 | E23: 100 | F23: 250 | G23: ='00_Assumptions'!G63*'02_Revenue'!G17 | H23: ='00_Assumptions'!H63*'02_Revenue'!H17 | I23: ='00_Assumptions'!I63*'02_Revenue'!I17 | J23: ='00_Assumptions'!J63*'02_Revenue'!J17 | K23: ='00_Assumptions'!K63*'02_Revenue'!K17
B24: Total opex ($M) | D24: =SUM(D20:D23) | E24: =SUM(E20:E23) | F24: =SUM(F20:F23) | G24: =SUM(G20:G23) | H24: =SUM(H20:H23) | I24: =SUM(I20:I23) | J24: =SUM(J20:J23) | K24: =SUM(K20:K23)
B26: Training compute sits in R&D and is expensed in full (GAAP) — the dual-basis EBIT on 04_PL separates it, per the WSJ investor-doc framework.

Sheet 04_PL
B3: P&L — Consolidated (GROSS revenue basis)
B5: All figures in USD millions unless stated
D7: ='00_Assumptions'!D$10 | E7: ='00_Assumptions'!E$10 | F7: ='00_Assumptions'!F$10 | G7: ='00_Assumptions'!G$10 | H7: ='00_Assumptions'!H$10 | I7: ='00_Assumptions'!I$10 | J7: ='00_Assumptions'!J$10 | K7: ='00_Assumptions'!K$10
B9: Revenue — gross ($M) | D9: ='02_Revenue'!D17 | E9: ='02_Revenue'!E17 | F9: ='02_Revenue'!F17 | G9: ='02_Revenue'!G17 | H9: ='02_Revenue'!H17 | I9: ='02_Revenue'!I17 | J9: ='02_Revenue'!J17 | K9: ='02_Revenue'!K17
B10: COGS | D10: ='03_Costs'!D11 | E10: ='03_Costs'!E11 | F10: ='03_Costs'!F11 | G10: ='03_Costs'!G11 | H10: ='03_Costs'!H11 | I10: ='03_Costs'!I11 | J10: ='03_Costs'!J11 | K10: ='03_Costs'!K11
B11: Gross profit | D11: =D9-D10 | E11: =E9-E10 | F11: =F9-F10 | G11: =G9-G10 | H11: =H9-H10 | I11: =I9-I10 | J11: =J9-J10 | K11: =K9-K10
B12: Gross margin | D12: =D11/D9 | E12: =E11/E9 | F12: =F11/F9 | G12: =G11/G9 | H12: =H11/H9 | I12: =I11/I9 | J12: =J11/J9 | K12: =K11/K9
B14: R&D — training compute | D14: ='03_Costs'!D20 | E14: ='03_Costs'!E20 | F14: ='03_Costs'!F20 | G14: ='03_Costs'!G20 | H14: ='03_Costs'!H20 | I14: ='03_Costs'!I20 | J14: ='03_Costs'!J20 | K14: ='03_Costs'!K20
B15: R&D — people & other | D15: ='03_Costs'!D21 | E15: ='03_Costs'!E21 | F15: ='03_Costs'!F21 | G15: ='03_Costs'!G21 | H15: ='03_Costs'!H21 | I15: ='03_Costs'!I21 | J15: ='03_Costs'!J21 | K15: ='03_Costs'!K21
B16: S&M | D16: ='03_Costs'!D22 | E16: ='03_Costs'!E22 | F16: ='03_Costs'!F22 | G16: ='03_Costs'!G22 | H16: ='03_Costs'!H22 | I16: ='03_Costs'!I22 | J16: ='03_Costs'!J22 | K16: ='03_Costs'!K22
B17: G&A | D17: ='03_Costs'!D23 | E17: ='03_Costs'!E23 | F17: ='03_Costs'!F23 | G17: ='03_Costs'!G23 | H17: ='03_Costs'!H23 | I17: ='03_Costs'!I23 | J17: ='03_Costs'!J23 | K17: ='03_Costs'!K23
B18: Total opex | D18: =SUM(D14:D17) | E18: =SUM(E14:E17) | F18: =SUM(F14:F17) | G18: =SUM(G14:G17) | H18: =SUM(H14:H17) | I18: =SUM(I14:I17) | J18: =SUM(J14:J17) | K18: =SUM(K14:K17)
B20: EBIT | D20: =D11-D18 | E20: =E11-E18 | F20: =F11-F18 | G20: =G11-G18 | H20: =H11-H18 | I20: =I11-I18 | J20: =J11-J18 | K20: =K11-K18
B21: EBIT margin | D21: =D20/D9 | E21: =E20/E9 | F21: =F20/F9 | G21: =G20/G9 | H21: =H20/H9 | I21: =I20/I9 | J21: =J20/J9 | K21: =K20/K9
B22: EBIT excl. training compute | D22: =D20+D14 | E22: =E20+E14 | F22: =F20+F14 | G22: =G20+G14 | H22: =H20+H14 | I22: =I20+I14 | J22: =J20+J14 | K22: =K20+K14 | M22: WSJ dual-basis: excl-training breakeven 2025, incl-training 2028 (Apr-26 vintage) — actuals beat plan (Q2-26 op profit $559M, T3)
B24: Interest income | D24: ='05_Cash_Fund'!D24*'00_Assumptions'!$D$25 | E24: ='05_Cash_Fund'!E24*'00_Assumptions'!$D$25 | F24: ='05_Cash_Fund'!F24*'00_Assumptions'!$D$25 | G24: ='05_Cash_Fund'!G24*'00_Assumptions'!$D$25 | H24: ='05_Cash_Fund'!H24*'00_Assumptions'!$D$25 | I24: ='05_Cash_Fund'!I24*'00_Assumptions'!$D$25 | J24: ='05_Cash_Fund'!J24*'00_Assumptions'!$D$25 | K24: ='05_Cash_Fund'!K24*'00_Assumptions'!$D$25 | M24: beginning-of-year cash × yield — avoids circularity
B25: Interest expense | D25: =('05_Cash_Fund'!D23/2)*'00_Assumptions'!$D$24 | E25: =(('05_Cash_Fund'!D23+'05_Cash_Fund'!E23)/2)*'00_Assumptions'!$D$24 | F25: =(('05_Cash_Fund'!E23+'05_Cash_Fund'!F23)/2)*'00_Assumptions'!$D$24 | G25: =(('05_Cash_Fund'!F23+'05_Cash_Fund'!G23)/2)*'00_Assumptions'!$D$24 | H25: =(('05_Cash_Fund'!G23+'05_Cash_Fund'!H23)/2)*'00_Assumptions'!$D$24 | I25: =(('05_Cash_Fund'!H23+'05_Cash_Fund'!I23)/2)*'00_Assumptions'!$D$24 | J25: =(('05_Cash_Fund'!I23+'05_Cash_Fund'!J23)/2)*'00_Assumptions'!$D$24 | K25: =(('05_Cash_Fund'!J23+'05_Cash_Fund'!K23)/2)*'00_Assumptions'!$D$24
B26: EBT | D26: =D20+D24-D25 | E26: =E20+E24-E25 | F26: =F20+F24-F25 | G26: =G20+G24-G25 | H26: =H20+H24-H25 | I26: =I20+I24-I25 | J26: =J20+J24-J25 | K26: =K20+K24-K25
B28: NOL balance (BoY) | D28: 700 | E28: =D28+MAX(0,-D26)-D29 | F28: =E28+MAX(0,-E26)-E29 | G28: =F28+MAX(0,-F26)-F29 | H28: =G28+MAX(0,-G26)-G29 | I28: =H28+MAX(0,-H26)-H29 | J28: =I28+MAX(0,-I26)-I29 | K28: =J28+MAX(0,-J26)-J29 | M28: pre-2023 accumulated losses est. $0.7B — schedule accretes losses, burns against profits
B29: NOL used | D29: =MIN(D28,MAX(0,D26)) | E29: =MIN(E28,MAX(0,E26)) | F29: =MIN(F28,MAX(0,F26)) | G29: =MIN(G28,MAX(0,G26)) | H29: =MIN(H28,MAX(0,H26)) | I29: =MIN(I28,MAX(0,I26)) | J29: =MIN(J28,MAX(0,J26)) | K29: =MIN(K28,MAX(0,K26))
B30: Taxable income | D30: =MAX(0,D26-D29) | E30: =MAX(0,E26-E29) | F30: =MAX(0,F26-F29) | G30: =MAX(0,G26-G29) | H30: =MAX(0,H26-H29) | I30: =MAX(0,I26-I29) | J30: =MAX(0,J26-J29) | K30: =MAX(0,K26-K29)
B31: Tax expense | D31: =D30*'00_Assumptions'!$D$23 | E31: =E30*'00_Assumptions'!$D$23 | F31: =F30*'00_Assumptions'!$D$23 | G31: =G30*'00_Assumptions'!$D$23 | H31: =H30*'00_Assumptions'!$D$23 | I31: =I30*'00_Assumptions'!$D$23 | J31: =J30*'00_Assumptions'!$D$23 | K31: =K30*'00_Assumptions'!$D$23
B33: Net income | D33: =D26-D31 | E33: =E26-E31 | F33: =F26-F31 | G33: =G26-G31 | H33: =H26-H31 | I33: =I26-I31 | J33: =J26-J31 | K33: =K26-K31
B34: Net margin | D34: =D33/D9 | E34: =E33/E9 | F34: =F33/F9 | G34: =G33/G9 | H34: =H33/H9 | I34: =I33/I9 | J34: =J33/J9 | K34: =K33/K9
B36: No D&A line: compute is rented/prepaid (opex), owned-infra capex is small — see 05_Cash_Fund. SBC not separable pre-S-1 (private); flag for the T1 upgrade.

Sheet 05_Cash_Fund
B3: Free Cash Flow
B5: All figures in USD millions unless stated
D7: ='00_Assumptions'!D$10 | E7: ='00_Assumptions'!E$10 | F7: ='00_Assumptions'!F$10 | G7: ='00_Assumptions'!G$10 | H7: ='00_Assumptions'!H$10 | I7: ='00_Assumptions'!I$10 | J7: ='00_Assumptions'!J$10 | K7: ='00_Assumptions'!K$10
B9: Net income | D9: ='04_PL'!D33 | E9: ='04_PL'!E33 | F9: ='04_PL'!F33 | G9: ='04_PL'!G33 | H9: ='04_PL'!H33 | I9: ='04_PL'!I33 | J9: ='04_PL'!J33 | K9: ='04_PL'!K33
B10: Prepaid compute & WC build | D10: 0 | E10: 0 | F10: 0 | G10: =-('00_Assumptions'!G69*'02_Revenue'!G17) | H10: =-('00_Assumptions'!H69*'02_Revenue'!H17) | I10: =-('00_Assumptions'!I69*'02_Revenue'!I17) | J10: =-('00_Assumptions'!J69*'02_Revenue'!J17) | K10: =-('00_Assumptions'!K69*'02_Revenue'!K17)
B11: Owned-infra capex | D11: 0 | E11: 0 | F11: 0 | G11: =-('00_Assumptions'!$D$26*'02_Revenue'!G17) | H11: =-('00_Assumptions'!$D$26*'02_Revenue'!H17) | I11: =-('00_Assumptions'!$D$26*'02_Revenue'!I17) | J11: =-('00_Assumptions'!$D$26*'02_Revenue'!J17) | K11: =-('00_Assumptions'!$D$26*'02_Revenue'!K17)
B13: Free cash flow | D13: =SUM(D9:D11) | E13: =SUM(E9:E11) | F13: =SUM(F9:F11) | G13: =SUM(G9:G11) | H13: =SUM(H9:H11) | I13: =SUM(I9:I11) | J13: =SUM(J9:J11) | K13: =SUM(K9:K11)
B14: Reported burn: FY2025 −$5.6B (T3) vs derived — triangulation gap documented on 01_Data row 40. Hist. prepay/capex set to 0 (est.).
B16: Financing & Cash Walk
B18: All figures in USD millions unless stated
D19: ='00_Assumptions'!D$10 | E19: ='00_Assumptions'!E$10 | F19: ='00_Assumptions'!F$10 | G19: ='00_Assumptions'!G$10 | H19: ='00_Assumptions'!H$10 | I19: ='00_Assumptions'!I$10 | J19: ='00_Assumptions'!J$10 | K19: ='00_Assumptions'!K$10
B21: Equity raised ($M) | D21: 2000 | E21: 9200 | F21: 16500 | G21: 95000 | H21: 0 | I21: 0 | J21: 0 | K21: 0 | M21: 2026 = Series G $30B + Series H $65B · pre-2023 $1.6B sits in opening cash · est. year-split, tied to $124.3B [CANONICAL] via check
B22: Debt raised ($M) | D22: 0 | E22: 0 | F22: 2500 | G22: 34500 | H22: 0 | I22: 0 | J22: 0 | K22: 0
B23: Debt balance (EoY) | D23: =D22 | E23: =D23+E22 | F23: =E23+F22 | G23: =F23+G22 | H23: =G23+H22 | I23: =H23+I22 | J23: =I23+J22 | K23: =J23+K22
B24: Cash — BoY | D24: 700 | E24: =D25 | F24: =E25 | G24: =F25 | H24: =G25 | I24: =H25 | J24: =I25 | K24: =J25 | M24: opening cash = pre-2023 raises net of pre-2023 burn (est.)
B25: Cash — EoY | D25: =D24+D21+D22+D13 | E25: =E24+E21+E22+E13 | F25: =F24+F21+F22+F13 | G25: =G24+G21+G22+G13 | H25: =H24+H21+H22+H13 | I25: =I24+I21+I22+I13 | J25: =J24+J21+J22+J13 | K25: =K24+K21+K22+K13
B27: Check: cum. equity − $124.3B [CANONICAL] | D27: =1600+SUM(D21:K21)-124300 | F27: (0 = ties · red = broken)
B29: Capitalization & Efficiency
B31: Total equity raised (cum., $M) | C31: =1600+SUM(D21:K21) | E31: Ruling 1 denominator
B32: Total debt ($M) | C32: =K23 | E32: chip bonds + revolver
B33: Net cash — EoY 2026E ($M) | C33: =G25-G23 | E33: feeds the DCF bridge
B34: CE — Jul-26 run-rate ÷ equity | C34: ='01_Data'!C28/C31 | E34: gross basis (Ruling 1)
B35: CE — equalized net ÷ equity | C35: =('01_Data'!C28*'00_Assumptions'!$D$22)/C31 | E35: comparable to OpenAI 0.138x

Sheet 06_Valuation
B3: Marks Ladder — what each round paid per $ of run-rate
B5: USD millions · multiples on GROSS run-rate unless noted
B7: Round | C7: Date | D7: Post-money | E7: RR at mark | F7: EV / RR | G7: Note
B8: Series E | C8: Mar-25 | D8: 61500 | E8: 2000 | F8: =D8/E8 | G8: RR est. (T3)
B9: Series F | C9: Sep-25 | D9: 183000 | E9: 5000 | F9: =D9/E9 | G9: RR ~Aug-25 (T2)
B10: Series G | C10: Feb-26 | D10: 380000 | E10: 14000 | F10: =D10/E10 | G10: RR Feb-26 (T3)
B11: Series H | C11: May-26 | D11: 965000 | E11: 47000 | F11: =D11/E11 | G11: RR May-26 (T2)
B12: Series H mark vs Jul-26 RR | C12: Aug-26 | D12: =D11 | E12: ='01_Data'!C28 | F12: =D12/E12 | G12: compression on growth alone
B13: same, equalized NET (Ruling 5) | E13: =E12*'00_Assumptions'!$D$22 | F13: =D12/E13 | G13: was 34.1x at the May close
B15: Comps — equalized basis only (Ruling 5: never gross vs net)
B17: Company | D17: EV / mark | E17: Net RR | F17: EV / net RR | G17: Note
B18: OpenAI | D18: 852000 | E18: 25000 | F18: =D18/E18 | G18: [STALE — Mar-26 mark, ~Jun-26 ARR · re-pull]
B19: Anthropic (equalized) | D19: =D12 | E19: =E13 | F19: =D19/E19 | G19: identical basis to OpenAI row
B20: Databricks | D20: 134000 | E20: 5400 | F20: =D20/E20 | G20: [STALE — Feb-26 · reports net]
B21: xAI-in-SPCX: SOTP stale, Q2 printed Aug-6 [VERIFY] — excluded until re-pulled
B23: DCF — valuation date 31-Dec-2026 · active scenario
B25: All figures in USD millions unless stated
D26: ='00_Assumptions'!D$10 | E26: ='00_Assumptions'!E$10 | F26: ='00_Assumptions'!F$10 | G26: ='00_Assumptions'!G$10 | H26: ='00_Assumptions'!H$10 | I26: ='00_Assumptions'!I$10 | J26: ='00_Assumptions'!J$10 | K26: ='00_Assumptions'!K$10
B28: Free cash flow ($M) | D28: ='05_Cash_Fund'!D13 | E28: ='05_Cash_Fund'!E13 | F28: ='05_Cash_Fund'!F13 | G28: ='05_Cash_Fund'!G13 | H28: ='05_Cash_Fund'!H13 | I28: ='05_Cash_Fund'!I13 | J28: ='05_Cash_Fund'!J13 | K28: ='05_Cash_Fund'!K13
B29: Discount period (yrs) | H29: 1 | I29: 2 | J29: 3 | K29: 4
B30: PV of FCF | H30: =H28/(1+'00_Assumptions'!$G$17)^H29 | I30: =I28/(1+'00_Assumptions'!$G$17)^I29 | J30: =J28/(1+'00_Assumptions'!$G$17)^J29 | K30: =K28/(1+'00_Assumptions'!$G$17)^K29
B32: PV of explicit FCF 2027E–2030E | C32: =SUM(H30:K30)
B33: Terminal value — Gordon | C33: =K28*(1+'00_Assumptions'!$G$18)/('00_Assumptions'!$G$17-'00_Assumptions'!$G$18)
B34: PV of terminal (Gordon) | C34: =C33/(1+'00_Assumptions'!$G$17)^4
B35: Terminal value — exit multiple | C35: =K28*'00_Assumptions'!$G$19
B36: PV of terminal (multiple) | C36: =C35/(1+'00_Assumptions'!$G$17)^4
B37: Net cash — EoY 2026E | C37: ='05_Cash_Fund'!C33
B39: Equity value — Gordon ($M) | C39: =C32+C34+C37
B40: Equity value — exit multiple ($M) | C40: =C32+C36+C37
B42: Terminal as % of operating EV (Gordon) | C42: =C34/(C32+C34)
B43: vs Series H $965B — Gordon | C43: =C39/965000-1
B44: vs Series H $965B — exit multiple | C44: =C40/965000-1
B46: Reverse-DCF: implied 2030E FCF multiple at $965B | C46: =(965000-C37-C32)*(1+'00_Assumptions'!$G$17)^4/K28
B48: FCF is basis-invariant: gross vs net revenue presentation changes multiples, never cash. 4-yr explicit window ⇒ terminal dominates — Gordon at ~3% understates a business still compounding double-digit into 2030; the exit multiple carries persistence. The two bracket the question.

Sheet 07_Sensitivity
B3: Equity Value ($B) — Discount Rate × Terminal Growth (Gordon)
B5: Rebuilds the DCF at each (r, g) from the active-scenario FCF stream + net cash
B7: r \ g | C7: 0.02 | D7: 0.025 | E7: 0.03 | F7: 0.035 | G7: 0.04
B8: 0.14 | C8: =('06_Valuation'!$H$28/(1+$B8)^1+'06_Valuation'!$I$28/(1+$B8)^2+'06_Valuation'!$J$28/(1+$B8)^3+'06_Valuation'!$K$28/(1+$B8)^4+('06_Valuation'!$K$28*(1+C$7)/($B8-C$7))/(1+$B8)^4+'06_Valuation'!$C$37)/1000 | D8: =('06_Valuation'!$H$28/(1+$B8)^1+'06_Valuation'!$I$28/(1+$B8)^2+'06_Valuation'!$J$28/(1+$B8)^3+'06_Valuation'!$K$28/(1+$B8)^4+('06_Valuation'!$K$28*(1+D$7)/($B8-D$7))/(1+$B8)^4+'06_Valuation'!$C$37)/1000 | E8: =('06_Valuation'!$H$28/(1+$B8)^1+'06_Valuation'!$I$28/(1+$B8)^2+'06_Valuation'!$J$28/(1+$B8)^3+'06_Valuation'!$K$28/(1+$B8)^4+('06_Valuation'!$K$28*(1+E$7)/($B8-E$7))/(1+$B8)^4+'06_Valuation'!$C$37)/1000 | F8: =('06_Valuation'!$H$28/(1+$B8)^1+'06_Valuation'!$I$28/(1+$B8)^2+'06_Valuation'!$J$28/(1+$B8)^3+'06_Valuation'!$K$28/(1+$B8)^4+('06_Valuation'!$K$28*(1+F$7)/($B8-F$7))/(1+$B8)^4+'06_Valuation'!$C$37)/1000 | G8: =('06_Valuation'!$H$28/(1+$B8)^1+'06_Valuation'!$I$28/(1+$B8)^2+'06_Valuation'!$J$28/(1+$B8)^3+'06_Valuation'!$K$28/(1+$B8)^4+('06_Valuation'!$K$28*(1+G$7)/($B8-G$7))/(1+$B8)^4+'06_Valuation'!$C$37)/1000 | I8: Base cell: r 18.0% × g 3.0% (Base scenario)
B9: 0.16 | C9: =('06_Valuation'!$H$28/(1+$B9)^1+'06_Valuation'!$I$28/(1+$B9)^2+'06_Valuation'!$J$28/(1+$B9)^3+'06_Valuation'!$K$28/(1+$B9)^4+('06_Valuation'!$K$28*(1+C$7)/($B9-C$7))/(1+$B9)^4+'06_Valuation'!$C$37)/1000 | D9: =('06_Valuation'!$H$28/(1+$B9)^1+'06_Valuation'!$I$28/(1+$B9)^2+'06_Valuation'!$J$28/(1+$B9)^3+'06_Valuation'!$K$28/(1+$B9)^4+('06_Valuation'!$K$28*(1+D$7)/($B9-D$7))/(1+$B9)^4+'06_Valuation'!$C$37)/1000 | E9: =('06_Valuation'!$H$28/(1+$B9)^1+'06_Valuation'!$I$28/(1+$B9)^2+'06_Valuation'!$J$28/(1+$B9)^3+'06_Valuation'!$K$28/(1+$B9)^4+('06_Valuation'!$K$28*(1+E$7)/($B9-E$7))/(1+$B9)^4+'06_Valuation'!$C$37)/1000 | F9: =('06_Valuation'!$H$28/(1+$B9)^1+'06_Valuation'!$I$28/(1+$B9)^2+'06_Valuation'!$J$28/(1+$B9)^3+'06_Valuation'!$K$28/(1+$B9)^4+('06_Valuation'!$K$28*(1+F$7)/($B9-F$7))/(1+$B9)^4+'06_Valuation'!$C$37)/1000 | G9: =('06_Valuation'!$H$28/(1+$B9)^1+'06_Valuation'!$I$28/(1+$B9)^2+'06_Valuation'!$J$28/(1+$B9)^3+'06_Valuation'!$K$28/(1+$B9)^4+('06_Valuation'!$K$28*(1+G$7)/($B9-G$7))/(1+$B9)^4+'06_Valuation'!$C$37)/1000 | I9: $965B mark = Series H, May-26
B10: 0.18 | C10: =('06_Valuation'!$H$28/(1+$B10)^1+'06_Valuation'!$I$28/(1+$B10)^2+'06_Valuation'!$J$28/(1+$B10)^3+'06_Valuation'!$K$28/(1+$B10)^4+('06_Valuation'!$K$28*(1+C$7)/($B10-C$7))/(1+$B10)^4+'06_Valuation'!$C$37)/1000 | D10: =('06_Valuation'!$H$28/(1+$B10)^1+'06_Valuation'!$I$28/(1+$B10)^2+'06_Valuation'!$J$28/(1+$B10)^3+'06_Valuation'!$K$28/(1+$B10)^4+('06_Valuation'!$K$28*(1+D$7)/($B10-D$7))/(1+$B10)^4+'06_Valuation'!$C$37)/1000 | E10: =('06_Valuation'!$H$28/(1+$B10)^1+'06_Valuation'!$I$28/(1+$B10)^2+'06_Valuation'!$J$28/(1+$B10)^3+'06_Valuation'!$K$28/(1+$B10)^4+('06_Valuation'!$K$28*(1+E$7)/($B10-E$7))/(1+$B10)^4+'06_Valuation'!$C$37)/1000 | F10: =('06_Valuation'!$H$28/(1+$B10)^1+'06_Valuation'!$I$28/(1+$B10)^2+'06_Valuation'!$J$28/(1+$B10)^3+'06_Valuation'!$K$28/(1+$B10)^4+('06_Valuation'!$K$28*(1+F$7)/($B10-F$7))/(1+$B10)^4+'06_Valuation'!$C$37)/1000 | G10: =('06_Valuation'!$H$28/(1+$B10)^1+'06_Valuation'!$I$28/(1+$B10)^2+'06_Valuation'!$J$28/(1+$B10)^3+'06_Valuation'!$K$28/(1+$B10)^4+('06_Valuation'!$K$28*(1+G$7)/($B10-G$7))/(1+$B10)^4+'06_Valuation'!$C$37)/1000
B11: 0.2 | C11: =('06_Valuation'!$H$28/(1+$B11)^1+'06_Valuation'!$I$28/(1+$B11)^2+'06_Valuation'!$J$28/(1+$B11)^3+'06_Valuation'!$K$28/(1+$B11)^4+('06_Valuation'!$K$28*(1+C$7)/($B11-C$7))/(1+$B11)^4+'06_Valuation'!$C$37)/1000 | D11: =('06_Valuation'!$H$28/(1+$B11)^1+'06_Valuation'!$I$28/(1+$B11)^2+'06_Valuation'!$J$28/(1+$B11)^3+'06_Valuation'!$K$28/(1+$B11)^4+('06_Valuation'!$K$28*(1+D$7)/($B11-D$7))/(1+$B11)^4+'06_Valuation'!$C$37)/1000 | E11: =('06_Valuation'!$H$28/(1+$B11)^1+'06_Valuation'!$I$28/(1+$B11)^2+'06_Valuation'!$J$28/(1+$B11)^3+'06_Valuation'!$K$28/(1+$B11)^4+('06_Valuation'!$K$28*(1+E$7)/($B11-E$7))/(1+$B11)^4+'06_Valuation'!$C$37)/1000 | F11: =('06_Valuation'!$H$28/(1+$B11)^1+'06_Valuation'!$I$28/(1+$B11)^2+'06_Valuation'!$J$28/(1+$B11)^3+'06_Valuation'!$K$28/(1+$B11)^4+('06_Valuation'!$K$28*(1+F$7)/($B11-F$7))/(1+$B11)^4+'06_Valuation'!$C$37)/1000 | G11: =('06_Valuation'!$H$28/(1+$B11)^1+'06_Valuation'!$I$28/(1+$B11)^2+'06_Valuation'!$J$28/(1+$B11)^3+'06_Valuation'!$K$28/(1+$B11)^4+('06_Valuation'!$K$28*(1+G$7)/($B11-G$7))/(1+$B11)^4+'06_Valuation'!$C$37)/1000
B12: 0.22 | C12: =('06_Valuation'!$H$28/(1+$B12)^1+'06_Valuation'!$I$28/(1+$B12)^2+'06_Valuation'!$J$28/(1+$B12)^3+'06_Valuation'!$K$28/(1+$B12)^4+('06_Valuation'!$K$28*(1+C$7)/($B12-C$7))/(1+$B12)^4+'06_Valuation'!$C$37)/1000 | D12: =('06_Valuation'!$H$28/(1+$B12)^1+'06_Valuation'!$I$28/(1+$B12)^2+'06_Valuation'!$J$28/(1+$B12)^3+'06_Valuation'!$K$28/(1+$B12)^4+('06_Valuation'!$K$28*(1+D$7)/($B12-D$7))/(1+$B12)^4+'06_Valuation'!$C$37)/1000 | E12: =('06_Valuation'!$H$28/(1+$B12)^1+'06_Valuation'!$I$28/(1+$B12)^2+'06_Valuation'!$J$28/(1+$B12)^3+'06_Valuation'!$K$28/(1+$B12)^4+('06_Valuation'!$K$28*(1+E$7)/($B12-E$7))/(1+$B12)^4+'06_Valuation'!$C$37)/1000 | F12: =('06_Valuation'!$H$28/(1+$B12)^1+'06_Valuation'!$I$28/(1+$B12)^2+'06_Valuation'!$J$28/(1+$B12)^3+'06_Valuation'!$K$28/(1+$B12)^4+('06_Valuation'!$K$28*(1+F$7)/($B12-F$7))/(1+$B12)^4+'06_Valuation'!$C$37)/1000 | G12: =('06_Valuation'!$H$28/(1+$B12)^1+'06_Valuation'!$I$28/(1+$B12)^2+'06_Valuation'!$J$28/(1+$B12)^3+'06_Valuation'!$K$28/(1+$B12)^4+('06_Valuation'!$K$28*(1+G$7)/($B12-G$7))/(1+$B12)^4+'06_Valuation'!$C$37)/1000
B15: Equity Value ($B) — Multiple × 2027E Net Revenue
B17: x \ $B | C17: 50 | D17: 70 | E17: 90 | F17: 110 | G17: 130
B18: 10 | C18: =(C$17*1000*$B18+'06_Valuation'!$C$37)/1000 | D18: =(D$17*1000*$B18+'06_Valuation'!$C$37)/1000 | E18: =(E$17*1000*$B18+'06_Valuation'!$C$37)/1000 | F18: =(F$17*1000*$B18+'06_Valuation'!$C$37)/1000 | G18: =(G$17*1000*$B18+'06_Valuation'!$C$37)/1000
B19: 15 | C19: =(C$17*1000*$B19+'06_Valuation'!$C$37)/1000 | D19: =(D$17*1000*$B19+'06_Valuation'!$C$37)/1000 | E19: =(E$17*1000*$B19+'06_Valuation'!$C$37)/1000 | F19: =(F$17*1000*$B19+'06_Valuation'!$C$37)/1000 | G19: =(G$17*1000*$B19+'06_Valuation'!$C$37)/1000
B20: 20 | C20: =(C$17*1000*$B20+'06_Valuation'!$C$37)/1000 | D20: =(D$17*1000*$B20+'06_Valuation'!$C$37)/1000 | E20: =(E$17*1000*$B20+'06_Valuation'!$C$37)/1000 | F20: =(F$17*1000*$B20+'06_Valuation'!$C$37)/1000 | G20: =(G$17*1000*$B20+'06_Valuation'!$C$37)/1000
B21: 25 | C21: =(C$17*1000*$B21+'06_Valuation'!$C$37)/1000 | D21: =(D$17*1000*$B21+'06_Valuation'!$C$37)/1000 | E21: =(E$17*1000*$B21+'06_Valuation'!$C$37)/1000 | F21: =(F$17*1000*$B21+'06_Valuation'!$C$37)/1000 | G21: =(G$17*1000*$B21+'06_Valuation'!$C$37)/1000
B22: 30 | C22: =(C$17*1000*$B22+'06_Valuation'!$C$37)/1000 | D22: =(D$17*1000*$B22+'06_Valuation'!$C$37)/1000 | E22: =(E$17*1000*$B22+'06_Valuation'!$C$37)/1000 | F22: =(F$17*1000*$B22+'06_Valuation'!$C$37)/1000 | G22: =(G$17*1000*$B22+'06_Valuation'!$C$37)/1000
B24: Model 2027E net revenue (active scenario, $B): | D24: ='02_Revenue'!H19/1000
B26: The model computes one scenario at a time — flip 00_Assumptions!D7 to compare. Grids above are scenario-invariant only through the FCF stream they reference.

Sheet 08_Output
B3: Dashboard — What Must Be True for $965B?
B5: USD millions unless noted · active scenario: | D5: ='00_Assumptions'!D8
B7: Run-rate — end-Jul 2026 (gross) | D7: ='01_Data'!C28 | F7: T2 · CNBC/Bloomberg/Fortune, Aug 17–18
B8: Mark ÷ run-rate — gross / equalized | D8: ='06_Valuation'!F12 | E8: ='06_Valuation'!F13 | F8: equalized in E — was 20.5x / 34.1x in May
B9: 2026E recognized revenue | D9: ='02_Revenue'!G17 | F9: derived, log-mean of the exit curve
B10: 2027E recognized revenue | D10: ='02_Revenue'!H17 | F10: every scenario floors high — usage momentum
B11: EBIT 2027E | D11: ='04_PL'!H20 | F11: margin plan 63% doing the lifting
B12: FCF 2027E | D12: ='05_Cash_Fund'!H13 | F12: vs WSJ −$25B trough (Apr-26 vintage) — re-based
B13: Equity value — Gordon | D13: ='06_Valuation'!C39 | F13: floor-ish: terminal ignores post-2030 compounding
B14: Equity value — exit multiple | D14: ='06_Valuation'!C40 | F14: growth-persistence case
B15: vs $965B — Gordon / exit multiple | D15: ='06_Valuation'!C43 | E15: ='06_Valuation'!C44 | F15: exit-multiple case in E
B16: Reverse-DCF: implied 2030E FCF multiple | D16: ='06_Valuation'!C46 | F16: what the mark actually requires
B17: CE — equalized net RR ÷ equity | D17: ='05_Cash_Fund'!C35 | F17: OpenAI comp: 0.138x (Ruling 1)
B19: 1 · GROWTH — YE-26 exit ~$110B, then +50/+32/+22/+15% (Base). Usage revenue is not contracted ARR: durability is the bet.
B20: 2 · MARGINS — 40% (2025A) → 77% (2028E company plan) against price deflation, cloud rev-share, and inference-cost curves.
B21: 3 · COMPUTE — training spend scales to ~$45B/yr by 2030E and operating leverage still shows through.
B22: 4 · BASIS — a gross→net SEC restatement (Ruling 5: ×60.25%) moves multiples ~40%, and cash not at all.
